Workbook
Name 是否: [1]选项!$A$1:$A$2
Name Hidden000cdfc206468fca52c_1_11: [2]Hidden000cdfc206468fca52c!$A$1:$A$71
Name Hidden000cdfc206468fca52c_1_17: [2]Hidden000cdfc206468fca52c!$B$1:$B$7
Name Hidden000cdfc206468fca52c_1_22: [2]Hidden000cdfc206468fca52c!$C$1:$C$7
Name Hidden000cdfc206468fca52c_1_23: [2]Hidden000cdfc206468fca52c!$D$1:$D$2
Name Hidden000cdfc206468fca52c_1_24: [2]Hidden000cdfc206468fca52c!$E$1:$E$8
Name Hidden000cdfc206468fca52c_1_27: [2]Hidden000cdfc206468fca52c!$F$1:$F$10
Name Hidden000cdfc206468fca52c_1_32: [2]Hidden000cdfc206468fca52c!$G$1:$G$2
Name Hidden000cdfc206468fca52c_1_33: [2]Hidden000cdfc206468fca52c!$H$1:$H$5
Name Hidden000cdfc206468fca52c_1_34: [2]Hidden000cdfc206468fca52c!$I$1:$I$5
Name Hidden000cdfc206468fca52c_1_35: [2]Hidden000cdfc206468fca52c!$J$1:$J$58
Name Hidden000cdfc206468fca52c_1_43: [2]Hidden000cdfc206468fca52c!$K$1:$K$9
Name Hidden000cdfc206468fca52c_1_44: [2]Hidden000cdfc206468fca52c!$L$1:$L$4
Name Hidden000cdfc206468fca52c_1_56: [2]Hidden000cdfc206468fca52c!$M$1:$M$8
Name Hidden000cdfc206468fca52c_1_57: [2]Hidden000cdfc206468fca52c!$N$1:$N$7
Name Hidden000cdfc206468fca52c_1_58: [2]Hidden000cdfc206468fca52c!$O$1:$O$8
Name Hidden000cdfc206468fca52c_1_63: [2]Hidden000cdfc206468fca52c!$P$1:$P$5
Name Hidden000cdfc206468fca52c_1_67: [2]Hidden000cdfc206468fca52c!$Q$1:$Q$6
Name Hidden000cdfc206468fca52c_1_70: [2]Hidden000cdfc206468fca52c!$R$1:$R$6
Name Hidden000cdfc206468fca52c_1_71: [2]Hidden000cdfc206468fca52c!$S$1:$S$2
Name categoryHidden33: [3]categoryHidden33!A1:A170
Name categoryHidden9: #REF!
Name 证件类型: [4]填表说明!$A$6:$A$17

Sheet 北分人力成本
A1: 日期： | B1: 46204 | E1: 公司名称： | F1: 六棱镜（杭州）科技有限公司北京分公司
A3: 员工工资及代扣代缴费用汇总表
A4: 一级部门 | B4: 二级部门 | C4: 三级部门 | D4: 人数 | E4: 应发工资 | F4: 养老个人 | G4: 医疗个人 | H4: 失业个人 | I4: 社保个人扣款 | J4: 住房公积金 | K4: 个税 | L4: 税后补款 | M4: 税后扣款 | N4: 实发工资
E5: 金额 | F5: 金额 | G5: 金额 | H5: 金额 | I5: 金额 | J5: 金额 | K5: 金额 | L5: 金额 | M5: 金额 | N5: 金额
A6: 姜文超 | B6: 0 | C6: 0 | D6: =COUNTIFS(工资明细!BM:BM,$F$1,工资明细!H:H,A6,工资明细!I:I,B6,工资明细!J:J,C6) -> 0 | E6: =SUMIFS(工资明细!AO:AO,工资明细!BM:BM,$F$1,工资明细!H:H,A6,工资明细!I:I,B6,工资明细!J:J,C6) -> 0 | F6: =SUMIFS(工资明细!AP:AP,工资明细!BM:BM,$F$1,工资明细!H:H,A6,工资明细!I:I,B6,工资明细!J:J,C6) -> 0 | G6: =SUMIFS(工资明细!AQ:AQ,工资明细!BM:BM,$F$1,工资明细!H:H,A6,工资明细!I:I,B6,工资明细!J:J,C6) -> 0 | H6: =SUMIFS(工资明细!AR:AR,工资明细!BM:BM,$F$1,工资明细!H:H,A6,工资明细!I:I,B6,工资明细!J:J,C6) -> 0 | I6: =F6+G6+H6 -> 0 | J6: =SUMIFS(工资明细!AT:AT,工资明细!BM:BM,$F$1,工资明细!H:H,A6,工资明细!I:I,B6,工资明细!J:J,C6) -> 0 | K6: =SUMIFS(工资明细!AU:AU,工资明细!BM:BM,$F$1,工资明细!H:H,A6,工资明细!I:I,B6,工资明细!J:J,C6) -> 0 | L6: =SUMIFS(工资明细!AV:AV,工资明细!BM:BM,$F$1,工资明细!H:H,A6,工资明细!I:I,B6,工资明细!J:J,C6) -> 0 | M6: =SUMIFS(工资明细!AW:AW,工资明细!BM:BM,$F$1,工资明细!H:H,A6,工资明细!I:I,B6,工资明细!J:J,C6) -> 0 | N6: =SUMIFS(工资明细!AX:AX,工资明细!BM:BM,$F$1,工资明细!H:H,A6,工资明细!I:I,B6,工资明细!J:J,C6) -> 0
A7: 郭子轶 | B7: 0 | C7: 0 | D7: =COUNTIFS(工资明细!BM:BM,$F$1,工资明细!H:H,A7,工资明细!I:I,B7,工资明细!J:J,C7) -> 0 | E7: =SUMIFS(工资明细!AO:AO,工资明细!BM:BM,$F$1,工资明细!H:H,A7,工资明细!I:I,B7,工资明细!J:J,C7) -> 0 | F7: =SUMIFS(工资明细!AP:AP,工资明细!BM:BM,$F$1,工资明细!H:H,A7,工资明细!I:I,B7,工资明细!J:J,C7) -> 0 | G7: =SUMIFS(工资明细!AQ:AQ,工资明细!BM:BM,$F$1,工资明细!H:H,A7,工资明细!I:I,B7,工资明细!J:J,C7) -> 0 | H7: =SUMIFS(工资明细!AR:AR,工资明细!BM:BM,$F$1,工资明细!H:H,A7,工资明细!I:I,B7,工资明细!J:J,C7) -> 0 | I7: =F7+G7+H7 -> 0 | J7: =SUMIFS(工资明细!AT:AT,工资明细!BM:BM,$F$1,工资明细!H:H,A7,工资明细!I:I,B7,工资明细!J:J,C7) -> 0 | K7: =SUMIFS(工资明细!AU:AU,工资明细!BM:BM,$F$1,工资明细!H:H,A7,工资明细!I:I,B7,工资明细!J:J,C7) -> 0 | L7: =SUMIFS(工资明细!AV:AV,工资明细!BM:BM,$F$1,工资明细!H:H,A7,工资明细!I:I,B7,工资明细!J:J,C7) -> 0 | M7: =SUMIFS(工资明细!AW:AW,工资明细!BM:BM,$F$1,工资明细!H:H,A7,工资明细!I:I,B7,工资明细!J:J,C7) -> 0 | N7: =SUMIFS(工资明细!AX:AX,工资明细!BM:BM,$F$1,工资明细!H:H,A7,工资明细!I:I,B7,工资明细!J:J,C7) -> 0
A8: 董事会办公室 | B8: 法务部 | C8: 0 | D8: =COUNTIFS(工资明细!BM:BM,$F$1,工资明细!H:H,A8,工资明细!I:I,B8,工资明细!J:J,C8) -> 0 | E8: =SUMIFS(工资明细!AO:AO,工资明细!BM:BM,$F$1,工资明细!H:H,A8,工资明细!I:I,B8,工资明细!J:J,C8) -> 0 | F8: =SUMIFS(工资明细!AP:AP,工资明细!BM:BM,$F$1,工资明细!H:H,A8,工资明细!I:I,B8,工资明细!J:J,C8) -> 0 | G8: =SUMIFS(工资明细!AQ:AQ,工资明细!BM:BM,$F$1,工资明细!H:H,A8,工资明细!I:I,B8,工资明细!J:J,C8) -> 0 | H8: =SUMIFS(工资明细!AR:AR,工资明细!BM:BM,$F$1,工资明细!H:H,A8,工资明细!I:I,B8,工资明细!J:J,C8) -> 0 | I8: =F8+G8+H8 -> 0 | J8: =SUMIFS(工资明细!AT:AT,工资明细!BM:BM,$F$1,工资明细!H:H,A8,工资明细!I:I,B8,工资明细!J:J,C8) -> 0 | K8: =SUMIFS(工资明细!AU:AU,工资明细!BM:BM,$F$1,工资明细!H:H,A8,工资明细!I:I,B8,工资明细!J:J,C8) -> 0 | L8: =SUMIFS(工资明细!AV:AV,工资明细!BM:BM,$F$1,工资明细!H:H,A8,工资明细!I:I,B8,工资明细!J:J,C8) -> 0 | M8: =SUMIFS(工资明细!AW:AW,工资明细!BM:BM,$F$1,工资明细!H:H,A8,工资明细!I:I,B8,工资明细!J:J,C8) -> 0 | N8: =SUMIFS(工资明细!AX:AX,工资明细!BM:BM,$F$1,工资明细!H:H,A8,工资明细!I:I,B8,工资明细!J:J,C8) -> 0
A9: 总经理办公室 | B9: 人力资源部 | C9: 0 | D9: =COUNTIFS(工资明细!BM:BM,$F$1,工资明细!H:H,A9,工资明细!I:I,B9,工资明细!J:J,C9) -> 0 | E9: =SUMIFS(工资明细!AO:AO,工资明细!BM:BM,$F$1,工资明细!H:H,A9,工资明细!I:I,B9,工资明细!J:J,C9) -> 0 | F9: =SUMIFS(工资明细!AP:AP,工资明细!BM:BM,$F$1,工资明细!H:H,A9,工资明细!I:I,B9,工资明细!J:J,C9) -> 0 | G9: =SUMIFS(工资明细!AQ:AQ,工资明细!BM:BM,$F$1,工资明细!H:H,A9,工资明细!I:I,B9,工资明细!J:J,C9) -> 0 | H9: =SUMIFS(工资明细!AR:AR,工资明细!BM:BM,$F$1,工资明细!H:H,A9,工资明细!I:I,B9,工资明细!J:J,C9) -> 0 | I9: =F9+G9+H9 -> 0 | J9: =SUMIFS(工资明细!AT:AT,工资明细!BM:BM,$F$1,工资明细!H:H,A9,工资明细!I:I,B9,工资明细!J:J,C9) -> 0 | K9: =SUMIFS(工资明细!AU:AU,工资明细!BM:BM,$F$1,工资明细!H:H,A9,工资明细!I:I,B9,工资明细!J:J,C9) -> 0 | L9: =SUMIFS(工资明细!AV:AV,工资明细!BM:BM,$F$1,工资明细!H:H,A9,工资明细!I:I,B9,工资明细!J:J,C9) -> 0 | M9: =SUMIFS(工资明细!AW:AW,工资明细!BM:BM,$F$1,工资明细!H:H,A9,工资明细!I:I,B9,工资明细!J:J,C9) -> 0 | N9: =SUMIFS(工资明细!AX:AX,工资明细!BM:BM,$F$1,工资明细!H:H,A9,工资明细!I:I,B9,工资明细!J:J,C9) -> 0
A10: 总经理办公室 | B10: 综合部 | C10: 北京综合部 | D10: =COUNTIFS(工资明细!BM:BM,$F$1,工资明细!H:H,A10,工资明细!I:I,B10,工资明细!J:J,C10) -> 0 | E10: =SUMIFS(工资明细!AO:AO,工资明细!BM:BM,$F$1,工资明细!H:H,A10,工资明细!I:I,B10,工资明细!J:J,C10) -> 0 | F10: =SUMIFS(工资明细!AP:AP,工资明细!BM:BM,$F$1,工资明细!H:H,A10,工资明细!I:I,B10,工资明细!J:J,C10) -> 0 | G10: =SUMIFS(工资明细!AQ:AQ,工资明细!BM:BM,$F$1,工资明细!H:H,A10,工资明细!I:I,B10,工资明细!J:J,C10) -> 0 | H10: =SUMIFS(工资明细!AR:AR,工资明细!BM:BM,$F$1,工资明细!H:H,A10,工资明细!I:I,B10,工资明细!J:J,C10) -> 0 | I10: =F10+G10+H10 -> 0 | J10: =SUMIFS(工资明细!AT:AT,工资明细!BM:BM,$F$1,工资明细!H:H,A10,工资明细!I:I,B10,工资明细!J:J,C10) -> 0 | K10: =SUMIFS(工资明细!AU:AU,工资明细!BM:BM,$F$1,工资明细!H:H,A10,工资明细!I:I,B10,工资明细!J:J,C10) -> 0 | L10: =SUMIFS(工资明细!AV:AV,工资明细!BM:BM,$F$1,工资明细!H:H,A10,工资明细!I:I,B10,工资明细!J:J,C10) -> 0 | M10: =SUMIFS(工资明细!AW:AW,工资明细!BM:BM,$F$1,工资明细!H:H,A10,工资明细!I:I,B10,工资明细!J:J,C10) -> 0 | N10: =SUMIFS(工资明细!AX:AX,工资明细!BM:BM,$F$1,工资明细!H:H,A10,工资明细!I:I,B10,工资明细!J:J,C10) -> 0
A11: 总经理办公室 | B11: 综合部 | C11: 杭州综合部 | D11: =COUNTIFS(工资明细!BM:BM,$F$1,工资明细!H:H,A11,工资明细!I:I,B11,工资明细!J:J,C11) -> 0 | E11: =SUMIFS(工资明细!AO:AO,工资明细!BM:BM,$F$1,工资明细!H:H,A11,工资明细!I:I,B11,工资明细!J:J,C11) -> 0 | F11: =SUMIFS(工资明细!AP:AP,工资明细!BM:BM,$F$1,工资明细!H:H,A11,工资明细!I:I,B11,工资明细!J:J,C11) -> 0 | G11: =SUMIFS(工资明细!AQ:AQ,工资明细!BM:BM,$F$1,工资明细!H:H,A11,工资明细!I:I,B11,工资明细!J:J,C11) -> 0 | H11: =SUMIFS(工资明细!AR:AR,工资明细!BM:BM,$F$1,工资明细!H:H,A11,工资明细!I:I,B11,工资明细!J:J,C11) -> 0 | I11: =F11+G11+H11 -> 0 | J11: =SUMIFS(工资明细!AT:AT,工资明细!BM:BM,$F$1,工资明细!H:H,A11,工资明细!I:I,B11,工资明细!J:J,C11) -> 0 | K11: =SUMIFS(工资明细!AU:AU,工资明细!BM:BM,$F$1,工资明细!H:H,A11,工资明细!I:I,B11,工资明细!J:J,C11) -> 0 | L11: =SUMIFS(工资明细!AV:AV,工资明细!BM:BM,$F$1,工资明细!H:H,A11,工资明细!I:I,B11,工资明细!J:J,C11) -> 0 | M11: =SUMIFS(工资明细!AW:AW,工资明细!BM:BM,$F$1,工资明细!H:H,A11,工资明细!I:I,B11,工资明细!J:J,C11) -> 0 | N11: =SUMIFS(工资明细!AX:AX,工资明细!BM:BM,$F$1,工资明细!H:H,A11,工资明细!I:I,B11,工资明细!J:J,C11) -> 0
A12: 解决方案中心 | B12: 0 | C12: 0 | D12: =COUNTIFS(工资明细!BM:BM,$F$1,工资明细!H:H,A12,工资明细!I:I,B12,工资明细!J:J,C12) -> 0 | E12: =SUMIFS(工资明细!AO:AO,工资明细!BM:BM,$F$1,工资明细!H:H,A12,工资明细!I:I,B12,工资明细!J:J,C12) -> 0 | F12: =SUMIFS(工资明细!AP:AP,工资明细!BM:BM,$F$1,工资明细!H:H,A12,工资明细!I:I,B12,工资明细!J:J,C12) -> 0 | G12: =SUMIFS(工资明细!AQ:AQ,工资明细!BM:BM,$F$1,工资明细!H:H,A12,工资明细!I:I,B12,工资明细!J:J,C12) -> 0 | H12: =SUMIFS(工资明细!AR:AR,工资明细!BM:BM,$F$1,工资明细!H:H,A12,工资明细!I:I,B12,工资明细!J:J,C12) -> 0 | I12: =F12+G12+H12 -> 0 | J12: =SUMIFS(工资明细!AT:AT,工资明细!BM:BM,$F$1,工资明细!H:H,A12,工资明细!I:I,B12,工资明细!J:J,C12) -> 0 | K12: =SUMIFS(工资明细!AU:AU,工资明细!BM:BM,$F$1,工资明细!H:H,A12,工资明细!I:I,B12,工资明细!J:J,C12) -> 0 | L12: =SUMIFS(工资明细!AV:AV,工资明细!BM:BM,$F$1,工资明细!H:H,A12,工资明细!I:I,B12,工资明细!J:J,C12) -> 0 | M12: =SUMIFS(工资明细!AW:AW,工资明细!BM:BM,$F$1,工资明细!H:H,A12,工资明细!I:I,B12,工资明细!J:J,C12) -> 0 | N12: =SUMIFS(工资明细!AX:AX,工资明细!BM:BM,$F$1,工资明细!H:H,A12,工资明细!I:I,B12,工资明细!J:J,C12) -> 0
A13: 市场部 | B13: SaaS中心 | C13: 客服中心 | D13: =COUNTIFS(工资明细!BM:BM,$F$1,工资明细!H:H,A13,工资明细!I:I,B13,工资明细!J:J,C13) -> 0 | E13: =SUMIFS(工资明细!AO:AO,工资明细!BM:BM,$F$1,工资明细!H:H,A13,工资明细!I:I,B13,工资明细!J:J,C13) -> 0 | F13: =SUMIFS(工资明细!AP:AP,工资明细!BM:BM,$F$1,工资明细!H:H,A13,工资明细!I:I,B13,工资明细!J:J,C13) -> 0 | G13: =SUMIFS(工资明细!AQ:AQ,工资明细!BM:BM,$F$1,工资明细!H:H,A13,工资明细!I:I,B13,工资明细!J:J,C13) -> 0 | H13: =SUMIFS(工资明细!AR:AR,工资明细!BM:BM,$F$1,工资明细!H:H,A13,工资明细!I:I,B13,工资明细!J:J,C13) -> 0 | I13: =F13+G13+H13 -> 0 | J13: =SUMIFS(工资明细!AT:AT,工资明细!BM:BM,$F$1,工资明细!H:H,A13,工资明细!I:I,B13,工资明细!J:J,C13) -> 0 | K13: =SUMIFS(工资明细!AU:AU,工资明细!BM:BM,$F$1,工资明细!H:H,A13,工资明细!I:I,B13,工资明细!J:J,C13) -> 0 | L13: =SUMIFS(工资明细!AV:AV,工资明细!BM:BM,$F$1,工资明细!H:H,A13,工资明细!I:I,B13,工资明细!J:J,C13) -> 0 | M13: =SUMIFS(工资明细!AW:AW,工资明细!BM:BM,$F$1,工资明细!H:H,A13,工资明细!I:I,B13,工资明细!J:J,C13) -> 0 | N13: =SUMIFS(工资明细!AX:AX,工资明细!BM:BM,$F$1,工资明细!H:H,A13,工资明细!I:I,B13,工资明细!J:J,C13) -> 0
A14: 市场部 | B14: 战略规划部 | C14: 北京总部 | D14: =COUNTIFS(工资明细!BM:BM,$F$1,工资明细!H:H,A14,工资明细!I:I,B14,工资明细!J:J,C14) -> 0 | E14: =SUMIFS(工资明细!AO:AO,工资明细!BM:BM,$F$1,工资明细!H:H,A14,工资明细!I:I,B14,工资明细!J:J,C14) -> 0 | F14: =SUMIFS(工资明细!AP:AP,工资明细!BM:BM,$F$1,工资明细!H:H,A14,工资明细!I:I,B14,工资明细!J:J,C14) -> 0 | G14: =SUMIFS(工资明细!AQ:AQ,工资明细!BM:BM,$F$1,工资明细!H:H,A14,工资明细!I:I,B14,工资明细!J:J,C14) -> 0 | H14: =SUMIFS(工资明细!AR:AR,工资明细!BM:BM,$F$1,工资明细!H:H,A14,工资明细!I:I,B14,工资明细!J:J,C14) -> 0 | I14: =F14+G14+H14 -> 0 | J14: =SUMIFS(工资明细!AT:AT,工资明细!BM:BM,$F$1,工资明细!H:H,A14,工资明细!I:I,B14,工资明细!J:J,C14) -> 0 | K14: =SUMIFS(工资明细!AU:AU,工资明细!BM:BM,$F$1,工资明细!H:H,A14,工资明细!I:I,B14,工资明细!J:J,C14) -> 0 | L14: =SUMIFS(工资明细!AV:AV,工资明细!BM:BM,$F$1,工资明细!H:H,A14,工资明细!I:I,B14,工资明细!J:J,C14) -> 0 | M14: =SUMIFS(工资明细!AW:AW,工资明细!BM:BM,$F$1,工资明细!H:H,A14,工资明细!I:I,B14,工资明细!J:J,C14) -> 0 | N14: =SUMIFS(工资明细!AX:AX,工资明细!BM:BM,$F$1,工资明细!H:H,A14,工资明细!I:I,B14,工资明细!J:J,C14) -> 0
A15: 市场部 | B15: 0 | C15: 0 | D15: =COUNTIFS(工资明细!BM:BM,$F$1,工资明细!H:H,A15,工资明细!I:I,B15,工资明细!J:J,C15) -> 0 | E15: =SUMIFS(工资明细!AO:AO,工资明细!BM:BM,$F$1,工资明细!H:H,A15,工资明细!I:I,B15,工资明细!J:J,C15) -> 0 | F15: =SUMIFS(工资明细!AP:AP,工资明细!BM:BM,$F$1,工资明细!H:H,A15,工资明细!I:I,B15,工资明细!J:J,C15) -> 0 | G15: =SUMIFS(工资明细!AQ:AQ,工资明细!BM:BM,$F$1,工资明细!H:H,A15,工资明细!I:I,B15,工资明细!J:J,C15) -> 0 | H15: =SUMIFS(工资明细!AR:AR,工资明细!BM:BM,$F$1,工资明细!H:H,A15,工资明细!I:I,B15,工资明细!J:J,C15) -> 0 | I15: =F15+G15+H15 -> 0 | J15: =SUMIFS(工资明细!AT:AT,工资明细!BM:BM,$F$1,工资明细!H:H,A15,工资明细!I:I,B15,工资明细!J:J,C15) -> 0 | K15: =SUMIFS(工资明细!AU:AU,工资明细!BM:BM,$F$1,工资明细!H:H,A15,工资明细!I:I,B15,工资明细!J:J,C15) -> 0 | L15: =SUMIFS(工资明细!AV:AV,工资明细!BM:BM,$F$1,工资明细!H:H,A15,工资明细!I:I,B15,工资明细!J:J,C15) -> 0 | M15: =SUMIFS(工资明细!AW:AW,工资明细!BM:BM,$F$1,工资明细!H:H,A15,工资明细!I:I,B15,工资明细!J:J,C15) -> 0 | N15: =SUMIFS(工资明细!AX:AX,工资明细!BM:BM,$F$1,工资明细!H:H,A15,工资明细!I:I,B15,工资明细!J:J,C15) -> 0
A16: 技术研发事业部 | B16: 产品研发部 | C16: 产品组 | D16: =COUNTIFS(工资明细!BM:BM,$F$1,工资明细!H:H,A16,工资明细!I:I,B16,工资明细!J:J,C16) -> 0 | E16: =SUMIFS(工资明细!AO:AO,工资明细!BM:BM,$F$1,工资明细!H:H,A16,工资明细!I:I,B16,工资明细!J:J,C16) -> 0 | F16: =SUMIFS(工资明细!AP:AP,工资明细!BM:BM,$F$1,工资明细!H:H,A16,工资明细!I:I,B16,工资明细!J:J,C16) -> 0 | G16: =SUMIFS(工资明细!AQ:AQ,工资明细!BM:BM,$F$1,工资明细!H:H,A16,工资明细!I:I,B16,工资明细!J:J,C16) -> 0 | H16: =SUMIFS(工资明细!AR:AR,工资明细!BM:BM,$F$1,工资明细!H:H,A16,工资明细!I:I,B16,工资明细!J:J,C16) -> 0 | I16: =F16+G16+H16 -> 0 | J16: =SUMIFS(工资明细!AT:AT,工资明细!BM:BM,$F$1,工资明细!H:H,A16,工资明细!I:I,B16,工资明细!J:J,C16) -> 0 | K16: =SUMIFS(工资明细!AU:AU,工资明细!BM:BM,$F$1,工资明细!H:H,A16,工资明细!I:I,B16,工资明细!J:J,C16) -> 0 | L16: =SUMIFS(工资明细!AV:AV,工资明细!BM:BM,$F$1,工资明细!H:H,A16,工资明细!I:I,B16,工资明细!J:J,C16) -> 0 | M16: =SUMIFS(工资明细!AW:AW,工资明细!BM:BM,$F$1,工资明细!H:H,A16,工资明细!I:I,B16,工资明细!J:J,C16) -> 0 | N16: =SUMIFS(工资明细!AX:AX,工资明细!BM:BM,$F$1,工资明细!H:H,A16,工资明细!I:I,B16,工资明细!J:J,C16) -> 0
A17: 技术研发事业部 | B17: 产品研发部 | C17: 项目组 | D17: =COUNTIFS(工资明细!BM:BM,$F$1,工资明细!H:H,A17,工资明细!I:I,B17,工资明细!J:J,C17) -> 0 | E17: =SUMIFS(工资明细!AO:AO,工资明细!BM:BM,$F$1,工资明细!H:H,A17,工资明细!I:I,B17,工资明细!J:J,C17) -> 0 | F17: =SUMIFS(工资明细!AP:AP,工资明细!BM:BM,$F$1,工资明细!H:H,A17,工资明细!I:I,B17,工资明细!J:J,C17) -> 0 | G17: =SUMIFS(工资明细!AQ:AQ,工资明细!BM:BM,$F$1,工资明细!H:H,A17,工资明细!I:I,B17,工资明细!J:J,C17) -> 0 | H17: =SUMIFS(工资明细!AR:AR,工资明细!BM:BM,$F$1,工资明细!H:H,A17,工资明细!I:I,B17,工资明细!J:J,C17) -> 0 | I17: =F17+G17+H17 -> 0 | J17: =SUMIFS(工资明细!AT:AT,工资明细!BM:BM,$F$1,工资明细!H:H,A17,工资明细!I:I,B17,工资明细!J:J,C17) -> 0 | K17: =SUMIFS(工资明细!AU:AU,工资明细!BM:BM,$F$1,工资明细!H:H,A17,工资明细!I:I,B17,工资明细!J:J,C17) -> 0 | L17: =SUMIFS(工资明细!AV:AV,工资明细!BM:BM,$F$1,工资明细!H:H,A17,工资明细!I:I,B17,工资明细!J:J,C17) -> 0 | M17: =SUMIFS(工资明细!AW:AW,工资明细!BM:BM,$F$1,工资明细!H:H,A17,工资明细!I:I,B17,工资明细!J:J,C17) -> 0 | N17: =SUMIFS(工资明细!AX:AX,工资明细!BM:BM,$F$1,工资明细!H:H,A17,工资明细!I:I,B17,工资明细!J:J,C17) -> 0
A18: 技术研发事业部 | B18: 大数据部 | C18: 数据采集组 | D18: =COUNTIFS(工资明细!BM:BM,$F$1,工资明细!H:H,A18,工资明细!I:I,B18,工资明细!J:J,C18) -> 0 | E18: =SUMIFS(工资明细!AO:AO,工资明细!BM:BM,$F$1,工资明细!H:H,A18,工资明细!I:I,B18,工资明细!J:J,C18) -> 0 | F18: =SUMIFS(工资明细!AP:AP,工资明细!BM:BM,$F$1,工资明细!H:H,A18,工资明细!I:I,B18,工资明细!J:J,C18) -> 0 | G18: =SUMIFS(工资明细!AQ:AQ,工资明细!BM:BM,$F$1,工资明细!H:H,A18,工资明细!I:I,B18,工资明细!J:J,C18) -> 0 | H18: =SUMIFS(工资明细!AR:AR,工资明细!BM:BM,$F$1,工资明细!H:H,A18,工资明细!I:I,B18,工资明细!J:J,C18) -> 0 | I18: =F18+G18+H18 -> 0 | J18: =SUMIFS(工资明细!AT:AT,工资明细!BM:BM,$F$1,工资明细!H:H,A18,工资明细!I:I,B18,工资明细!J:J,C18) -> 0 | K18: =SUMIFS(工资明细!AU:AU,工资明细!BM:BM,$F$1,工资明细!H:H,A18,工资明细!I:I,B18,工资明细!J:J,C18) -> 0 | L18: =SUMIFS(工资明细!AV:AV,工资明细!BM:BM,$F$1,工资明细!H:H,A18,工资明细!I:I,B18,工资明细!J:J,C18) -> 0 | M18: =SUMIFS(工资明细!AW:AW,工资明细!BM:BM,$F$1,工资明细!H:H,A18,工资明细!I:I,B18,工资明细!J:J,C18) -> 0 | N18: =SUMIFS(工资明细!AX:AX,工资明细!BM:BM,$F$1,工资明细!H:H,A18,工资明细!I:I,B18,工资明细!J:J,C18) -> 0
A19: 技术研发事业部 | B19: 大数据部 | C19: 数据仓库组 | D19: =COUNTIFS(工资明细!BM:BM,$F$1,工资明细!H:H,A19,工资明细!I:I,B19,工资明细!J:J,C19) -> 0 | E19: =SUMIFS(工资明细!AO:AO,工资明细!BM:BM,$F$1,工资明细!H:H,A19,工资明细!I:I,B19,工资明细!J:J,C19) -> 0 | F19: =SUMIFS(工资明细!AP:AP,工资明细!BM:BM,$F$1,工资明细!H:H,A19,工资明细!I:I,B19,工资明细!J:J,C19) -> 0 | G19: =SUMIFS(工资明细!AQ:AQ,工资明细!BM:BM,$F$1,工资明细!H:H,A19,工资明细!I:I,B19,工资明细!J:J,C19) -> 0 | H19: =SUMIFS(工资明细!AR:AR,工资明细!BM:BM,$F$1,工资明细!H:H,A19,工资明细!I:I,B19,工资明细!J:J,C19) -> 0 | I19: =F19+G19+H19 -> 0 | J19: =SUMIFS(工资明细!AT:AT,工资明细!BM:BM,$F$1,工资明细!H:H,A19,工资明细!I:I,B19,工资明细!J:J,C19) -> 0 | K19: =SUMIFS(工资明细!AU:AU,工资明细!BM:BM,$F$1,工资明细!H:H,A19,工资明细!I:I,B19,工资明细!J:J,C19) -> 0 | L19: =SUMIFS(工资明细!AV:AV,工资明细!BM:BM,$F$1,工资明细!H:H,A19,工资明细!I:I,B19,工资明细!J:J,C19) -> 0 | M19: =SUMIFS(工资明细!AW:AW,工资明细!BM:BM,$F$1,工资明细!H:H,A19,工资明细!I:I,B19,工资明细!J:J,C19) -> 0 | N19: =SUMIFS(工资明细!AX:AX,工资明细!BM:BM,$F$1,工资明细!H:H,A19,工资明细!I:I,B19,工资明细!J:J,C19) -> 0
A20: 技术研发事业部 | B20: 大数据部 | C20: 数据规则组 | D20: =COUNTIFS(工资明细!BM:BM,$F$1,工资明细!H:H,A20,工资明细!I:I,B20,工资明细!J:J,C20) -> 0 | E20: =SUMIFS(工资明细!AO:AO,工资明细!BM:BM,$F$1,工资明细!H:H,A20,工资明细!I:I,B20,工资明细!J:J,C20) -> 0 | F20: =SUMIFS(工资明细!AP:AP,工资明细!BM:BM,$F$1,工资明细!H:H,A20,工资明细!I:I,B20,工资明细!J:J,C20) -> 0 | G20: =SUMIFS(工资明细!AQ:AQ,工资明细!BM:BM,$F$1,工资明细!H:H,A20,工资明细!I:I,B20,工资明细!J:J,C20) -> 0 | H20: =SUMIFS(工资明细!AR:AR,工资明细!BM:BM,$F$1,工资明细!H:H,A20,工资明细!I:I,B20,工资明细!J:J,C20) -> 0 | I20: =F20+G20+H20 -> 0 | J20: =SUMIFS(工资明细!AT:AT,工资明细!BM:BM,$F$1,工资明细!H:H,A20,工资明细!I:I,B20,工资明细!J:J,C20) -> 0 | K20: =SUMIFS(工资明细!AU:AU,工资明细!BM:BM,$F$1,工资明细!H:H,A20,工资明细!I:I,B20,工资明细!J:J,C20) -> 0 | L20: =SUMIFS(工资明细!AV:AV,工资明细!BM:BM,$F$1,工资明细!H:H,A20,工资明细!I:I,B20,工资明细!J:J,C20) -> 0 | M20: =SUMIFS(工资明细!AW:AW,工资明细!BM:BM,$F$1,工资明细!H:H,A20,工资明细!I:I,B20,工资明细!J:J,C20) -> 0 | N20: =SUMIFS(工资明细!AX:AX,工资明细!BM:BM,$F$1,工资明细!H:H,A20,工资明细!I:I,B20,工资明细!J:J,C20) -> 0
A21: 技术研发事业部 | B21: 大数据部 | C21: 数据平台组 | D21: =COUNTIFS(工资明细!BM:BM,$F$1,工资明细!H:H,A21,工资明细!I:I,B21,工资明细!J:J,C21) -> 0 | E21: =SUMIFS(工资明细!AO:AO,工资明细!BM:BM,$F$1,工资明细!H:H,A21,工资明细!I:I,B21,工资明细!J:J,C21) -> 0 | F21: =SUMIFS(工资明细!AP:AP,工资明细!BM:BM,$F$1,工资明细!H:H,A21,工资明细!I:I,B21,工资明细!J:J,C21) -> 0 | G21: =SUMIFS(工资明细!AQ:AQ,工资明细!BM:BM,$F$1,工资明细!H:H,A21,工资明细!I:I,B21,工资明细!J:J,C21) -> 0 | H21: =SUMIFS(工资明细!AR:AR,工资明细!BM:BM,$F$1,工资明细!H:H,A21,工资明细!I:I,B21,工资明细!J:J,C21) -> 0 | I21: =F21+G21+H21 -> 0 | J21: =SUMIFS(工资明细!AT:AT,工资明细!BM:BM,$F$1,工资明细!H:H,A21,工资明细!I:I,B21,工资明细!J:J,C21) -> 0 | K21: =SUMIFS(工资明细!AU:AU,工资明细!BM:BM,$F$1,工资明细!H:H,A21,工资明细!I:I,B21,工资明细!J:J,C21) -> 0 | L21: =SUMIFS(工资明细!AV:AV,工资明细!BM:BM,$F$1,工资明细!H:H,A21,工资明细!I:I,B21,工资明细!J:J,C21) -> 0 | M21: =SUMIFS(工资明细!AW:AW,工资明细!BM:BM,$F$1,工资明细!H:H,A21,工资明细!I:I,B21,工资明细!J:J,C21) -> 0 | N21: =SUMIFS(工资明细!AX:AX,工资明细!BM:BM,$F$1,工资明细!H:H,A21,工资明细!I:I,B21,工资明细!J:J,C21) -> 0
A22: 技术研发事业部 | B22: 架构与算法部 | C22: 0 | D22: =COUNTIFS(工资明细!BM:BM,$F$1,工资明细!H:H,A22,工资明细!I:I,B22,工资明细!J:J,C22) -> 0 | E22: =SUMIFS(工资明细!AO:AO,工资明细!BM:BM,$F$1,工资明细!H:H,A22,工资明细!I:I,B22,工资明细!J:J,C22) -> 0 | F22: =SUMIFS(工资明细!AP:AP,工资明细!BM:BM,$F$1,工资明细!H:H,A22,工资明细!I:I,B22,工资明细!J:J,C22) -> 0 | G22: =SUMIFS(工资明细!AQ:AQ,工资明细!BM:BM,$F$1,工资明细!H:H,A22,工资明细!I:I,B22,工资明细!J:J,C22) -> 0 | H22: =SUMIFS(工资明细!AR:AR,工资明细!BM:BM,$F$1,工资明细!H:H,A22,工资明细!I:I,B22,工资明细!J:J,C22) -> 0 | I22: =F22+G22+H22 -> 0 | J22: =SUMIFS(工资明细!AT:AT,工资明细!BM:BM,$F$1,工资明细!H:H,A22,工资明细!I:I,B22,工资明细!J:J,C22) -> 0 | K22: =SUMIFS(工资明细!AU:AU,工资明细!BM:BM,$F$1,工资明细!H:H,A22,工资明细!I:I,B22,工资明细!J:J,C22) -> 0 | L22: =SUMIFS(工资明细!AV:AV,工资明细!BM:BM,$F$1,工资明细!H:H,A22,工资明细!I:I,B22,工资明细!J:J,C22) -> 0 | M22: =SUMIFS(工资明细!AW:AW,工资明细!BM:BM,$F$1,工资明细!H:H,A22,工资明细!I:I,B22,工资明细!J:J,C22) -> 0 | N22: =SUMIFS(工资明细!AX:AX,工资明细!BM:BM,$F$1,工资明细!H:H,A22,工资明细!I:I,B22,工资明细!J:J,C22) -> 0
A23: 知识产权咨询事业部 | B23: 0 | C23: 0 | D23: =COUNTIFS(工资明细!BM:BM,$F$1,工资明细!H:H,A23,工资明细!I:I,B23,工资明细!J:J,C23) -> 0 | E23: =SUMIFS(工资明细!AO:AO,工资明细!BM:BM,$F$1,工资明细!H:H,A23,工资明细!I:I,B23,工资明细!J:J,C23) -> 0 | F23: =SUMIFS(工资明细!AP:AP,工资明细!BM:BM,$F$1,工资明细!H:H,A23,工资明细!I:I,B23,工资明细!J:J,C23) -> 0 | G23: =SUMIFS(工资明细!AQ:AQ,工资明细!BM:BM,$F$1,工资明细!H:H,A23,工资明细!I:I,B23,工资明细!J:J,C23) -> 0 | H23: =SUMIFS(工资明细!AR:AR,工资明细!BM:BM,$F$1,工资明细!H:H,A23,工资明细!I:I,B23,工资明细!J:J,C23) -> 0 | I23: =F23+G23+H23 -> 0 | J23: =SUMIFS(工资明细!AT:AT,工资明细!BM:BM,$F$1,工资明细!H:H,A23,工资明细!I:I,B23,工资明细!J:J,C23) -> 0 | K23: =SUMIFS(工资明细!AU:AU,工资明细!BM:BM,$F$1,工资明细!H:H,A23,工资明细!I:I,B23,工资明细!J:J,C23) -> 0 | L23: =SUMIFS(工资明细!AV:AV,工资明细!BM:BM,$F$1,工资明细!H:H,A23,工资明细!I:I,B23,工资明细!J:J,C23) -> 0 | M23: =SUMIFS(工资明细!AW:AW,工资明细!BM:BM,$F$1,工资明细!H:H,A23,工资明细!I:I,B23,工资明细!J:J,C23) -> 0 | N23: =SUMIFS(工资明细!AX:AX,工资明细!BM:BM,$F$1,工资明细!H:H,A23,工资明细!I:I,B23,工资明细!J:J,C23) -> 0
A24: 招投标部 | B24: 0 | C24: 0 | D24: =COUNTIFS(工资明细!BM:BM,$F$1,工资明细!H:H,A24,工资明细!I:I,B24,工资明细!J:J,C24) -> 0 | E24: =SUMIFS(工资明细!AO:AO,工资明细!BM:BM,$F$1,工资明细!H:H,A24,工资明细!I:I,B24,工资明细!J:J,C24) -> 0 | F24: =SUMIFS(工资明细!AP:AP,工资明细!BM:BM,$F$1,工资明细!H:H,A24,工资明细!I:I,B24,工资明细!J:J,C24) -> 0 | G24: =SUMIFS(工资明细!AQ:AQ,工资明细!BM:BM,$F$1,工资明细!H:H,A24,工资明细!I:I,B24,工资明细!J:J,C24) -> 0 | H24: =SUMIFS(工资明细!AR:AR,工资明细!BM:BM,$F$1,工资明细!H:H,A24,工资明细!I:I,B24,工资明细!J:J,C24) -> 0 | I24: =F24+G24+H24 -> 0 | J24: =SUMIFS(工资明细!AT:AT,工资明细!BM:BM,$F$1,工资明细!H:H,A24,工资明细!I:I,B24,工资明细!J:J,C24) -> 0 | K24: =SUMIFS(工资明细!AU:AU,工资明细!BM:BM,$F$1,工资明细!H:H,A24,工资明细!I:I,B24,工资明细!J:J,C24) -> 0 | L24: =SUMIFS(工资明细!AV:AV,工资明细!BM:BM,$F$1,工资明细!H:H,A24,工资明细!I:I,B24,工资明细!J:J,C24) -> 0 | M24: =SUMIFS(工资明细!AW:AW,工资明细!BM:BM,$F$1,工资明细!H:H,A24,工资明细!I:I,B24,工资明细!J:J,C24) -> 0 | N24: =SUMIFS(工资明细!AX:AX,工资明细!BM:BM,$F$1,工资明细!H:H,A24,工资明细!I:I,B24,工资明细!J:J,C24) -> 0
A25: 其他 | B25: 0 | C25: 0 | D25: =COUNTIFS(工资明细!BM:BM,$F$1,工资明细!H:H,A25,工资明细!I:I,B25,工资明细!J:J,C25) -> 0 | E25: =SUMIFS(工资明细!AO:AO,工资明细!BM:BM,$F$1,工资明细!H:H,A25,工资明细!I:I,B25,工资明细!J:J,C25) -> 0 | F25: =SUMIFS(工资明细!AP:AP,工资明细!BM:BM,$F$1,工资明细!H:H,A25,工资明细!I:I,B25,工资明细!J:J,C25) -> 0 | G25: =SUMIFS(工资明细!AQ:AQ,工资明细!BM:BM,$F$1,工资明细!H:H,A25,工资明细!I:I,B25,工资明细!J:J,C25) -> 0 | H25: =SUMIFS(工资明细!AR:AR,工资明细!BM:BM,$F$1,工资明细!H:H,A25,工资明细!I:I,B25,工资明细!J:J,C25) -> 0 | I25: =F25+G25+H25 -> 0 | J25: =SUMIFS(工资明细!AT:AT,工资明细!BM:BM,$F$1,工资明细!H:H,A25,工资明细!I:I,B25,工资明细!J:J,C25) -> 0 | K25: =SUMIFS(工资明细!AU:AU,工资明细!BM:BM,$F$1,工资明细!H:H,A25,工资明细!I:I,B25,工资明细!J:J,C25) -> 0 | L25: =SUMIFS(工资明细!AV:AV,工资明细!BM:BM,$F$1,工资明细!H:H,A25,工资明细!I:I,B25,工资明细!J:J,C25) -> 0 | M25: =SUMIFS(工资明细!AW:AW,工资明细!BM:BM,$F$1,工资明细!H:H,A25,工资明细!I:I,B25,工资明细!J:J,C25) -> 0 | N25: =SUMIFS(工资明细!AX:AX,工资明细!BM:BM,$F$1,工资明细!H:H,A25,工资明细!I:I,B25,工资明细!J:J,C25) -> 0
A26: 合计 | D26: =SUM(D6:D25) -> 0 | E26: =SUM(E6:E25) -> 0 | F26: =SUM(F6:F25) -> 0 | G26: =SUM(G6:G25) -> 0 | H26: =SUM(H6:H25) -> 0 | I26: =SUM(I6:I25) -> 0 | J26: =SUM(J6:J25) -> 0 | K26: =SUM(K6:K25) -> 0 | ... N26: =SUM(N6:N25) -> 0
A28: 公积金缴纳汇总表
A29: 一级部门 | B29: 二级部门 | C29: 三级部门 | D29: 人数 | E29: 企业缴纳 | F29: 个人缴纳 | G29: 合计
D30: 人数 | E30: 金额 | F30: 金额 | G30: 合计
A31: 姜文超 | D31: =COUNTIFS(工资明细!BM:BM,$F$1,工资明细!H:H,A31,工资明细!I:I,B31,工资明细!J:J,C31) -> 0 | E31: =SUMIFS(工资明细!BE:BE,工资明细!BM:BM,$F$1,工资明细!H:H,A31,工资明细!I:I,B31,工资明细!J:J,C31) -> 0 | F31: =SUMIFS(工资明细!AT:AT,工资明细!BM:BM,$F$1,工资明细!H:H,A31,工资明细!I:I,B31,工资明细!J:J,C31) -> 0 | G31: =SUM(E31:F31) -> 0
A32: 郭子轶 | D32: =COUNTIFS(工资明细!BM:BM,$F$1,工资明细!H:H,A32,工资明细!I:I,B32,工资明细!J:J,C32) -> 0 | E32: =SUMIFS(工资明细!BE:BE,工资明细!BM:BM,$F$1,工资明细!H:H,A32,工资明细!I:I,B32,工资明细!J:J,C32) -> 0 | F32: =SUMIFS(工资明细!AT:AT,工资明细!BM:BM,$F$1,工资明细!H:H,A32,工资明细!I:I,B32,工资明细!J:J,C32) -> 0 | G32: =SUM(E32:F32) -> 0
A33: 董事会办公室 | B33: 法务部 | D33: =COUNTIFS(工资明细!BM:BM,$F$1,工资明细!H:H,A33,工资明细!I:I,B33,工资明细!J:J,C33) -> 0 | E33: =SUMIFS(工资明细!BE:BE,工资明细!BM:BM,$F$1,工资明细!H:H,A33,工资明细!I:I,B33,工资明细!J:J,C33) -> 0 | F33: =SUMIFS(工资明细!AT:AT,工资明细!BM:BM,$F$1,工资明细!H:H,A33,工资明细!I:I,B33,工资明细!J:J,C33) -> 0 | G33: =SUM(E33:F33) -> 0
A34: 总经理办公室 | B34: 人力资源部 | D34: =COUNTIFS(工资明细!BM:BM,$F$1,工资明细!H:H,A34,工资明细!I:I,B34,工资明细!J:J,C34) -> 0 | E34: =SUMIFS(工资明细!BE:BE,工资明细!BM:BM,$F$1,工资明细!H:H,A34,工资明细!I:I,B34,工资明细!J:J,C34) -> 0 | F34: =SUMIFS(工资明细!AT:AT,工资明细!BM:BM,$F$1,工资明细!H:H,A34,工资明细!I:I,B34,工资明细!J:J,C34) -> 0 | G34: =SUM(E34:F34) -> 0
A35: 总经理办公室 | B35: 综合部 | C35: 北京综合部 | D35: =COUNTIFS(工资明细!BM:BM,$F$1,工资明细!H:H,A35,工资明细!I:I,B35,工资明细!J:J,C35) -> 0 | E35: =SUMIFS(工资明细!BE:BE,工资明细!BM:BM,$F$1,工资明细!H:H,A35,工资明细!I:I,B35,工资明细!J:J,C35) -> 0 | F35: =SUMIFS(工资明细!AT:AT,工资明细!BM:BM,$F$1,工资明细!H:H,A35,工资明细!I:I,B35,工资明细!J:J,C35) -> 0 | G35: =SUM(E35:F35) -> 0
A36: 总经理办公室 | B36: 综合部 | C36: 杭州综合部 | D36: =COUNTIFS(工资明细!BM:BM,$F$1,工资明细!H:H,A36,工资明细!I:I,B36,工资明细!J:J,C36) -> 0 | E36: =SUMIFS(工资明细!BE:BE,工资明细!BM:BM,$F$1,工资明细!H:H,A36,工资明细!I:I,B36,工资明细!J:J,C36) -> 0 | F36: =SUMIFS(工资明细!AT:AT,工资明细!BM:BM,$F$1,工资明细!H:H,A36,工资明细!I:I,B36,工资明细!J:J,C36) -> 0 | G36: =SUM(E36:F36) -> 0
A37: 解决方案中心 | D37: =COUNTIFS(工资明细!BM:BM,$F$1,工资明细!H:H,A37,工资明细!I:I,B37,工资明细!J:J,C37) -> 0 | E37: =SUMIFS(工资明细!BE:BE,工资明细!BM:BM,$F$1,工资明细!H:H,A37,工资明细!I:I,B37,工资明细!J:J,C37) -> 0 | F37: =SUMIFS(工资明细!AT:AT,工资明细!BM:BM,$F$1,工资明细!H:H,A37,工资明细!I:I,B37,工资明细!J:J,C37) -> 0 | G37: =SUM(E37:F37) -> 0
A38: 市场部 | B38: SaaS中心 | C38: 客服中心 | D38: =COUNTIFS(工资明细!BM:BM,$F$1,工资明细!H:H,A38,工资明细!I:I,B38,工资明细!J:J,C38) -> 0 | E38: =SUMIFS(工资明细!BE:BE,工资明细!BM:BM,$F$1,工资明细!H:H,A38,工资明细!I:I,B38,工资明细!J:J,C38) -> 0 | F38: =SUMIFS(工资明细!AT:AT,工资明细!BM:BM,$F$1,工资明细!H:H,A38,工资明细!I:I,B38,工资明细!J:J,C38) -> 0 | G38: =SUM(E38:F38) -> 0
A39: 市场部 | B39: 战略规划部 | C39: 北京总部 | D39: =COUNTIFS(工资明细!BM:BM,$F$1,工资明细!H:H,A39,工资明细!I:I,B39,工资明细!J:J,C39) -> 0 | E39: =SUMIFS(工资明细!BE:BE,工资明细!BM:BM,$F$1,工资明细!H:H,A39,工资明细!I:I,B39,工资明细!J:J,C39) -> 0 | F39: =SUMIFS(工资明细!AT:AT,工资明细!BM:BM,$F$1,工资明细!H:H,A39,工资明细!I:I,B39,工资明细!J:J,C39) -> 0 | G39: =SUM(E39:F39) -> 0
A40: 市场部 | D40: =COUNTIFS(工资明细!BM:BM,$F$1,工资明细!H:H,A40,工资明细!I:I,B40,工资明细!J:J,C40) -> 0 | E40: =SUMIFS(工资明细!BE:BE,工资明细!BM:BM,$F$1,工资明细!H:H,A40,工资明细!I:I,B40,工资明细!J:J,C40) -> 0 | F40: =SUMIFS(工资明细!AT:AT,工资明细!BM:BM,$F$1,工资明细!H:H,A40,工资明细!I:I,B40,工资明细!J:J,C40) -> 0 | G40: =SUM(E40:F40) -> 0
A41: 技术研发事业部 | B41: 产品研发部 | C41: 产品组 | D41: =COUNTIFS(工资明细!BM:BM,$F$1,工资明细!H:H,A41,工资明细!I:I,B41,工资明细!J:J,C41) -> 0 | E41: =SUMIFS(工资明细!BE:BE,工资明细!BM:BM,$F$1,工资明细!H:H,A41,工资明细!I:I,B41,工资明细!J:J,C41) -> 0 | F41: =SUMIFS(工资明细!AT:AT,工资明细!BM:BM,$F$1,工资明细!H:H,A41,工资明细!I:I,B41,工资明细!J:J,C41) -> 0 | G41: =SUM(E41:F41) -> 0
A42: 技术研发事业部 | B42: 产品研发部 | C42: 项目组 | D42: =COUNTIFS(工资明细!BM:BM,$F$1,工资明细!H:H,A42,工资明细!I:I,B42,工资明细!J:J,C42) -> 0 | E42: =SUMIFS(工资明细!BE:BE,工资明细!BM:BM,$F$1,工资明细!H:H,A42,工资明细!I:I,B42,工资明细!J:J,C42) -> 0 | F42: =SUMIFS(工资明细!AT:AT,工资明细!BM:BM,$F$1,工资明细!H:H,A42,工资明细!I:I,B42,工资明细!J:J,C42) -> 0 | G42: =SUM(E42:F42) -> 0
...

Sheet 北京人力成本
A1: 日期： | B1: =北分人力成本!B1 -> 46204 | E1: 公司名称： | F1: 北京六棱镜数字科技发展有限公司
A3: 员工工资及代扣代缴费用汇总表
A4: 一级部门 | B4: 二级部门 | C4: 三级部门 | D4: 人数 | E4: 应发工资 | F4: 养老个人 | G4: 医疗个人 | H4: 失业个人 | I4: 社保个人扣款 | J4: 住房公积金 | K4: 个税 | L4: 税后补款 | M4: 税后扣款 | N4: 实发工资
E5: 金额 | F5: 金额 | G5: 金额 | H5: 金额 | I5: 金额 | J5: 金额 | K5: 金额 | L5: 金额 | M5: 金额 | N5: 金额
A6: 总经理办公室 | B6: 综合部 | C6: 杭州综合部 | D6: =COUNTIFS(工资明细!BM:BM,$F$1,工资明细!H:H,A6,工资明细!I:I,B6,工资明细!J:J,C6) -> 0 | E6: =SUMIFS(工资明细!AO:AO,工资明细!BM:BM,$F$1,工资明细!H:H,A6,工资明细!I:I,B6,工资明细!J:J,C6) -> 0 | F6: =SUMIFS(工资明细!AP:AP,工资明细!BM:BM,$F$1,工资明细!H:H,A6,工资明细!I:I,B6,工资明细!J:J,C6) -> 0 | G6: =SUMIFS(工资明细!AQ:AQ,工资明细!BM:BM,$F$1,工资明细!H:H,A6,工资明细!I:I,B6,工资明细!J:J,C6) -> 0 | H6: =SUMIFS(工资明细!AR:AR,工资明细!BM:BM,$F$1,工资明细!H:H,A6,工资明细!I:I,B6,工资明细!J:J,C6) -> 0 | I6: =F6+G6+H6 -> 0 | J6: =SUMIFS(工资明细!AT:AT,工资明细!BM:BM,$F$1,工资明细!H:H,A6,工资明细!I:I,B6,工资明细!J:J,C6) -> 0 | K6: =SUMIFS(工资明细!AU:AU,工资明细!BM:BM,$F$1,工资明细!H:H,A6,工资明细!I:I,B6,工资明细!J:J,C6) -> 0 | L6: =SUMIFS(工资明细!AV:AV,工资明细!BM:BM,$F$1,工资明细!H:H,A6,工资明细!I:I,B6,工资明细!J:J,C6) -> 0 | M6: =SUMIFS(工资明细!AW:AW,工资明细!BM:BM,$F$1,工资明细!H:H,A6,工资明细!I:I,B6,工资明细!J:J,C6) -> 0 | N6: =SUMIFS(工资明细!AX:AX,工资明细!BM:BM,$F$1,工资明细!H:H,A6,工资明细!I:I,B6,工资明细!J:J,C6) -> 0
A7: 合计 | D7: =SUM(D6:D6) -> 0 | E7: =SUM(E6:E6) -> 0 | F7: =SUM(F6:F6) -> 0 | G7: =SUM(G6:G6) -> 0 | H7: =SUM(H6:H6) -> 0 | I7: =SUM(I6:I6) -> 0 | J7: =SUM(J6:J6) -> 0 | K7: =SUM(K6:K6) -> 0 | ... N7: =SUM(N6:N6) -> 0
A9: 公积金缴纳汇总表
A10: 一级部门 | B10: 二级部门 | C10: 三级部门 | D10: 人数 | E10: 企业缴纳 | F10: 个人缴纳 | G10: 合计
D11: 人数 | E11: 金额 | F11: 金额 | G11: 合计
A12: 总经理办公室 | B12: 综合部 | C12: 杭州综合部 | D12: =COUNTIFS(工资明细!BM:BM,$F$1,工资明细!H:H,A12,工资明细!I:I,B12,工资明细!J:J,C12) -> 0 | E12: =SUMIFS(工资明细!BE:BE,工资明细!BM:BM,$F$1,工资明细!H:H,A12,工资明细!I:I,B12,工资明细!J:J,C12) -> 0 | F12: =SUMIFS(工资明细!AT:AT,工资明细!BM:BM,$F$1,工资明细!H:H,A12,工资明细!I:I,B12,工资明细!J:J,C12) -> 0 | G12: =SUM(E12:F12) -> 0
A13: 合计 | D13: =SUM(D12:D12) -> 0 | E13: =SUM(E12:E12) -> 0 | F13: =SUM(F12:F12) -> 0 | G13: =SUM(G12:G12) -> 0
A15: 社保缴纳汇总表
A16: 一级部门 | B16: 二级部门 | C16: 三级部门 | D16: 人数 | E16: 养老单位 | F16: 医疗单位 | G16: 失业单位 | H16: 工伤单位 | I16: 生育单位 | J16: 企业部分 | K16: 个人部分 | L16: 合计
E17: 金额 | F17: 金额 | G17: 金额 | H17: 金额 | I17: 金额 | J17: 金额 | K17: 金额
A18: 总经理办公室 | B18: 综合部 | C18: 杭州综合部 | D18: =COUNTIFS(工资明细!BM:BM,$F$1,工资明细!H:H,A18,工资明细!I:I,B18,工资明细!J:J,C18) -> 0 | E18: =SUMIFS(工资明细!AY:AY,工资明细!BM:BM,$F$1,工资明细!H:H,A18,工资明细!I:I,B18,工资明细!J:J,C18) -> 0 | F18: =SUMIFS(工资明细!AZ:AZ,工资明细!BM:BM,$F$1,工资明细!H:H,A18,工资明细!I:I,B18,工资明细!J:J,C18) -> 0 | G18: =SUMIFS(工资明细!BA:BA,工资明细!BM:BM,$F$1,工资明细!H:H,A18,工资明细!I:I,B18,工资明细!J:J,C18) -> 0 | H18: =SUMIFS(工资明细!BB:BB,工资明细!BM:BM,$F$1,工资明细!H:H,A18,工资明细!I:I,B18,工资明细!J:J,C18) -> 0 | I18: =SUMIFS(工资明细!BC:BC,工资明细!BM:BM,$F$1,工资明细!H:H,A18,工资明细!I:I,B18,工资明细!J:J,C18) -> 0 | J18: =SUM(E18:I18) -> 0 | K18: =SUMIFS(工资明细!AS:AS,工资明细!BM:BM,$F$1,工资明细!H:H,A18,工资明细!I:I,B18,工资明细!J:J,C18) -> 0 | L18: =SUM(J18:K18) -> 0
A19: 合计 | D19: =SUM(D18:D18) -> 0 | E19: =SUM(E18:E18) -> 0 | F19: =SUM(F18:F18) -> 0 | G19: =SUM(G18:G18) -> 0 | H19: =SUM(H18:H18) -> 0 | I19: =SUM(I18:I18) -> 0 | J19: =SUM(J18:J18) -> 0 | K19: =SUM(K18:K18) -> 0 | L19: =SUM(L18:L18) -> 0

Sheet 成都人力成本
A1: 日期： | B1: =北分人力成本!B1 -> 46204 | E1: 公司名称： | F1: 成都六棱镜数字科技有限公司
A3: 员工工资及代扣代缴费用汇总表
A4: 一级部门 | B4: 二级部门 | C4: 三级部门 | D4: 人数 | E4: 应发工资 | F4: 养老个人 | G4: 医疗个人 | H4: 失业个人 | I4: 社保个人扣款 | J4: 住房公积金 | K4: 个税 | L4: 税后补款 | M4: 税后扣款 | N4: 实发工资
E5: 金额 | F5: 金额 | G5: 金额 | H5: 金额 | I5: 金额 | J5: 金额 | K5: 金额 | L5: 金额 | M5: 金额 | N5: 金额
A6: 市场部 | B6: 市场推广部 | C6: 成都区域 | D6: =COUNTIFS(工资明细!BM:BM,$F$1,工资明细!H:H,A6,工资明细!I:I,B6,工资明细!J:J,C6) -> 0 | E6: =SUMIFS(工资明细!AO:AO,工资明细!BM:BM,$F$1,工资明细!H:H,A6,工资明细!I:I,B6,工资明细!J:J,C6) -> 0 | F6: =SUMIFS(工资明细!AP:AP,工资明细!BM:BM,$F$1,工资明细!H:H,A6,工资明细!I:I,B6,工资明细!J:J,C6) -> 0 | G6: =SUMIFS(工资明细!AQ:AQ,工资明细!BM:BM,$F$1,工资明细!H:H,A6,工资明细!I:I,B6,工资明细!J:J,C6) -> 0 | H6: =SUMIFS(工资明细!AR:AR,工资明细!BM:BM,$F$1,工资明细!H:H,A6,工资明细!I:I,B6,工资明细!J:J,C6) -> 0 | I6: =F6+G6+H6 -> 0 | J6: =SUMIFS(工资明细!AT:AT,工资明细!BM:BM,$F$1,工资明细!H:H,A6,工资明细!I:I,B6,工资明细!J:J,C6) -> 0 | K6: =SUMIFS(工资明细!AU:AU,工资明细!BM:BM,$F$1,工资明细!H:H,A6,工资明细!I:I,B6,工资明细!J:J,C6) -> 0 | L6: =SUMIFS(工资明细!AV:AV,工资明细!BM:BM,$F$1,工资明细!H:H,A6,工资明细!I:I,B6,工资明细!J:J,C6) -> 0 | M6: =SUMIFS(工资明细!AW:AW,工资明细!BM:BM,$F$1,工资明细!H:H,A6,工资明细!I:I,B6,工资明细!J:J,C6) -> 0 | N6: =SUMIFS(工资明细!AX:AX,工资明细!BM:BM,$F$1,工资明细!H:H,A6,工资明细!I:I,B6,工资明细!J:J,C6) -> 0
A7: 合计 | D7: =SUM(D6:D6) -> 0 | E7: =SUM(E6:E6) -> 0 | F7: =SUM(F6:F6) -> 0 | G7: =SUM(G6:G6) -> 0 | H7: =SUM(H6:H6) -> 0 | I7: =SUM(I6:I6) -> 0 | J7: =SUM(J6:J6) -> 0 | K7: =SUM(K6:K6) -> 0 | ... N7: =SUM(N6:N6) -> 0
A9: 公积金缴纳汇总表
A10: 一级部门 | B10: 二级部门 | C10: 三级部门 | D10: 人数 | E10: 企业缴纳 | F10: 个人缴纳 | G10: 合计
D11: 人数 | E11: 金额 | F11: 金额
A12: 市场部 | B12: 市场推广部 | C12: 成都区域 | D12: =COUNTIFS(工资明细!BM:BM,$F$1,工资明细!H:H,A12,工资明细!I:I,B12,工资明细!J:J,C12) -> 0 | E12: =SUMIFS(工资明细!BE:BE,工资明细!BM:BM,$F$1,工资明细!H:H,A12,工资明细!I:I,B12,工资明细!J:J,C12) -> 0 | F12: =SUMIFS(工资明细!AT:AT,工资明细!BM:BM,$F$1,工资明细!H:H,A12,工资明细!I:I,B12,工资明细!J:J,C12) -> 0 | G12: =SUM(E12:F12) -> 0
A13: 合计 | D13: =SUM(D12:D12) -> 0 | E13: =SUM(E12:E12) -> 0 | F13: =SUM(F12:F12) -> 0 | G13: =SUM(G12:G12) -> 0
A15: 社保缴纳汇总表
A16: 一级部门 | B16: 二级部门 | C16: 三级部门 | D16: 人数 | E16: 养老单位 | F16: 医疗单位 | G16: 失业单位 | H16: 工伤单位 | I16: 生育单位 | J16: 企业部分 | K16: 个人部分 | L16: 合计
E17: 金额 | F17: 金额 | G17: 金额 | H17: 金额 | I17: 金额 | J17: 金额 | K17: 金额
A18: 市场部 | B18: 市场推广部 | C18: 成都区域 | D18: =COUNTIFS(工资明细!BM:BM,$F$1,工资明细!H:H,A18,工资明细!I:I,B18,工资明细!J:J,C18) -> 0 | E18: =SUMIFS(工资明细!AY:AY,工资明细!BM:BM,$F$1,工资明细!H:H,A18,工资明细!I:I,B18,工资明细!J:J,C18) -> 0 | F18: =SUMIFS(工资明细!AZ:AZ,工资明细!BM:BM,$F$1,工资明细!H:H,A18,工资明细!I:I,B18,工资明细!J:J,C18) -> 0 | G18: =SUMIFS(工资明细!BA:BA,工资明细!BM:BM,$F$1,工资明细!H:H,A18,工资明细!I:I,B18,工资明细!J:J,C18) -> 0 | H18: =SUMIFS(工资明细!BB:BB,工资明细!BM:BM,$F$1,工资明细!H:H,A18,工资明细!I:I,B18,工资明细!J:J,C18) -> 0 | I18: =SUMIFS(工资明细!BC:BC,工资明细!BM:BM,$F$1,工资明细!H:H,A18,工资明细!I:I,B18,工资明细!J:J,C18) -> 0 | J18: =SUM(E18:I18) -> 0 | K18: =SUMIFS(工资明细!AS:AS,工资明细!BM:BM,$F$1,工资明细!H:H,A18,工资明细!I:I,B18,工资明细!J:J,C18) -> 0 | L18: =SUM(J18:K18) -> 0
A19: 合计 | D19: =SUM(D18:D18) -> 0 | E19: =SUM(E18:E18) -> 0 | F19: =SUM(F18:F18) -> 0 | G19: =SUM(G18:G18) -> 0 | H19: =SUM(H18:H18) -> 0 | I19: =SUM(I18:I18) -> 0 | J19: =SUM(J18:J18) -> 0 | K19: =SUM(K18:K18) -> 0 | L19: =SUM(L18:L18) -> 0

Sheet 杭州人力成本
A1: 日期： | B1: =北分人力成本!B1 -> 46204 | E1: 公司名称： | F1: 六棱镜（杭州）科技有限公司
A3: 员工工资及代扣代缴费用汇总表
A4: 一级部门 | B4: 二级部门 | C4: 三级部门 | D4: 人数 | E4: 应发工资 | F4: 养老个人 | G4: 医疗个人 | H4: 失业个人 | I4: 社保个人扣款 | J4: 住房公积金 | K4: 个税 | L4: 税后补款 | M4: 税后扣款 | N4: 实发工资
E5: 金额 | F5: 金额 | G5: 金额 | H5: 金额 | I5: 金额 | J5: 金额 | K5: 金额 | L5: 金额 | M5: 金额 | N5: 金额
A6: 刘洋 | D6: =COUNTIFS(工资明细!BM:BM,$F$1,工资明细!H:H,A6,工资明细!I:I,B6,工资明细!J:J,C6) -> 0 | E6: =SUMIFS(工资明细!AO:AO,工资明细!BM:BM,$F$1,工资明细!H:H,A6,工资明细!I:I,B6,工资明细!J:J,C6) -> 0 | F6: =SUMIFS(工资明细!AP:AP,工资明细!BM:BM,$F$1,工资明细!H:H,A6,工资明细!I:I,B6,工资明细!J:J,C6) -> 0 | G6: =SUMIFS(工资明细!AQ:AQ,工资明细!BM:BM,$F$1,工资明细!H:H,A6,工资明细!I:I,B6,工资明细!J:J,C6) -> 0 | H6: =SUMIFS(工资明细!AR:AR,工资明细!BM:BM,$F$1,工资明细!H:H,A6,工资明细!I:I,B6,工资明细!J:J,C6) -> 0 | I6: =F6+G6+H6 -> 0 | J6: =SUMIFS(工资明细!AT:AT,工资明细!BM:BM,$F$1,工资明细!H:H,A6,工资明细!I:I,B6,工资明细!J:J,C6) -> 0 | K6: =SUMIFS(工资明细!AU:AU,工资明细!BM:BM,$F$1,工资明细!H:H,A6,工资明细!I:I,B6,工资明细!J:J,C6) -> 0 | L6: =SUMIFS(工资明细!AV:AV,工资明细!BM:BM,$F$1,工资明细!H:H,A6,工资明细!I:I,B6,工资明细!J:J,C6) -> 0 | M6: =SUMIFS(工资明细!AW:AW,工资明细!BM:BM,$F$1,工资明细!H:H,A6,工资明细!I:I,B6,工资明细!J:J,C6) -> 0 | N6: =SUMIFS(工资明细!AX:AX,工资明细!BM:BM,$F$1,工资明细!H:H,A6,工资明细!I:I,B6,工资明细!J:J,C6) -> 0
A7: 耿德强 | D7: =COUNTIFS(工资明细!BM:BM,$F$1,工资明细!H:H,A7,工资明细!I:I,B7,工资明细!J:J,C7) -> 0 | E7: =SUMIFS(工资明细!AO:AO,工资明细!BM:BM,$F$1,工资明细!H:H,A7,工资明细!I:I,B7,工资明细!J:J,C7) -> 0 | F7: =SUMIFS(工资明细!AP:AP,工资明细!BM:BM,$F$1,工资明细!H:H,A7,工资明细!I:I,B7,工资明细!J:J,C7) -> 0 | G7: =SUMIFS(工资明细!AQ:AQ,工资明细!BM:BM,$F$1,工资明细!H:H,A7,工资明细!I:I,B7,工资明细!J:J,C7) -> 0 | H7: =SUMIFS(工资明细!AR:AR,工资明细!BM:BM,$F$1,工资明细!H:H,A7,工资明细!I:I,B7,工资明细!J:J,C7) -> 0 | I7: =F7+G7+H7 -> 0 | J7: =SUMIFS(工资明细!AT:AT,工资明细!BM:BM,$F$1,工资明细!H:H,A7,工资明细!I:I,B7,工资明细!J:J,C7) -> 0 | K7: =SUMIFS(工资明细!AU:AU,工资明细!BM:BM,$F$1,工资明细!H:H,A7,工资明细!I:I,B7,工资明细!J:J,C7) -> 0 | L7: =SUMIFS(工资明细!AV:AV,工资明细!BM:BM,$F$1,工资明细!H:H,A7,工资明细!I:I,B7,工资明细!J:J,C7) -> 0 | M7: =SUMIFS(工资明细!AW:AW,工资明细!BM:BM,$F$1,工资明细!H:H,A7,工资明细!I:I,B7,工资明细!J:J,C7) -> 0 | N7: =SUMIFS(工资明细!AX:AX,工资明细!BM:BM,$F$1,工资明细!H:H,A7,工资明细!I:I,B7,工资明细!J:J,C7) -> 0
A8: 总经理办公室 | B8: 财务部 | D8: =COUNTIFS(工资明细!BM:BM,$F$1,工资明细!H:H,A8,工资明细!I:I,B8,工资明细!J:J,C8) -> 0 | E8: =SUMIFS(工资明细!AO:AO,工资明细!BM:BM,$F$1,工资明细!H:H,A8,工资明细!I:I,B8,工资明细!J:J,C8) -> 0 | F8: =SUMIFS(工资明细!AP:AP,工资明细!BM:BM,$F$1,工资明细!H:H,A8,工资明细!I:I,B8,工资明细!J:J,C8) -> 0 | G8: =SUMIFS(工资明细!AQ:AQ,工资明细!BM:BM,$F$1,工资明细!H:H,A8,工资明细!I:I,B8,工资明细!J:J,C8) -> 0 | H8: =SUMIFS(工资明细!AR:AR,工资明细!BM:BM,$F$1,工资明细!H:H,A8,工资明细!I:I,B8,工资明细!J:J,C8) -> 0 | I8: =F8+G8+H8 -> 0 | J8: =SUMIFS(工资明细!AT:AT,工资明细!BM:BM,$F$1,工资明细!H:H,A8,工资明细!I:I,B8,工资明细!J:J,C8) -> 0 | K8: =SUMIFS(工资明细!AU:AU,工资明细!BM:BM,$F$1,工资明细!H:H,A8,工资明细!I:I,B8,工资明细!J:J,C8) -> 0 | L8: =SUMIFS(工资明细!AV:AV,工资明细!BM:BM,$F$1,工资明细!H:H,A8,工资明细!I:I,B8,工资明细!J:J,C8) -> 0 | M8: =SUMIFS(工资明细!AW:AW,工资明细!BM:BM,$F$1,工资明细!H:H,A8,工资明细!I:I,B8,工资明细!J:J,C8) -> 0 | N8: =SUMIFS(工资明细!AX:AX,工资明细!BM:BM,$F$1,工资明细!H:H,A8,工资明细!I:I,B8,工资明细!J:J,C8) -> 0
A9: 总经理办公室 | B9: 人力资源部 | D9: =COUNTIFS(工资明细!BM:BM,$F$1,工资明细!H:H,A9,工资明细!I:I,B9,工资明细!J:J,C9) -> 0 | E9: =SUMIFS(工资明细!AO:AO,工资明细!BM:BM,$F$1,工资明细!H:H,A9,工资明细!I:I,B9,工资明细!J:J,C9) -> 0 | F9: =SUMIFS(工资明细!AP:AP,工资明细!BM:BM,$F$1,工资明细!H:H,A9,工资明细!I:I,B9,工资明细!J:J,C9) -> 0 | G9: =SUMIFS(工资明细!AQ:AQ,工资明细!BM:BM,$F$1,工资明细!H:H,A9,工资明细!I:I,B9,工资明细!J:J,C9) -> 0 | H9: =SUMIFS(工资明细!AR:AR,工资明细!BM:BM,$F$1,工资明细!H:H,A9,工资明细!I:I,B9,工资明细!J:J,C9) -> 0 | I9: =F9+G9+H9 -> 0 | J9: =SUMIFS(工资明细!AT:AT,工资明细!BM:BM,$F$1,工资明细!H:H,A9,工资明细!I:I,B9,工资明细!J:J,C9) -> 0 | K9: =SUMIFS(工资明细!AU:AU,工资明细!BM:BM,$F$1,工资明细!H:H,A9,工资明细!I:I,B9,工资明细!J:J,C9) -> 0 | L9: =SUMIFS(工资明细!AV:AV,工资明细!BM:BM,$F$1,工资明细!H:H,A9,工资明细!I:I,B9,工资明细!J:J,C9) -> 0 | M9: =SUMIFS(工资明细!AW:AW,工资明细!BM:BM,$F$1,工资明细!H:H,A9,工资明细!I:I,B9,工资明细!J:J,C9) -> 0 | N9: =SUMIFS(工资明细!AX:AX,工资明细!BM:BM,$F$1,工资明细!H:H,A9,工资明细!I:I,B9,工资明细!J:J,C9) -> 0
A10: 总经理办公室 | B10: 综合部 | C10: 杭州综合部 | D10: =COUNTIFS(工资明细!BM:BM,$F$1,工资明细!H:H,A10,工资明细!I:I,B10,工资明细!J:J,C10) -> 0 | E10: =SUMIFS(工资明细!AO:AO,工资明细!BM:BM,$F$1,工资明细!H:H,A10,工资明细!I:I,B10,工资明细!J:J,C10) -> 0 | F10: =SUMIFS(工资明细!AP:AP,工资明细!BM:BM,$F$1,工资明细!H:H,A10,工资明细!I:I,B10,工资明细!J:J,C10) -> 0 | G10: =SUMIFS(工资明细!AQ:AQ,工资明细!BM:BM,$F$1,工资明细!H:H,A10,工资明细!I:I,B10,工资明细!J:J,C10) -> 0 | H10: =SUMIFS(工资明细!AR:AR,工资明细!BM:BM,$F$1,工资明细!H:H,A10,工资明细!I:I,B10,工资明细!J:J,C10) -> 0 | I10: =F10+G10+H10 -> 0 | J10: =SUMIFS(工资明细!AT:AT,工资明细!BM:BM,$F$1,工资明细!H:H,A10,工资明细!I:I,B10,工资明细!J:J,C10) -> 0 | K10: =SUMIFS(工资明细!AU:AU,工资明细!BM:BM,$F$1,工资明细!H:H,A10,工资明细!I:I,B10,工资明细!J:J,C10) -> 0 | L10: =SUMIFS(工资明细!AV:AV,工资明细!BM:BM,$F$1,工资明细!H:H,A10,工资明细!I:I,B10,工资明细!J:J,C10) -> 0 | M10: =SUMIFS(工资明细!AW:AW,工资明细!BM:BM,$F$1,工资明细!H:H,A10,工资明细!I:I,B10,工资明细!J:J,C10) -> 0 | N10: =SUMIFS(工资明细!AX:AX,工资明细!BM:BM,$F$1,工资明细!H:H,A10,工资明细!I:I,B10,工资明细!J:J,C10) -> 0
A11: 市场部 | B11: 市场推广部 | C11: 杭州区域 | D11: =COUNTIFS(工资明细!BM:BM,$F$1,工资明细!H:H,A11,工资明细!I:I,B11,工资明细!J:J,C11) -> 0 | E11: =SUMIFS(工资明细!AO:AO,工资明细!BM:BM,$F$1,工资明细!H:H,A11,工资明细!I:I,B11,工资明细!J:J,C11) -> 0 | F11: =SUMIFS(工资明细!AP:AP,工资明细!BM:BM,$F$1,工资明细!H:H,A11,工资明细!I:I,B11,工资明细!J:J,C11) -> 0 | G11: =SUMIFS(工资明细!AQ:AQ,工资明细!BM:BM,$F$1,工资明细!H:H,A11,工资明细!I:I,B11,工资明细!J:J,C11) -> 0 | H11: =SUMIFS(工资明细!AR:AR,工资明细!BM:BM,$F$1,工资明细!H:H,A11,工资明细!I:I,B11,工资明细!J:J,C11) -> 0 | I11: =F11+G11+H11 -> 0 | J11: =SUMIFS(工资明细!AT:AT,工资明细!BM:BM,$F$1,工资明细!H:H,A11,工资明细!I:I,B11,工资明细!J:J,C11) -> 0 | K11: =SUMIFS(工资明细!AU:AU,工资明细!BM:BM,$F$1,工资明细!H:H,A11,工资明细!I:I,B11,工资明细!J:J,C11) -> 0 | L11: =SUMIFS(工资明细!AV:AV,工资明细!BM:BM,$F$1,工资明细!H:H,A11,工资明细!I:I,B11,工资明细!J:J,C11) -> 0 | M11: =SUMIFS(工资明细!AW:AW,工资明细!BM:BM,$F$1,工资明细!H:H,A11,工资明细!I:I,B11,工资明细!J:J,C11) -> 0 | N11: =SUMIFS(工资明细!AX:AX,工资明细!BM:BM,$F$1,工资明细!H:H,A11,工资明细!I:I,B11,工资明细!J:J,C11) -> 0
A12: 市场部 | B12: 战略规划部 | C12: 泉州区域 | D12: =COUNTIFS(工资明细!BM:BM,$F$1,工资明细!H:H,A12,工资明细!I:I,B12,工资明细!J:J,C12) -> 0 | E12: =SUMIFS(工资明细!AO:AO,工资明细!BM:BM,$F$1,工资明细!H:H,A12,工资明细!I:I,B12,工资明细!J:J,C12) -> 0 | F12: =SUMIFS(工资明细!AP:AP,工资明细!BM:BM,$F$1,工资明细!H:H,A12,工资明细!I:I,B12,工资明细!J:J,C12) -> 0 | G12: =SUMIFS(工资明细!AQ:AQ,工资明细!BM:BM,$F$1,工资明细!H:H,A12,工资明细!I:I,B12,工资明细!J:J,C12) -> 0 | H12: =SUMIFS(工资明细!AR:AR,工资明细!BM:BM,$F$1,工资明细!H:H,A12,工资明细!I:I,B12,工资明细!J:J,C12) -> 0 | I12: =F12+G12+H12 -> 0 | J12: =SUMIFS(工资明细!AT:AT,工资明细!BM:BM,$F$1,工资明细!H:H,A12,工资明细!I:I,B12,工资明细!J:J,C12) -> 0 | K12: =SUMIFS(工资明细!AU:AU,工资明细!BM:BM,$F$1,工资明细!H:H,A12,工资明细!I:I,B12,工资明细!J:J,C12) -> 0 | L12: =SUMIFS(工资明细!AV:AV,工资明细!BM:BM,$F$1,工资明细!H:H,A12,工资明细!I:I,B12,工资明细!J:J,C12) -> 0 | M12: =SUMIFS(工资明细!AW:AW,工资明细!BM:BM,$F$1,工资明细!H:H,A12,工资明细!I:I,B12,工资明细!J:J,C12) -> 0 | N12: =SUMIFS(工资明细!AX:AX,工资明细!BM:BM,$F$1,工资明细!H:H,A12,工资明细!I:I,B12,工资明细!J:J,C12) -> 0
A13: 市场部 | B13: 战略规划部 | C13: 0 | D13: =COUNTIFS(工资明细!BM:BM,$F$1,工资明细!H:H,A13,工资明细!I:I,B13,工资明细!J:J,C13) -> 0 | E13: =SUMIFS(工资明细!AO:AO,工资明细!BM:BM,$F$1,工资明细!H:H,A13,工资明细!I:I,B13,工资明细!J:J,C13) -> 0 | F13: =SUMIFS(工资明细!AP:AP,工资明细!BM:BM,$F$1,工资明细!H:H,A13,工资明细!I:I,B13,工资明细!J:J,C13) -> 0 | G13: =SUMIFS(工资明细!AQ:AQ,工资明细!BM:BM,$F$1,工资明细!H:H,A13,工资明细!I:I,B13,工资明细!J:J,C13) -> 0 | H13: =SUMIFS(工资明细!AR:AR,工资明细!BM:BM,$F$1,工资明细!H:H,A13,工资明细!I:I,B13,工资明细!J:J,C13) -> 0 | I13: =F13+G13+H13 -> 0 | J13: =SUMIFS(工资明细!AT:AT,工资明细!BM:BM,$F$1,工资明细!H:H,A13,工资明细!I:I,B13,工资明细!J:J,C13) -> 0 | K13: =SUMIFS(工资明细!AU:AU,工资明细!BM:BM,$F$1,工资明细!H:H,A13,工资明细!I:I,B13,工资明细!J:J,C13) -> 0 | L13: =SUMIFS(工资明细!AV:AV,工资明细!BM:BM,$F$1,工资明细!H:H,A13,工资明细!I:I,B13,工资明细!J:J,C13) -> 0 | M13: =SUMIFS(工资明细!AW:AW,工资明细!BM:BM,$F$1,工资明细!H:H,A13,工资明细!I:I,B13,工资明细!J:J,C13) -> 0 | N13: =SUMIFS(工资明细!AX:AX,工资明细!BM:BM,$F$1,工资明细!H:H,A13,工资明细!I:I,B13,工资明细!J:J,C13) -> 0
A14: 技术研发事业部 | B14: 产品研发部 | C14: 项目组 | D14: =COUNTIFS(工资明细!BM:BM,$F$1,工资明细!H:H,A14,工资明细!I:I,B14,工资明细!J:J,C14) -> 0 | E14: =SUMIFS(工资明细!AO:AO,工资明细!BM:BM,$F$1,工资明细!H:H,A14,工资明细!I:I,B14,工资明细!J:J,C14) -> 0 | F14: =SUMIFS(工资明细!AP:AP,工资明细!BM:BM,$F$1,工资明细!H:H,A14,工资明细!I:I,B14,工资明细!J:J,C14) -> 0 | G14: =SUMIFS(工资明细!AQ:AQ,工资明细!BM:BM,$F$1,工资明细!H:H,A14,工资明细!I:I,B14,工资明细!J:J,C14) -> 0 | H14: =SUMIFS(工资明细!AR:AR,工资明细!BM:BM,$F$1,工资明细!H:H,A14,工资明细!I:I,B14,工资明细!J:J,C14) -> 0 | I14: =F14+G14+H14 -> 0 | J14: =SUMIFS(工资明细!AT:AT,工资明细!BM:BM,$F$1,工资明细!H:H,A14,工资明细!I:I,B14,工资明细!J:J,C14) -> 0 | K14: =SUMIFS(工资明细!AU:AU,工资明细!BM:BM,$F$1,工资明细!H:H,A14,工资明细!I:I,B14,工资明细!J:J,C14) -> 0 | L14: =SUMIFS(工资明细!AV:AV,工资明细!BM:BM,$F$1,工资明细!H:H,A14,工资明细!I:I,B14,工资明细!J:J,C14) -> 0 | M14: =SUMIFS(工资明细!AW:AW,工资明细!BM:BM,$F$1,工资明细!H:H,A14,工资明细!I:I,B14,工资明细!J:J,C14) -> 0 | N14: =SUMIFS(工资明细!AX:AX,工资明细!BM:BM,$F$1,工资明细!H:H,A14,工资明细!I:I,B14,工资明细!J:J,C14) -> 0
A15: 合计 | D15: =SUM(D6:D14) -> 0 | E15: =SUM(E6:E14) -> 0 | F15: =SUM(F6:F14) -> 0 | G15: =SUM(G6:G14) -> 0 | H15: =SUM(H6:H14) -> 0 | I15: =SUM(I6:I14) -> 0 | J15: =SUM(J6:J14) -> 0 | K15: =SUM(K6:K14) -> 0 | ... N15: =SUM(N6:N14) -> 0
A17: 公积金缴纳汇总表
A18: 一级部门 | B18: 二级部门 | C18: 三级部门 | D18: 人数 | E18: 企业缴纳 | F18: 个人缴纳 | G18: 合计
E19: 金额 | F19: 金额
A20: 刘洋 | D20: =COUNTIFS(工资明细!BM:BM,$F$1,工资明细!H:H,A20,工资明细!I:I,B20,工资明细!J:J,C20) -> 0 | E20: =SUMIFS(工资明细!BE:BE,工资明细!BM:BM,$F$1,工资明细!H:H,A20,工资明细!I:I,B20,工资明细!J:J,C20) -> 0 | F20: =SUMIFS(工资明细!AT:AT,工资明细!BM:BM,$F$1,工资明细!H:H,A20,工资明细!I:I,B20,工资明细!J:J,C20) -> 0 | G20: =SUM(E20:F20) -> 0
A21: 耿德强 | D21: =COUNTIFS(工资明细!BM:BM,$F$1,工资明细!H:H,A21,工资明细!I:I,B21,工资明细!J:J,C21) -> 0 | E21: =SUMIFS(工资明细!BE:BE,工资明细!BM:BM,$F$1,工资明细!H:H,A21,工资明细!I:I,B21,工资明细!J:J,C21) -> 0 | F21: =SUMIFS(工资明细!AT:AT,工资明细!BM:BM,$F$1,工资明细!H:H,A21,工资明细!I:I,B21,工资明细!J:J,C21) -> 0 | G21: =SUM(E21:F21) -> 0
A22: 总经理办公室 | B22: 财务部 | D22: =COUNTIFS(工资明细!BM:BM,$F$1,工资明细!H:H,A22,工资明细!I:I,B22,工资明细!J:J,C22) -> 0 | E22: =SUMIFS(工资明细!BE:BE,工资明细!BM:BM,$F$1,工资明细!H:H,A22,工资明细!I:I,B22,工资明细!J:J,C22) -> 0 | F22: =SUMIFS(工资明细!AT:AT,工资明细!BM:BM,$F$1,工资明细!H:H,A22,工资明细!I:I,B22,工资明细!J:J,C22) -> 0 | G22: =SUM(E22:F22) -> 0
A23: 总经理办公室 | B23: 人力资源部 | D23: =COUNTIFS(工资明细!BM:BM,$F$1,工资明细!H:H,A23,工资明细!I:I,B23,工资明细!J:J,C23) -> 0 | E23: =SUMIFS(工资明细!BE:BE,工资明细!BM:BM,$F$1,工资明细!H:H,A23,工资明细!I:I,B23,工资明细!J:J,C23) -> 0 | F23: =SUMIFS(工资明细!AT:AT,工资明细!BM:BM,$F$1,工资明细!H:H,A23,工资明细!I:I,B23,工资明细!J:J,C23) -> 0 | G23: =SUM(E23:F23) -> 0
A24: 总经理办公室 | B24: 综合部 | C24: 杭州综合部 | D24: =COUNTIFS(工资明细!BM:BM,$F$1,工资明细!H:H,A24,工资明细!I:I,B24,工资明细!J:J,C24) -> 0 | E24: =SUMIFS(工资明细!BE:BE,工资明细!BM:BM,$F$1,工资明细!H:H,A24,工资明细!I:I,B24,工资明细!J:J,C24) -> 0 | F24: =SUMIFS(工资明细!AT:AT,工资明细!BM:BM,$F$1,工资明细!H:H,A24,工资明细!I:I,B24,工资明细!J:J,C24) -> 0 | G24: =SUM(E24:F24) -> 0
A25: 市场部 | B25: 市场推广部 | C25: 杭州区域 | D25: =COUNTIFS(工资明细!BM:BM,$F$1,工资明细!H:H,A25,工资明细!I:I,B25,工资明细!J:J,C25) -> 0 | E25: =SUMIFS(工资明细!BE:BE,工资明细!BM:BM,$F$1,工资明细!H:H,A25,工资明细!I:I,B25,工资明细!J:J,C25) -> 0 | F25: =SUMIFS(工资明细!AT:AT,工资明细!BM:BM,$F$1,工资明细!H:H,A25,工资明细!I:I,B25,工资明细!J:J,C25) -> 0 | G25: =SUM(E25:F25) -> 0
A26: 市场部 | B26: 战略规划部 | C26: 泉州区域 | D26: =COUNTIFS(工资明细!BM:BM,$F$1,工资明细!H:H,A26,工资明细!I:I,B26,工资明细!J:J,C26) -> 0 | E26: =SUMIFS(工资明细!BE:BE,工资明细!BM:BM,$F$1,工资明细!H:H,A26,工资明细!I:I,B26,工资明细!J:J,C26) -> 0 | F26: =SUMIFS(工资明细!AT:AT,工资明细!BM:BM,$F$1,工资明细!H:H,A26,工资明细!I:I,B26,工资明细!J:J,C26) -> 0 | G26: =SUM(E26:F26) -> 0
A27: 市场部 | B27: 战略规划部 | C27: 0 | D27: =COUNTIFS(工资明细!BM:BM,$F$1,工资明细!H:H,A27,工资明细!I:I,B27,工资明细!J:J,C27) -> 0 | E27: =SUMIFS(工资明细!BE:BE,工资明细!BM:BM,$F$1,工资明细!H:H,A27,工资明细!I:I,B27,工资明细!J:J,C27) -> 0 | F27: =SUMIFS(工资明细!AT:AT,工资明细!BM:BM,$F$1,工资明细!H:H,A27,工资明细!I:I,B27,工资明细!J:J,C27) -> 0 | G27: =SUM(E27:F27) -> 0
A28: 技术研发事业部 | B28: 产品研发部 | C28: 项目组 | D28: =COUNTIFS(工资明细!BM:BM,$F$1,工资明细!H:H,A28,工资明细!I:I,B28,工资明细!J:J,C28) -> 0 | E28: =SUMIFS(工资明细!BE:BE,工资明细!BM:BM,$F$1,工资明细!H:H,A28,工资明细!I:I,B28,工资明细!J:J,C28) -> 0 | F28: =SUMIFS(工资明细!AT:AT,工资明细!BM:BM,$F$1,工资明细!H:H,A28,工资明细!I:I,B28,工资明细!J:J,C28) -> 0 | G28: =SUM(E28:F28) -> 0
A29: 合计 | D29: =SUM(D20:D28) -> 0 | E29: =SUM(E20:E28) -> 0 | F29: =SUM(F20:F28) -> 0 | G29: =SUM(G20:G28) -> 0
A31: 社保缴纳汇总表
A32: 一级部门 | B32: 二级部门 | C32: 三级部门 | D32: 人数 | E32: 养老单位 | F32: 医疗单位 | G32: 失业单位 | H32: 工伤单位 | I32: 生育单位 | J32: 企业部分 | K32: 个人部分 | L32: 合计
E33: 金额 | F33: 金额 | G33: 金额 | H33: 金额 | I33: 金额 | J33: 金额 | K33: 金额
A34: 刘洋 | D34: =COUNTIFS(工资明细!BM:BM,$F$1,工资明细!H:H,A34,工资明细!I:I,B34,工资明细!J:J,C34) -> 0 | E34: =SUMIFS(工资明细!AY:AY,工资明细!BM:BM,$F$1,工资明细!H:H,A34,工资明细!I:I,B34,工资明细!J:J,C34) -> 0 | F34: =SUMIFS(工资明细!AZ:AZ,工资明细!BM:BM,$F$1,工资明细!H:H,A34,工资明细!I:I,B34,工资明细!J:J,C34) -> 0 | G34: =SUMIFS(工资明细!BA:BA,工资明细!BM:BM,$F$1,工资明细!H:H,A34,工资明细!I:I,B34,工资明细!J:J,C34) -> 0 | H34: =SUMIFS(工资明细!BB:BB,工资明细!BM:BM,$F$1,工资明细!H:H,A34,工资明细!I:I,B34,工资明细!J:J,C34) -> 0 | I34: =SUMIFS(工资明细!BC:BC,工资明细!BM:BM,$F$1,工资明细!H:H,A34,工资明细!I:I,B34,工资明细!J:J,C34) -> 0 | J34: =SUM(E34:I34) -> 0 | K34: =SUMIFS(工资明细!AS:AS,工资明细!BM:BM,$F$1,工资明细!H:H,A34,工资明细!I:I,B34,工资明细!J:J,C34) -> 0 | L34: =SUM(J34:K34) -> 0
A35: 耿德强 | D35: =COUNTIFS(工资明细!BM:BM,$F$1,工资明细!H:H,A35,工资明细!I:I,B35,工资明细!J:J,C35) -> 0 | E35: =SUMIFS(工资明细!AY:AY,工资明细!BM:BM,$F$1,工资明细!H:H,A35,工资明细!I:I,B35,工资明细!J:J,C35) -> 0 | F35: =SUMIFS(工资明细!AZ:AZ,工资明细!BM:BM,$F$1,工资明细!H:H,A35,工资明细!I:I,B35,工资明细!J:J,C35) -> 0 | G35: =SUMIFS(工资明细!BA:BA,工资明细!BM:BM,$F$1,工资明细!H:H,A35,工资明细!I:I,B35,工资明细!J:J,C35) -> 0 | H35: =SUMIFS(工资明细!BB:BB,工资明细!BM:BM,$F$1,工资明细!H:H,A35,工资明细!I:I,B35,工资明细!J:J,C35) -> 0 | I35: =SUMIFS(工资明细!BC:BC,工资明细!BM:BM,$F$1,工资明细!H:H,A35,工资明细!I:I,B35,工资明细!J:J,C35) -> 0 | J35: =SUM(E35:I35) -> 0 | K35: =SUMIFS(工资明细!AS:AS,工资明细!BM:BM,$F$1,工资明细!H:H,A35,工资明细!I:I,B35,工资明细!J:J,C35) -> 0 | L35: =SUM(J35:K35) -> 0
A36: 总经理办公室 | B36: 财务部 | D36: =COUNTIFS(工资明细!BM:BM,$F$1,工资明细!H:H,A36,工资明细!I:I,B36,工资明细!J:J,C36) -> 0 | E36: =SUMIFS(工资明细!AY:AY,工资明细!BM:BM,$F$1,工资明细!H:H,A36,工资明细!I:I,B36,工资明细!J:J,C36) -> 0 | F36: =SUMIFS(工资明细!AZ:AZ,工资明细!BM:BM,$F$1,工资明细!H:H,A36,工资明细!I:I,B36,工资明细!J:J,C36) -> 0 | G36: =SUMIFS(工资明细!BA:BA,工资明细!BM:BM,$F$1,工资明细!H:H,A36,工资明细!I:I,B36,工资明细!J:J,C36) -> 0 | H36: =SUMIFS(工资明细!BB:BB,工资明细!BM:BM,$F$1,工资明细!H:H,A36,工资明细!I:I,B36,工资明细!J:J,C36) -> 0 | I36: =SUMIFS(工资明细!BC:BC,工资明细!BM:BM,$F$1,工资明细!H:H,A36,工资明细!I:I,B36,工资明细!J:J,C36) -> 0 | J36: =SUM(E36:I36) -> 0 | K36: =SUMIFS(工资明细!AS:AS,工资明细!BM:BM,$F$1,工资明细!H:H,A36,工资明细!I:I,B36,工资明细!J:J,C36) -> 0 | L36: =SUM(J36:K36) -> 0
A37: 总经理办公室 | B37: 人力资源部 | D37: =COUNTIFS(工资明细!BM:BM,$F$1,工资明细!H:H,A37,工资明细!I:I,B37,工资明细!J:J,C37) -> 0 | E37: =SUMIFS(工资明细!AY:AY,工资明细!BM:BM,$F$1,工资明细!H:H,A37,工资明细!I:I,B37,工资明细!J:J,C37) -> 0 | F37: =SUMIFS(工资明细!AZ:AZ,工资明细!BM:BM,$F$1,工资明细!H:H,A37,工资明细!I:I,B37,工资明细!J:J,C37) -> 0 | G37: =SUMIFS(工资明细!BA:BA,工资明细!BM:BM,$F$1,工资明细!H:H,A37,工资明细!I:I,B37,工资明细!J:J,C37) -> 0 | H37: =SUMIFS(工资明细!BB:BB,工资明细!BM:BM,$F$1,工资明细!H:H,A37,工资明细!I:I,B37,工资明细!J:J,C37) -> 0 | I37: =SUMIFS(工资明细!BC:BC,工资明细!BM:BM,$F$1,工资明细!H:H,A37,工资明细!I:I,B37,工资明细!J:J,C37) -> 0 | J37: =SUM(E37:I37) -> 0 | K37: =SUMIFS(工资明细!AS:AS,工资明细!BM:BM,$F$1,工资明细!H:H,A37,工资明细!I:I,B37,工资明细!J:J,C37) -> 0 | L37: =SUM(J37:K37) -> 0
A38: 总经理办公室 | B38: 综合部 | C38: 杭州综合部 | D38: =COUNTIFS(工资明细!BM:BM,$F$1,工资明细!H:H,A38,工资明细!I:I,B38,工资明细!J:J,C38) -> 0 | E38: =SUMIFS(工资明细!AY:AY,工资明细!BM:BM,$F$1,工资明细!H:H,A38,工资明细!I:I,B38,工资明细!J:J,C38) -> 0 | F38: =SUMIFS(工资明细!AZ:AZ,工资明细!BM:BM,$F$1,工资明细!H:H,A38,工资明细!I:I,B38,工资明细!J:J,C38) -> 0 | G38: =SUMIFS(工资明细!BA:BA,工资明细!BM:BM,$F$1,工资明细!H:H,A38,工资明细!I:I,B38,工资明细!J:J,C38) -> 0 | H38: =SUMIFS(工资明细!BB:BB,工资明细!BM:BM,$F$1,工资明细!H:H,A38,工资明细!I:I,B38,工资明细!J:J,C38) -> 0 | I38: =SUMIFS(工资明细!BC:BC,工资明细!BM:BM,$F$1,工资明细!H:H,A38,工资明细!I:I,B38,工资明细!J:J,C38) -> 0 | J38: =SUM(E38:I38) -> 0 | K38: =SUMIFS(工资明细!AS:AS,工资明细!BM:BM,$F$1,工资明细!H:H,A38,工资明细!I:I,B38,工资明细!J:J,C38) -> 0 | L38: =SUM(J38:K38) -> 0
A39: 市场部 | B39: 市场推广部 | C39: 杭州区域 | D39: =COUNTIFS(工资明细!BM:BM,$F$1,工资明细!H:H,A39,工资明细!I:I,B39,工资明细!J:J,C39) -> 0 | E39: =SUMIFS(工资明细!AY:AY,工资明细!BM:BM,$F$1,工资明细!H:H,A39,工资明细!I:I,B39,工资明细!J:J,C39) -> 0 | F39: =SUMIFS(工资明细!AZ:AZ,工资明细!BM:BM,$F$1,工资明细!H:H,A39,工资明细!I:I,B39,工资明细!J:J,C39) -> 0 | G39: =SUMIFS(工资明细!BA:BA,工资明细!BM:BM,$F$1,工资明细!H:H,A39,工资明细!I:I,B39,工资明细!J:J,C39) -> 0 | H39: =SUMIFS(工资明细!BB:BB,工资明细!BM:BM,$F$1,工资明细!H:H,A39,工资明细!I:I,B39,工资明细!J:J,C39) -> 0 | I39: =SUMIFS(工资明细!BC:BC,工资明细!BM:BM,$F$1,工资明细!H:H,A39,工资明细!I:I,B39,工资明细!J:J,C39) -> 0 | J39: =SUM(E39:I39) -> 0 | K39: =SUMIFS(工资明细!AS:AS,工资明细!BM:BM,$F$1,工资明细!H:H,A39,工资明细!I:I,B39,工资明细!J:J,C39) -> 0 | L39: =SUM(J39:K39) -> 0
A40: 市场部 | B40: 战略规划部 | C40: 泉州区域 | D40: =COUNTIFS(工资明细!BM:BM,$F$1,工资明细!H:H,A40,工资明细!I:I,B40,工资明细!J:J,C40) -> 0 | E40: =SUMIFS(工资明细!AY:AY,工资明细!BM:BM,$F$1,工资明细!H:H,A40,工资明细!I:I,B40,工资明细!J:J,C40) -> 0 | F40: =SUMIFS(工资明细!AZ:AZ,工资明细!BM:BM,$F$1,工资明细!H:H,A40,工资明细!I:I,B40,工资明细!J:J,C40) -> 0 | G40: =SUMIFS(工资明细!BA:BA,工资明细!BM:BM,$F$1,工资明细!H:H,A40,工资明细!I:I,B40,工资明细!J:J,C40) -> 0 | H40: =SUMIFS(工资明细!BB:BB,工资明细!BM:BM,$F$1,工资明细!H:H,A40,工资明细!I:I,B40,工资明细!J:J,C40) -> 0 | I40: =SUMIFS(工资明细!BC:BC,工资明细!BM:BM,$F$1,工资明细!H:H,A40,工资明细!I:I,B40,工资明细!J:J,C40) -> 0 | J40: =SUM(E40:I40) -> 0 | K40: =SUMIFS(工资明细!AS:AS,工资明细!BM:BM,$F$1,工资明细!H:H,A40,工资明细!I:I,B40,工资明细!J:J,C40) -> 0 | L40: =SUM(J40:K40) -> 0
A41: 市场部 | B41: 战略规划部 | C41: 0 | D41: =COUNTIFS(工资明细!BM:BM,$F$1,工资明细!H:H,A41,工资明细!I:I,B41,工资明细!J:J,C41) -> 0 | E41: =SUMIFS(工资明细!AY:AY,工资明细!BM:BM,$F$1,工资明细!H:H,A41,工资明细!I:I,B41,工资明细!J:J,C41) -> 0 | F41: =SUMIFS(工资明细!AZ:AZ,工资明细!BM:BM,$F$1,工资明细!H:H,A41,工资明细!I:I,B41,工资明细!J:J,C41) -> 0 | G41: =SUMIFS(工资明细!BA:BA,工资明细!BM:BM,$F$1,工资明细!H:H,A41,工资明细!I:I,B41,工资明细!J:J,C41) -> 0 | H41: =SUMIFS(工资明细!BB:BB,工资明细!BM:BM,$F$1,工资明细!H:H,A41,工资明细!I:I,B41,工资明细!J:J,C41) -> 0 | I41: =SUMIFS(工资明细!BC:BC,工资明细!BM:BM,$F$1,工资明细!H:H,A41,工资明细!I:I,B41,工资明细!J:J,C41) -> 0 | J41: =SUM(E41:I41) -> 0 | K41: =SUMIFS(工资明细!AS:AS,工资明细!BM:BM,$F$1,工资明细!H:H,A41,工资明细!I:I,B41,工资明细!J:J,C41) -> 0 | L41: =SUM(J41:K41) -> 0
A42: 技术研发事业部 | B42: 产品研发部 | C42: 项目组 | D42: =COUNTIFS(工资明细!BM:BM,$F$1,工资明细!H:H,A42,工资明细!I:I,B42,工资明细!J:J,C42) -> 0 | E42: =SUMIFS(工资明细!AY:AY,工资明细!BM:BM,$F$1,工资明细!H:H,A42,工资明细!I:I,B42,工资明细!J:J,C42) -> 0 | F42: =SUMIFS(工资明细!AZ:AZ,工资明细!BM:BM,$F$1,工资明细!H:H,A42,工资明细!I:I,B42,工资明细!J:J,C42) -> 0 | G42: =SUMIFS(工资明细!BA:BA,工资明细!BM:BM,$F$1,工资明细!H:H,A42,工资明细!I:I,B42,工资明细!J:J,C42) -> 0 | H42: =SUMIFS(工资明细!BB:BB,工资明细!BM:BM,$F$1,工资明细!H:H,A42,工资明细!I:I,B42,工资明细!J:J,C42) -> 0 | I42: =SUMIFS(工资明细!BC:BC,工资明细!BM:BM,$F$1,工资明细!H:H,A42,工资明细!I:I,B42,工资明细!J:J,C42) -> 0 | J42: =SUM(E42:I42) -> 0 | K42: =SUMIFS(工资明细!AS:AS,工资明细!BM:BM,$F$1,工资明细!H:H,A42,工资明细!I:I,B42,工资明细!J:J,C42) -> 0 | L42: =SUM(J42:K42) -> 0
A43: 合计 | D43: =SUM(D34:D42) -> 0 | E43: =SUM(E34:E42) -> 0 | F43: =SUM(F34:F42) -> 0 | G43: =SUM(G34:G42) -> 0 | H43: =SUM(H34:H42) -> 0 | I43: =SUM(I34:I42) -> 0 | J43: =SUM(J34:J42) -> 0 | K43: =SUM(K34:K42) -> 0 | L43: =SUM(L34:L42) -> 0

Sheet 广东人力成本
A1: 日期： | B1: =北分人力成本!B1 -> 46204 | E1: 公司名称： | F1: 广东六棱镜数字科技发展有限公司
A3: 员工工资及代扣代缴费用汇总表
A4: 一级部门 | B4: 二级部门 | C4: 三级部门 | D4: 人数 | E4: 应发工资 | F4: 养老个人 | G4: 医疗个人 | H4: 失业个人 | I4: 社保个人扣款 | J4: 住房公积金 | K4: 个税 | L4: 税后补款 | M4: 税后扣款 | N4: 实发工资
E5: 金额 | F5: 金额 | G5: 金额 | H5: 金额 | I5: 金额 | J5: 金额 | K5: 金额 | L5: 金额 | M5: 金额 | N5: 金额
A6: 总经理办公室 | B6: 综合部 | C6: 深圳综合部 | D6: =COUNTIFS(工资明细!BM:BM,$F$1,工资明细!H:H,A6,工资明细!I:I,B6,工资明细!J:J,C6) -> 0 | E6: =SUMIFS(工资明细!AO:AO,工资明细!BM:BM,$F$1,工资明细!H:H,A6,工资明细!I:I,B6,工资明细!J:J,C6) -> 0 | F6: =SUMIFS(工资明细!AP:AP,工资明细!BM:BM,$F$1,工资明细!H:H,A6,工资明细!I:I,B6,工资明细!J:J,C6) -> 0 | G6: =SUMIFS(工资明细!AQ:AQ,工资明细!BM:BM,$F$1,工资明细!H:H,A6,工资明细!I:I,B6,工资明细!J:J,C6) -> 0 | H6: =SUMIFS(工资明细!AR:AR,工资明细!BM:BM,$F$1,工资明细!H:H,A6,工资明细!I:I,B6,工资明细!J:J,C6) -> 0 | I6: =F6+G6+H6 -> 0 | J6: =SUMIFS(工资明细!AT:AT,工资明细!BM:BM,$F$1,工资明细!H:H,A6,工资明细!I:I,B6,工资明细!J:J,C6) -> 0 | K6: =SUMIFS(工资明细!AU:AU,工资明细!BM:BM,$F$1,工资明细!H:H,A6,工资明细!I:I,B6,工资明细!J:J,C6) -> 0 | L6: =SUMIFS(工资明细!AV:AV,工资明细!BM:BM,$F$1,工资明细!H:H,A6,工资明细!I:I,B6,工资明细!J:J,C6) -> 0 | M6: =SUMIFS(工资明细!AW:AW,工资明细!BM:BM,$F$1,工资明细!H:H,A6,工资明细!I:I,B6,工资明细!J:J,C6) -> 0 | N6: =SUMIFS(工资明细!AX:AX,工资明细!BM:BM,$F$1,工资明细!H:H,A6,工资明细!I:I,B6,工资明细!J:J,C6) -> 0
A7: 市场部 | B7: 战略规划部 | C7: 深圳区域 | D7: =COUNTIFS(工资明细!BM:BM,$F$1,工资明细!H:H,A7,工资明细!I:I,B7,工资明细!J:J,C7) -> 0 | E7: =SUMIFS(工资明细!AO:AO,工资明细!BM:BM,$F$1,工资明细!H:H,A7,工资明细!I:I,B7,工资明细!J:J,C7) -> 0 | F7: =SUMIFS(工资明细!AP:AP,工资明细!BM:BM,$F$1,工资明细!H:H,A7,工资明细!I:I,B7,工资明细!J:J,C7) -> 0 | G7: =SUMIFS(工资明细!AQ:AQ,工资明细!BM:BM,$F$1,工资明细!H:H,A7,工资明细!I:I,B7,工资明细!J:J,C7) -> 0 | H7: =SUMIFS(工资明细!AR:AR,工资明细!BM:BM,$F$1,工资明细!H:H,A7,工资明细!I:I,B7,工资明细!J:J,C7) -> 0 | I7: =F7+G7+H7 -> 0 | J7: =SUMIFS(工资明细!AT:AT,工资明细!BM:BM,$F$1,工资明细!H:H,A7,工资明细!I:I,B7,工资明细!J:J,C7) -> 0 | K7: =SUMIFS(工资明细!AU:AU,工资明细!BM:BM,$F$1,工资明细!H:H,A7,工资明细!I:I,B7,工资明细!J:J,C7) -> 0 | L7: =SUMIFS(工资明细!AV:AV,工资明细!BM:BM,$F$1,工资明细!H:H,A7,工资明细!I:I,B7,工资明细!J:J,C7) -> 0 | M7: =SUMIFS(工资明细!AW:AW,工资明细!BM:BM,$F$1,工资明细!H:H,A7,工资明细!I:I,B7,工资明细!J:J,C7) -> 0 | N7: =SUMIFS(工资明细!AX:AX,工资明细!BM:BM,$F$1,工资明细!H:H,A7,工资明细!I:I,B7,工资明细!J:J,C7) -> 0
A8: 合计 | D8: =SUM(D6:D7) -> 0 | E8: =SUM(E6:E7) -> 0 | F8: =SUM(F6:F7) -> 0 | G8: =SUM(G6:G7) -> 0 | H8: =SUM(H6:H7) -> 0 | I8: =SUM(I6:I7) -> 0 | J8: =SUM(J6:J7) -> 0 | K8: =SUM(K6:K7) -> 0 | ... N8: =SUM(N6:N7) -> 0
A10: 公积金缴纳汇总表
A11: 一级部门 | B11: 二级部门 | C11: 三级部门 | D11: 人数 | E11: 企业缴纳 | F11: 个人缴纳 | G11: 合计
D12: 人数 | E12: 金额 | F12: 金额
A13: 总经理办公室 | B13: 综合部 | C13: 深圳综合部 | D13: =COUNTIFS(工资明细!BM:BM,$F$1,工资明细!H:H,A13,工资明细!I:I,B13,工资明细!J:J,C13) -> 0 | E13: =SUMIFS(工资明细!BE:BE,工资明细!BM:BM,$F$1,工资明细!H:H,A13,工资明细!I:I,B13,工资明细!J:J,C13) -> 0 | F13: =SUMIFS(工资明细!AT:AT,工资明细!BM:BM,$F$1,工资明细!H:H,A13,工资明细!I:I,B13,工资明细!J:J,C13) -> 0 | G13: =SUM(E13:F13) -> 0
A14: 市场部 | B14: 战略规划部 | C14: 深圳区域 | D14: =COUNTIFS(工资明细!BM:BM,$F$1,工资明细!H:H,A14,工资明细!I:I,B14,工资明细!J:J,C14) -> 0 | E14: =SUMIFS(工资明细!BE:BE,工资明细!BM:BM,$F$1,工资明细!H:H,A14,工资明细!I:I,B14,工资明细!J:J,C14) -> 0 | F14: =SUMIFS(工资明细!AT:AT,工资明细!BM:BM,$F$1,工资明细!H:H,A14,工资明细!I:I,B14,工资明细!J:J,C14) -> 0 | G14: =SUM(E14:F14) -> 0
A15: 合计 | D15: =SUM(D13:D14) -> 0 | E15: =SUM(E13:E14) -> 0 | F15: =SUM(F13:F14) -> 0 | G15: =SUM(G13:G14) -> 0
A17: 社保缴纳汇总表
A18: 一级部门 | B18: 二级部门 | C18: 三级部门 | D18: 人数 | E18: 养老单位 | F18: 医疗单位 | G18: 失业单位 | H18: 工伤单位 | I18: 生育单位 | J18: 企业部分 | K18: 个人部分 | L18: 合计
E19: 金额 | F19: 金额 | G19: 金额 | H19: 金额 | I19: 金额 | J19: 金额 | K19: 金额
A20: 总经理办公室 | B20: 综合部 | C20: 深圳综合部 | D20: =COUNTIFS(工资明细!BM:BM,$F$1,工资明细!H:H,A20,工资明细!I:I,B20,工资明细!J:J,C20) -> 0 | E20: =SUMIFS(工资明细!AY:AY,工资明细!BM:BM,$F$1,工资明细!H:H,A20,工资明细!I:I,B20,工资明细!J:J,C20) -> 0 | F20: =SUMIFS(工资明细!AZ:AZ,工资明细!BM:BM,$F$1,工资明细!H:H,A20,工资明细!I:I,B20,工资明细!J:J,C20) -> 0 | G20: =SUMIFS(工资明细!BA:BA,工资明细!BM:BM,$F$1,工资明细!H:H,A20,工资明细!I:I,B20,工资明细!J:J,C20) -> 0 | H20: =SUMIFS(工资明细!BB:BB,工资明细!BM:BM,$F$1,工资明细!H:H,A20,工资明细!I:I,B20,工资明细!J:J,C20) -> 0 | I20: =SUMIFS(工资明细!BC:BC,工资明细!BM:BM,$F$1,工资明细!H:H,A20,工资明细!I:I,B20,工资明细!J:J,C20) -> 0 | J20: =SUM(E20:I20) -> 0 | K20: =SUMIFS(工资明细!AS:AS,工资明细!BM:BM,$F$1,工资明细!H:H,A20,工资明细!I:I,B20,工资明细!J:J,C20) -> 0 | L20: =SUM(J20:K20) -> 0
A21: 市场部 | B21: 战略规划部 | C21: 深圳区域 | D21: =COUNTIFS(工资明细!BM:BM,$F$1,工资明细!H:H,A21,工资明细!I:I,B21,工资明细!J:J,C21) -> 0 | E21: =SUMIFS(工资明细!AY:AY,工资明细!BM:BM,$F$1,工资明细!H:H,A21,工资明细!I:I,B21,工资明细!J:J,C21) -> 0 | F21: =SUMIFS(工资明细!AZ:AZ,工资明细!BM:BM,$F$1,工资明细!H:H,A21,工资明细!I:I,B21,工资明细!J:J,C21) -> 0 | G21: =SUMIFS(工资明细!BA:BA,工资明细!BM:BM,$F$1,工资明细!H:H,A21,工资明细!I:I,B21,工资明细!J:J,C21) -> 0 | H21: =SUMIFS(工资明细!BB:BB,工资明细!BM:BM,$F$1,工资明细!H:H,A21,工资明细!I:I,B21,工资明细!J:J,C21) -> 0 | I21: =SUMIFS(工资明细!BC:BC,工资明细!BM:BM,$F$1,工资明细!H:H,A21,工资明细!I:I,B21,工资明细!J:J,C21) -> 0 | J21: =SUM(E21:I21) -> 0 | K21: =SUMIFS(工资明细!AS:AS,工资明细!BM:BM,$F$1,工资明细!H:H,A21,工资明细!I:I,B21,工资明细!J:J,C21) -> 0 | L21: =SUM(J21:K21) -> 0
A22: 合计 | D22: =SUM(D20:D21) -> 0 | E22: =SUM(E20:E21) -> 0 | F22: =SUM(F20:F21) -> 0 | G22: =SUM(G20:G21) -> 0 | H22: =SUM(H20:H21) -> 0 | I22: =SUM(I20:I21) -> 0 | J22: =SUM(J20:J21) -> 0 | K22: =SUM(K20:K21) -> 0 | L22: =SUM(L20:L21) -> 0

Sheet 武汉人力成本
A1: 日期： | B1: =北分人力成本!B1 -> 46204 | E1: 公司名称： | F1: 中城六棱镜（武汉）科技有限公司
A3: 员工工资及代扣代缴费用汇总表
A4: 一级部门 | B4: 二级部门 | C4: 三级部门 | D4: 人数 | E4: 应发工资 | F4: 养老个人 | G4: 医疗个人 | H4: 失业个人 | I4: 社保个人扣款 | J4: 住房公积金 | K4: 个税 | L4: 税后补款 | M4: 税后扣款 | N4: 实发工资
E5: 金额 | F5: 金额 | G5: 金额 | H5: 金额 | I5: 金额 | J5: 金额 | K5: 金额 | L5: 金额 | M5: 金额 | N5: 金额
A6: 市场部 | B6: 市场推广部 | C6: 武汉区域 | D6: =COUNTIFS(工资明细!BM:BM,$F$1,工资明细!H:H,A6,工资明细!I:I,B6,工资明细!J:J,C6) -> 0 | E6: =SUMIFS(工资明细!AO:AO,工资明细!BM:BM,$F$1,工资明细!H:H,A6,工资明细!I:I,B6,工资明细!J:J,C6) -> 0 | F6: =SUMIFS(工资明细!AP:AP,工资明细!BM:BM,$F$1,工资明细!H:H,A6,工资明细!I:I,B6,工资明细!J:J,C6) -> 0 | G6: =SUMIFS(工资明细!AQ:AQ,工资明细!BM:BM,$F$1,工资明细!H:H,A6,工资明细!I:I,B6,工资明细!J:J,C6) -> 0 | H6: =SUMIFS(工资明细!AR:AR,工资明细!BM:BM,$F$1,工资明细!H:H,A6,工资明细!I:I,B6,工资明细!J:J,C6) -> 0 | I6: =F6+G6+H6 -> 0 | J6: =SUMIFS(工资明细!AT:AT,工资明细!BM:BM,$F$1,工资明细!H:H,A6,工资明细!I:I,B6,工资明细!J:J,C6) -> 0 | K6: =SUMIFS(工资明细!AU:AU,工资明细!BM:BM,$F$1,工资明细!H:H,A6,工资明细!I:I,B6,工资明细!J:J,C6) -> 0 | L6: =SUMIFS(工资明细!AV:AV,工资明细!BM:BM,$F$1,工资明细!H:H,A6,工资明细!I:I,B6,工资明细!J:J,C6) -> 0 | M6: =SUMIFS(工资明细!AW:AW,工资明细!BM:BM,$F$1,工资明细!H:H,A6,工资明细!I:I,B6,工资明细!J:J,C6) -> 0 | N6: =SUMIFS(工资明细!AX:AX,工资明细!BM:BM,$F$1,工资明细!H:H,A6,工资明细!I:I,B6,工资明细!J:J,C6) -> 0
A7: 技术研发事业部 | B7: 产品研发部 | C7: 项目组 | D7: =COUNTIFS(工资明细!BM:BM,$F$1,工资明细!H:H,A7,工资明细!I:I,B7,工资明细!J:J,C7) -> 0 | E7: =SUMIFS(工资明细!AO:AO,工资明细!BM:BM,$F$1,工资明细!H:H,A7,工资明细!I:I,B7,工资明细!J:J,C7) -> 0 | F7: =SUMIFS(工资明细!AP:AP,工资明细!BM:BM,$F$1,工资明细!H:H,A7,工资明细!I:I,B7,工资明细!J:J,C7) -> 0 | G7: =SUMIFS(工资明细!AQ:AQ,工资明细!BM:BM,$F$1,工资明细!H:H,A7,工资明细!I:I,B7,工资明细!J:J,C7) -> 0 | H7: =SUMIFS(工资明细!AR:AR,工资明细!BM:BM,$F$1,工资明细!H:H,A7,工资明细!I:I,B7,工资明细!J:J,C7) -> 0 | I7: =F7+G7+H7 -> 0 | J7: =SUMIFS(工资明细!AT:AT,工资明细!BM:BM,$F$1,工资明细!H:H,A7,工资明细!I:I,B7,工资明细!J:J,C7) -> 0 | K7: =SUMIFS(工资明细!AU:AU,工资明细!BM:BM,$F$1,工资明细!H:H,A7,工资明细!I:I,B7,工资明细!J:J,C7) -> 0 | L7: =SUMIFS(工资明细!AV:AV,工资明细!BM:BM,$F$1,工资明细!H:H,A7,工资明细!I:I,B7,工资明细!J:J,C7) -> 0 | M7: =SUMIFS(工资明细!AW:AW,工资明细!BM:BM,$F$1,工资明细!H:H,A7,工资明细!I:I,B7,工资明细!J:J,C7) -> 0 | N7: =SUMIFS(工资明细!AX:AX,工资明细!BM:BM,$F$1,工资明细!H:H,A7,工资明细!I:I,B7,工资明细!J:J,C7) -> 0
A8: 合计 | D8: =SUM(D6:D7) -> 0 | E8: =SUM(E6:E7) -> 0 | F8: =SUM(F6:F7) -> 0 | G8: =SUM(G6:G7) -> 0 | H8: =SUM(H6:H7) -> 0 | I8: =SUM(I6:I7) -> 0 | J8: =SUM(J6:J7) -> 0 | K8: =SUM(K6:K7) -> 0 | ... N8: =SUM(N6:N7) -> 0
A10: 公积金缴纳汇总表
A11: 一级部门 | B11: 二级部门 | C11: 三级部门 | D11: 人数 | E11: 企业缴纳 | F11: 个人缴纳 | G11: 合计
D12: 人数 | E12: 金额 | F12: 金额
A13: 市场部 | B13: 市场推广部 | C13: 武汉区域 | D13: =COUNTIFS(工资明细!BM:BM,$F$1,工资明细!H:H,A13,工资明细!I:I,B13,工资明细!J:J,C13) -> 0 | E13: =SUMIFS(工资明细!BE:BE,工资明细!BM:BM,$F$1,工资明细!H:H,A13,工资明细!I:I,B13,工资明细!J:J,C13) -> 0 | F13: =SUMIFS(工资明细!AT:AT,工资明细!BM:BM,$F$1,工资明细!H:H,A13,工资明细!I:I,B13,工资明细!J:J,C13) -> 0 | G13: =SUM(E13:F13) -> 0
A14: 技术研发事业部 | B14: 产品研发部 | C14: 项目组 | D14: =COUNTIFS(工资明细!BM:BM,$F$1,工资明细!H:H,A14,工资明细!I:I,B14,工资明细!J:J,C14) -> 0 | E14: =SUMIFS(工资明细!BE:BE,工资明细!BM:BM,$F$1,工资明细!H:H,A14,工资明细!I:I,B14,工资明细!J:J,C14) -> 0 | F14: =SUMIFS(工资明细!AT:AT,工资明细!BM:BM,$F$1,工资明细!H:H,A14,工资明细!I:I,B14,工资明细!J:J,C14) -> 0 | G14: =SUM(E14:F14) -> 0
A15: 合计 | D15: =SUM(D13:D14) -> 0 | E15: =SUM(E13:E14) -> 0 | F15: =SUM(F13:F14) -> 0 | G15: =SUM(G13:G14) -> 0
A17: 社保缴纳汇总表
A18: 一级部门 | B18: 二级部门 | C18: 三级部门 | D18: 人数 | E18: 养老单位 | F18: 医疗单位 | G18: 失业单位 | H18: 工伤单位 | I18: 生育单位 | J18: 企业部分 | K18: 个人部分 | L18: 合计
E19: 金额 | F19: 金额 | G19: 金额 | H19: 金额 | I19: 金额 | J19: 金额 | K19: 金额
A20: 市场部 | B20: 市场推广部 | C20: 武汉区域 | D20: =COUNTIFS(工资明细!BM:BM,$F$1,工资明细!H:H,A20,工资明细!I:I,B20,工资明细!J:J,C20) -> 0 | E20: =SUMIFS(工资明细!AY:AY,工资明细!BM:BM,$F$1,工资明细!H:H,A20,工资明细!I:I,B20,工资明细!J:J,C20) -> 0 | F20: =SUMIFS(工资明细!AZ:AZ,工资明细!BM:BM,$F$1,工资明细!H:H,A20,工资明细!I:I,B20,工资明细!J:J,C20) -> 0 | G20: =SUMIFS(工资明细!BA:BA,工资明细!BM:BM,$F$1,工资明细!H:H,A20,工资明细!I:I,B20,工资明细!J:J,C20) -> 0 | H20: =SUMIFS(工资明细!BB:BB,工资明细!BM:BM,$F$1,工资明细!H:H,A20,工资明细!I:I,B20,工资明细!J:J,C20) -> 0 | I20: =SUMIFS(工资明细!BC:BC,工资明细!BM:BM,$F$1,工资明细!H:H,A20,工资明细!I:I,B20,工资明细!J:J,C20) -> 0 | J20: =SUM(E20:I20) -> 0 | K20: =SUMIFS(工资明细!AS:AS,工资明细!BM:BM,$F$1,工资明细!H:H,A20,工资明细!I:I,B20,工资明细!J:J,C20) -> 0 | L20: =SUM(J20:K20) -> 0
A21: 技术研发事业部 | B21: 产品研发部 | C21: 项目组 | D21: =COUNTIFS(工资明细!BM:BM,$F$1,工资明细!H:H,A21,工资明细!I:I,B21,工资明细!J:J,C21) -> 0 | E21: =SUMIFS(工资明细!AY:AY,工资明细!BM:BM,$F$1,工资明细!H:H,A21,工资明细!I:I,B21,工资明细!J:J,C21) -> 0 | F21: =SUMIFS(工资明细!AZ:AZ,工资明细!BM:BM,$F$1,工资明细!H:H,A21,工资明细!I:I,B21,工资明细!J:J,C21) -> 0 | G21: =SUMIFS(工资明细!BA:BA,工资明细!BM:BM,$F$1,工资明细!H:H,A21,工资明细!I:I,B21,工资明细!J:J,C21) -> 0 | H21: =SUMIFS(工资明细!BB:BB,工资明细!BM:BM,$F$1,工资明细!H:H,A21,工资明细!I:I,B21,工资明细!J:J,C21) -> 0 | I21: =SUMIFS(工资明细!BC:BC,工资明细!BM:BM,$F$1,工资明细!H:H,A21,工资明细!I:I,B21,工资明细!J:J,C21) -> 0 | J21: =SUM(E21:I21) -> 0 | K21: =SUMIFS(工资明细!AS:AS,工资明细!BM:BM,$F$1,工资明细!H:H,A21,工资明细!I:I,B21,工资明细!J:J,C21) -> 0 | L21: =SUM(J21:K21) -> 0
A22: 合计 | D22: =SUM(D20:D21) -> 0 | E22: =SUM(E20:E21) -> 0 | F22: =SUM(F20:F21) -> 0 | G22: =SUM(G20:G21) -> 0 | H22: =SUM(H20:H21) -> 0 | I22: =SUM(I20:I21) -> 0 | J22: =SUM(J20:J21) -> 0 | K22: =SUM(K20:K21) -> 0 | L22: =SUM(L20:L21) -> 0

Sheet 中汽人力成本
A1: 日期： | B1: =北分人力成本!B1 -> 46204 | E1: 公司名称： | F1: 中汽知识产权投资运营中心（北京）有限公司
A3: 员工工资及代扣代缴费用汇总表
A4: 一级部门 | B4: 二级部门 | C4: 三级部门 | D4: 人数 | E4: 应发工资 | F4: 养老个人 | G4: 医疗个人 | H4: 失业个人 | I4: 社保个人扣款 | J4: 住房公积金 | K4: 个税 | L4: 税后补款 | M4: 税后扣款 | N4: 实发工资
E5: 金额 | F5: 金额 | G5: 金额 | H5: 金额 | I5: 金额 | J5: 金额 | K5: 金额 | L5: 金额 | M5: 金额 | N5: 金额
A6: 市场部 | B6: 战略规划部 | C6: 北京总部 | D6: =COUNTIFS(工资明细!BM:BM,$F$1,工资明细!H:H,A6,工资明细!I:I,B6,工资明细!J:J,C6) -> 0 | E6: =SUMIFS(工资明细!AO:AO,工资明细!BM:BM,$F$1,工资明细!H:H,A6,工资明细!I:I,B6,工资明细!J:J,C6) -> 0 | F6: =SUMIFS(工资明细!AP:AP,工资明细!BM:BM,$F$1,工资明细!H:H,A6,工资明细!I:I,B6,工资明细!J:J,C6) -> 0 | G6: =SUMIFS(工资明细!AQ:AQ,工资明细!BM:BM,$F$1,工资明细!H:H,A6,工资明细!I:I,B6,工资明细!J:J,C6) -> 0 | H6: =SUMIFS(工资明细!AR:AR,工资明细!BM:BM,$F$1,工资明细!H:H,A6,工资明细!I:I,B6,工资明细!J:J,C6) -> 0 | I6: =F6+G6+H6 -> 0 | J6: =SUMIFS(工资明细!AT:AT,工资明细!BM:BM,$F$1,工资明细!H:H,A6,工资明细!I:I,B6,工资明细!J:J,C6) -> 0 | K6: =SUMIFS(工资明细!AU:AU,工资明细!BM:BM,$F$1,工资明细!H:H,A6,工资明细!I:I,B6,工资明细!J:J,C6) -> 0 | L6: =SUMIFS(工资明细!AV:AV,工资明细!BM:BM,$F$1,工资明细!H:H,A6,工资明细!I:I,B6,工资明细!J:J,C6) -> 0 | M6: =SUMIFS(工资明细!AW:AW,工资明细!BM:BM,$F$1,工资明细!H:H,A6,工资明细!I:I,B6,工资明细!J:J,C6) -> 0 | N6: =SUMIFS(工资明细!AX:AX,工资明细!BM:BM,$F$1,工资明细!H:H,A6,工资明细!I:I,B6,工资明细!J:J,C6) -> 0
A7: 合计 | D7: =SUM(D6:D6) -> 0 | E7: =SUM(E6:E6) -> 0 | F7: =SUM(F6:F6) -> 0 | G7: =SUM(G6:G6) -> 0 | H7: =SUM(H6:H6) -> 0 | I7: =SUM(I6:I6) -> 0 | J7: =SUM(J6:J6) -> 0 | K7: =SUM(K6:K6) -> 0 | ... N7: =SUM(N6:N6) -> 0
A9: 公积金缴纳汇总表
