Workbook
Name 是否: [1]选项!$A$1:$A$2
Name Hidden000cdfc206468fca52c_1_11: [2]Hidden000cdfc206468fca52c!$A$1:$A$71
Name Hidden000cdfc206468fca52c_1_17: [2]Hidden000cdfc206468fca52c!$B$1:$B$7
Name Hidden000cdfc206468fca52c_1_22: [2]Hidden000cdfc206468fca52c!$C$1:$C$7
Name Hidden000cdfc206468fca52c_1_23: [2]Hidden000cdfc206468fca52c!$D$1:$D$2
Name Hidden000cdfc206468fca52c_1_24: [2]Hidden000cdfc206468fca52c!$E$1:$E$8
Name Hidden000cdfc206468fca52c_1_27: [2]Hidden000cdfc206468fca52c!$F$1:$F$10
Name Hidden000cdfc206468fca52c_1_32: [2]Hidden000cdfc206468fca52c!$G$1:$G$2
Name Hidden000cdfc206468fca52c_1_33: [2]Hidden000cdfc206468fca52c!$H$1:$H$5
Name Hidden000cdfc206468fca52c_1_34: [2]Hidden000cdfc206468fca52c!$I$1:$I$5
Name Hidden000cdfc206468fca52c_1_35: [2]Hidden000cdfc206468fca52c!$J$1:$J$58
Name Hidden000cdfc206468fca52c_1_43: [2]Hidden000cdfc206468fca52c!$K$1:$K$9
Name Hidden000cdfc206468fca52c_1_44: [2]Hidden000cdfc206468fca52c!$L$1:$L$4
Name Hidden000cdfc206468fca52c_1_56: [2]Hidden000cdfc206468fca52c!$M$1:$M$8
Name Hidden000cdfc206468fca52c_1_57: [2]Hidden000cdfc206468fca52c!$N$1:$N$7
Name Hidden000cdfc206468fca52c_1_58: [2]Hidden000cdfc206468fca52c!$O$1:$O$8
Name Hidden000cdfc206468fca52c_1_63: [2]Hidden000cdfc206468fca52c!$P$1:$P$5
Name Hidden000cdfc206468fca52c_1_67: [2]Hidden000cdfc206468fca52c!$Q$1:$Q$6
Name Hidden000cdfc206468fca52c_1_70: [2]Hidden000cdfc206468fca52c!$R$1:$R$6
Name Hidden000cdfc206468fca52c_1_71: [2]Hidden000cdfc206468fca52c!$S$1:$S$2
Name categoryHidden33: [3]categoryHidden33!A1:A170
Name categoryHidden9: #REF!
Name 证件类型: [4]填表说明!$A$6:$A$17
Name 法定假日: #REF!
Name 补班日: #REF!
Name 港澳居民来往内地通行证: [5]填表说明!$G$7
Name 国籍地区: [5]填表说明!$C$7:$C$249
Name 开户银行: [5]填表说明!$M$5:$M$717
Name 涉税事由: [5]填表说明!$A$39:$A$43
Name 省份: [5]填表说明!$K$5:$K$38
Name 证照类型: [5]填表说明!$E$6:$J$6
Name 所得项目: [6]填表说明!$A$5:$A$6
Name Hidden000cdfc206468fca52c_1_27: [7]Hidden000cdfc206468fca52c!$F$1:$F$10
Name Hidden000cdfc206468fca52c_1_27: [7]Hidden000cdfc206468fca52c!$F$1:$F$10
Name Hidden000cdfc206468fca52c_1_27: [7]Hidden000cdfc206468fca52c!$F$1:$F$10
Name Hidden000cdfc206468fca52c_1_27: [7]Hidden000cdfc206468fca52c!$F$1:$F$10
Name Hidden000cdfc206468fca52c_1_27: [7]Hidden000cdfc206468fca52c!$F$1:$F$10
Name Hidden000cdfc206468fca52c_1_27: [7]Hidden000cdfc206468fca52c!$F$1:$F$10
Name Hidden000cdfc206468fca52c_1_27: [7]Hidden000cdfc206468fca52c!$F$1:$F$10

Sheet 汇总
B1: 2026年7月六棱镜工资情况
B2: 主体 | C2: 实发工资 | D2: 个税 | E2: 社保公司 | F2: 社保个人 | G2: 公积金公司 | H2: 公积金个人 | I2: 发薪人数 | K2: 下发项目 | L2: 金额
B3: 北分 | C3: =SUMIFS(工资表明细!AX:AX,工资表明细!B:B,B3) -> 0 | D3: =SUMIFS(工资表明细!AU:AU,工资表明细!B:B,B3) -> 0 | E3: =SUMIFS(工资表明细!BD:BD,工资表明细!B:B,B3) -> 0 | F3: =SUMIFS(工资表明细!AS:AS,工资表明细!B:B,B3) -> 0 | G3: =SUMIFS(工资表明细!BE:BE,工资表明细!B:B,B3) -> 0 | H3: =SUMIFS(工资表明细!AT:AT,工资表明细!B:B,B3) -> 0 | I3: =COUNTIFS(工资表明细!AX:AX,">0",工资表明细!B:B,B3) -> 0 | K3: 在职实发 | L3: =SUMIFS(工资表明细!AX:AX,工资表明细!G:G,0) -> 0 | M3: =L3+L4-工资表明细!AX4 -> 0
B4: 成都 | C4: =SUMIFS(工资表明细!AX:AX,工资表明细!B:B,B4) -> 0 | D4: =SUMIFS(工资表明细!AU:AU,工资表明细!B:B,B4) -> 0 | E4: =SUMIFS(工资表明细!BD:BD,工资表明细!B:B,B4) -> 0 | F4: =SUMIFS(工资表明细!AS:AS,工资表明细!B:B,B4) -> 0 | G4: =SUMIFS(工资表明细!BE:BE,工资表明细!B:B,B4) -> 0 | H4: =SUMIFS(工资表明细!AT:AT,工资表明细!B:B,B4) -> 0 | I4: =COUNTIFS(工资表明细!AX:AX,">0",工资表明细!B:B,B4) -> 0 | K4: 离职实发 | L4: =SUMIFS(工资表明细!AX:AX,工资表明细!G:G,">0") -> 0
B5: 杭州 | C5: =SUMIFS(工资表明细!AX:AX,工资表明细!B:B,B5) -> 0 | D5: =SUMIFS(工资表明细!AU:AU,工资表明细!B:B,B5) -> 0 | E5: =SUMIFS(工资表明细!BD:BD,工资表明细!B:B,B5) -> 0 | F5: =SUMIFS(工资表明细!AS:AS,工资表明细!B:B,B5) -> 0 | G5: =SUMIFS(工资表明细!BE:BE,工资表明细!B:B,B5) -> 0 | H5: =SUMIFS(工资表明细!AT:AT,工资表明细!B:B,B5) -> 0 | I5: =COUNTIFS(工资表明细!AX:AX,">0",工资表明细!B:B,B5) -> 0 | K5: 本月离职分期下发 | L5: 86196.98
B6: 深圳 | C6: =SUMIFS(工资表明细!AX:AX,工资表明细!B:B,B6) -> 0 | D6: =SUMIFS(工资表明细!AU:AU,工资表明细!B:B,B6) -> 0 | E6: =SUMIFS(工资表明细!BD:BD,工资表明细!B:B,B6) -> 0 | F6: =SUMIFS(工资表明细!AS:AS,工资表明细!B:B,B6) -> 0 | G6: =SUMIFS(工资表明细!BE:BE,工资表明细!B:B,B6) -> 0 | H6: =SUMIFS(工资表明细!AT:AT,工资表明细!B:B,B6) -> 0 | I6: =COUNTIFS(工资表明细!AX:AX,">0",工资表明细!B:B,B6) -> 0 | K6: 本月在职分期下发 | L6: 0
B7: 武汉 | C7: =SUMIFS(工资表明细!AX:AX,工资表明细!B:B,B7) -> 0 | D7: =SUMIFS(工资表明细!AU:AU,工资表明细!B:B,B7) -> 0 | E7: =SUMIFS(工资表明细!BD:BD,工资表明细!B:B,B7) -> 0 | F7: =SUMIFS(工资表明细!AS:AS,工资表明细!B:B,B7) -> 0 | G7: =SUMIFS(工资表明细!BE:BE,工资表明细!B:B,B7) -> 0 | H7: =SUMIFS(工资表明细!AT:AT,工资表明细!B:B,B7) -> 0 | I7: =COUNTIFS(工资表明细!AX:AX,">0",工资表明细!B:B,B7) -> 0 | K7: 合计 | L7: =SUM(L3:L6) -> 86196.98
B8: 北京 | C8: =SUMIFS(工资表明细!AX:AX,工资表明细!B:B,B8) -> 0 | D8: =SUMIFS(工资表明细!AU:AU,工资表明细!B:B,B8) -> 0 | E8: =SUMIFS(工资表明细!BD:BD,工资表明细!B:B,B8) -> 0 | F8: =SUMIFS(工资表明细!AS:AS,工资表明细!B:B,B8) -> 0 | G8: =SUMIFS(工资表明细!BE:BE,工资表明细!B:B,B8) -> 0 | H8: =SUMIFS(工资表明细!AT:AT,工资表明细!B:B,B8) -> 0 | I8: =COUNTIFS(工资表明细!AX:AX,">0",工资表明细!B:B,B8) -> 0
B9: 总计 | C9: =SUM(C3:C8) -> 0 | D9: =SUM(D3:D8) -> 0 | E9: =SUM(E3:E8) -> 0 | F9: =SUM(F3:F8) -> 0 | G9: =SUM(G3:G8) -> 0 | H9: =SUM(H3:H8) -> 0 | I9: =SUM(I3:I8) -> 0
B12: 主体 | C12: 实发工资 | D12: 个税 | E12: 社保公司 | F12: 社保个人 | G12: 公积金公司 | H12: 公积金个人 | I12: 发薪人数
B13: 中汽 | C13: =SUMIFS(工资表明细!AX:AX,工资表明细!B:B,B13) -> 0 | D13: =SUMIFS(工资表明细!AU:AU,工资表明细!B:B,B13) -> 0 | E13: =SUMIFS(工资表明细!BD:BD,工资表明细!B:B,B13) -> 0 | F13: =SUMIFS(工资表明细!AS:AS,工资表明细!B:B,B13) -> 0 | G13: =SUMIFS(工资表明细!BE:BE,工资表明细!B:B,B13) -> 0 | H13: =SUMIFS(工资表明细!AT:AT,工资表明细!B:B,B13) -> 0 | I13: =COUNTIFS(工资表明细!AX:AX,">0",工资表明细!B:B,B13) -> 0
B14: 总计 | C14: =SUM(C13:C13) -> 0 | D14: =SUM(D13:D13) -> 0 | E14: =SUM(E13:E13) -> 0 | F14: =SUM(F13:F13) -> 0 | G14: =SUM(G13:G13) -> 0 | H14: =SUM(H13:H13) -> 0 | I14: =SUM(I13:I13) -> 0
C16: =C14+C9-工资表明细!AX4 -> 0 | D16: =D9+D14-工资表明细!AU4 -> 0 | E16: =E9+E14-工资表明细!BD4 -> 0 | F16: =F9+F14-工资表明细!AS4 -> 0 | G16: =G9+G14-工资表明细!BE4 -> 0 | H16: =H9+H14-工资表明细!AT4 -> 0

Sheet 工资表明细
A1: C | AD1: 工资表
A2: 序号 | B2: 员工信息 | N2: 年薪（万元） | O2: 当月薪资标准 | P2: 固定薪资 | AC2: 绩效薪资 | AK2: 业绩提成奖 | AL2: 其他增减项 | AO2: 本月应发工资合计 | AP2: 代扣代缴 | AV2: 税后补款 | AW2: 税后扣款 | AX2: 实发工资 | AY2: 社保公积金公司承担部分 | BF2: 人工成本 | BG2: 备注 | BH2: 报税 | BM2: 公司 | BN2: 银行卡号 | BO2: 开户行 | BP2: 备注
A3: 序号 | B3: 主体简称 | C3: 姓名 | D3: 身份证号 | E3: 入职日期 | F3: 转正日期 | G3: 离职日期 | H3: 一级部门 | I3: 二级部门 | J3: 三级部门 | K3: 职务 | L3: 劳动合同类型 | M3: 职级 | N3: 年薪（万元） | O3: 当月薪资标准 | P3: 当月固定薪资标准 | Q3: 迟到早退 扣款 | R3: 缺卡扣款 | S3: 事假扣款 | T3: 病假 扣款 | U3: 旷工 扣款 | V3: 产假扣款 | W3: 当月未出勤（入离职） | X3: 考勤扣款合计 | Y3: 考勤激励 | Z3: 工资增项 | AA3: 工资减项 | AB3: 应发固定工资 | AC3: 当月绩效标准 | AD3: 绩效 系数 | AE3: 本月工作日天数 | AF3: 实际出勤天数 | AG3: 绩效增项 | AH3: 绩效减项 | AI3: 绩效工资 支付方式 | AJ3: 应发绩效工资 | AK3: 业绩提成奖 | AL3: 经济补偿金 | AM3: 其他增项 | AN3: 其他减项 | AO3: 本月应发工资合计 | AP3: 养老扣款 个人 | AQ3: 医疗扣款 个人 | AR3: 失业扣款 个人 | AS3: 社保扣款 个人合计 | AT3: 公积金扣款 个人 | AU3: 个税 | AV3: 税后补款 | AW3: 税后扣款 | AX3: 实发工资 | AY3: 养老扣款 （单位） | AZ3: 医疗扣款 （单位） | BA3: 失业扣款 （单位） | BB3: 工伤扣款 （单位） | BC3: 生育保险（单位） | BD3: 公司社保合计 | BE3: 住房公积金扣款（单位） | BF3: 人工成本 | BG3: 备注 | BH3: 经济补偿金 | BI3: 年终一次性奖申报 | BJ3: 劳务申报 | BK3: 调整报税金额 | BL3: 正常工资申报 | BM3: 公司 | BN3: 银行卡号 | BO3: 开户行（存疑） | BP3: 备注
B4: 合计 | O4: =SUBTOTAL(9,O2:O3) -> 0 | P4: =SUBTOTAL(9,P2:P3) -> 0 | Q4: =SUBTOTAL(9,Q2:Q3) -> 0 | R4: =SUBTOTAL(9,R2:R3) -> 0 | S4: =SUBTOTAL(9,S2:S3) -> 0 | T4: =SUBTOTAL(9,T2:T3) -> 0 | U4: =SUBTOTAL(9,U2:U3) -> 0 | V4: =SUBTOTAL(9,V2:V3) -> 0 | ... BL4: =SUBTOTAL(9,BL2:BL3) -> 0
A7: 说明：
B8: 产假员工
B9: 调薪调动员工
B10: 新入职员工
B11: 劳务或特殊员工
B12: 离职员工

Sheet 考勤表
O1: 考勤截止日期 | P1: 46234 | Q1: 46204
A2: 身份证号 | B2: 姓名 | C2: 公司 | D2: 一级部门 | E2: 二级部门 | F2: 三级部门 | G2: 入职日期 | H2: 转正日期 | I2: 离职日期 | J2: 试用期固定薪资 | K2: 试用期绩效 | L2: 转正固定薪资 | M2: 转正绩效 | N2: 当月固定薪资标准 | O2: 当月绩效标准 | P2: 当期考勤基数 | Q2: 当地最低工资 | R2: 试用期工作日天数 | S2: 转正工作日天数 | T2: 工作日天数合计 | U2: 实际出勤天数 | V2: 请假外未出勤天数（当月入离职） | W2: 迟到时长 | X2: 早退时长 | Y2: 缺卡次数 | Z2: 旷工天数 | AA2: 事假天数 | AB2: 病假天数 | AC2: 年假天数 | AD2: 产假天数 | AE2: 产检假天数 | AF2: 陪产假天数 | AG2: 育儿假天数 | AH2: 婚假天数 | AI2: 丧假天数 | AJ2: 其他福利假 | AK2: 调休天数 | AL2: 工作日加班时长 | AM2: 休息日加班时长 | AN2: 法定节假日加班时长 | AO2: 请假外未出勤扣款 | AP2: 迟到/早退扣款 | AQ2: 缺卡扣款 | AR2: 事假扣款 | AS2: 病假扣款 | AT2: 产假扣款 | AU2: 旷工扣款 | AV2: 总扣款 | AW2: 工作日加班费 | AX2: 休息日加班费 | AY2: 法定节假日加班费 | AZ2: 全勤奖 | BA2: 合计 | BB2: 转正标记 | BC2: 效验 | BD2: 转正后实际出勤

Sheet 增减项异动表
A1: 序号 | B1: 身份证号 | C1: 姓名 | D1: 项目 | E1: 金额 | F1: 备注

Sheet 花名册
A1: 序号 | B1: 证件号码 | C1: 姓名 | D1: 主体简称 | E1: 公司主体全称 | F1: 一级部门 | G1: 二级部门 | H1: 三级部门 | I1: 岗位 | J1: 职级 | K1: 一级岗位 | L1: 二级岗位 | M1: 直属上级 | N1: 入职时间 | O1: 转正日期 | P1: 离职时间 | Q1: 手机号 | R1: 银行卡号 | S1: 开户行 | T1: 转正固定薪资 | U1: 转正绩效标准 | V1: 试用期底薪 | W1: 试用期绩效 | X1: 劳动合同类型 | Y1: 绩效支付周期 | Z1: 备注 | AA1: 年薪（万元） | AB1: 企业微信邮箱

Sheet 社保公积金明细
A1: 序号 | B1: 姓名 | C1: 身份证号码 | D1: 缴纳主体 | E1: 缴费地区 | F1: 社保基数 | G1: 住房公积金基数 | H1: 养老保险 | J1: 医疗保险 | L1: 失业保险 | N1: 工伤保险 | O1: 生育保险 | P1: 社会保险合计 | R1: 公积金 | T1: 公司合计 | U1: 个人合计 | V1: 滞纳金 | W1: 服务费 | X1: 其他费用 | Y1: 合计 | Z1: 备注
H2: 企业 | I2: 个人 | J2: 企业 | K2: 个人 | L2: 企业 | M2: 个人 | P2: 企业 | Q2: 个人 | R2: 企业 | S2: 个人

Sheet 最低工资标准
A1: 公司全称 | B1: 公司简称 | C1: 地区 | D1: 当地最低工资标准 | E1: 备注
A2: 六棱镜（杭州）科技有限公司北京分公司 | B2: 北分 | C2: 北京 | D2: 2540 | F2: https://rsj.beijing.gov.cn/xxgk/zcwj/202307/t20230714_3162615.html
A3: 北京六棱镜数字科技发展有限公司 | B3: 北京 | C3: 北京 | D3: 2540
A4: 成都六棱镜数字科技有限公司 | B4: 成都 | C4: 成都 | D4: 2330
A5: 六棱镜（杭州）科技有限公司 | B5: 杭州 | C5: 杭州 | D5: 2660 | E5: 浙江1档
A6: 广东六棱镜数字科技发展有限公司 | B6: 深圳 | C6: 深圳 | D6: 2520
A7: 中城六棱镜（武汉）科技有限公司 | B7: 武汉 | C7: 武汉 | D7: 2400
B8: 广州 | C8: 广州 | D8: 2500
B9: 中汽-长沙 | C9: 长沙 | D9: 2200
A10: 中汽知识产权投资运营中心（北京）有限公司 | B10: 中汽-北京 | C10: 北京 | D10: 2540

Sheet 工资条
A1: 身份证号 | B1: 姓名 | C1: 固定工资标准 | D1: 绩效工资标准 | E1: 本月工作 日天数 | F1: 实际出勤天数 | G1: 迟到早退时长 | H1: 事假 | I1: 当月未出勤（入离职）（天） | J1: 病假 （天） | K1: 考勤扣款合计 | L1: 应发固定工资 | M1: 增项合计 | N1: 减项合计 | O1: 本月应发工资合计 | P1: 社保 个人合计 | Q1: 公积金 个人合计 | R1: 个税 | S1: 税后补款 | T1: 税后扣款 | U1: 实发工资 | V1: 备注 | W1: 辅助列-赔偿金 | X1: 辅助列-实发金额核验

Sheet 个税计算
A1: 报税属期 | D1: 8 | E1: 月 | BK1: 46235
A2: 序号 | B2: 姓名 | C2: 身份证件类型 | D2: 身份证件号码 | E2: 是否为非居民个人 | F2: 所得项目 | G2: 本月（次）情况 | AC2: 累计情况 | AN2: 减按计税比例 | AO2: 准予扣除的捐赠额 | AP2: 税款计算 | AW2: 备注 | AX2: 累计情况
G3: 收入额计算 | J3: 减除费用 | K3: 专项扣除 | O3: 其他扣除 | AC3: 累计收入额 | AD3: 累计减除费用 | AE3: 累计专项扣除 | AF3: 累计专项附加扣除 | AL3: 累计个人养老金 | AM3: 累计其他扣除 | AP3: 应纳税所得额 | AQ3: 税率/预扣率 | AR3: 速算扣除数 | AS3: 应纳税额 | AT3: 减免税额 | AU3: 已缴税额 | AV3: 应补/退税额 | AX3: 累计收入额 | AY3: 累计减除费用 | AZ3: 累计专项扣除 | BA3: 累计专项附加扣除 | BG3: 累计个人养老金 | BH3: 累计其他扣除
G4: 收入 | H4: 费用 | I4: 免税收入 | K4: 基本养老保险费 | L4: 基本医疗保险费 | M4: 失业保险费 | N4: 住房公积金 | O4: 年金 | P4: 商业健康保险 | Q4: 税延养老保险 | R4: 财产原值 | S4: 允许扣除的税费 | T4: 公务交通费用 | U4: 通讯费用 | V4: 律师办案费用 | W4: 展业成本 | X4: 西藏附加减除费用 | Y4: 修缮费用 | Z4: 有关合理费用 | AA4: 向出租方支付的租金 | AB4: 其他 | AF4: 子女教育 | AG4: 赡养老人 | AH4: 住房贷款利息 | AI4: 住房租金 | AJ4: 继续教育 | AK4: 3岁以下婴幼儿照护 | BA4: 子女教育 | BB4: 赡养老人 | BC4: 住房贷款利息 | BD4: 住房租金 | BE4: 继续教育 | BF4: 3岁以下婴幼儿照护 | BI4: 上期已缴税额 | BJ4: 上期缴纳税额 | BK4: 辅助列-入职时间
B5: 耿德强 | C5: 居民身份证 | D5: 37028519831217171X | E5: 否 | F5: 正常工资薪金 | G5: {=_xlfn.IFS(F5="正常工资薪金",VLOOKUP(D5&"*",工资表明细!D:BL,61,0),F5="一般劳务报酬所得",VLOOKUP(D5&"*",工资表明细!D:BJ,59,0),F5="全年一次性奖金收入",VLOOKUP(D5&"*",工资表明细!D:BI,58,0),F5="解除劳动合同一次性补偿金",VLOOKUP(D5&"*",工资表明细!D:BH,57,0))} -> #N/A | H5: =IF(F5="一般劳务报酬所得",800,0) -> 0 | I5: 0 | J5: =IF(F5="正常工资薪金",5000,0) -> 5000 | K5: =IF(F5="正常工资薪金",VLOOKUP(D5&"*",工资表明细!D:AP,39,0),0) -> #N/A | L5: =IF(F5="正常工资薪金",VLOOKUP(D5&"*",工资表明细!D:AQ,40,0),0) -> #N/A | M5: =IF(F5="正常工资薪金",VLOOKUP(D5&"*",工资表明细!D:AR,41,0),0) -> #N/A | N5: =IF(F5="正常工资薪金",VLOOKUP(D5&"*",工资表明细!D:AT,43,0),0) -> #N/A | O5: 0 | P5: 0 | Q5: 0 | R5: 0 | S5: 0 | T5: 0 | U5: 0 | V5: 0 | W5: - | X5: 0 | Y5: - | Z5: - | AA5: - | AB5: 0 | AC5: =IF(F5="正常工资薪金",G5+AX5,"-") -> #N/A | AD5: =IF(F5="正常工资薪金",J5+AY5,"-") -> 40000 | AE5: =IF(F5="正常工资薪金",K5+L5+M5+N5+AZ5,"-") -> #N/A | AF5: =IFERROR(IF($F$5="正常工资薪金",IF(YEAR(BK5)<YEAR($BK$1),BA5/($D$1-1)*$D$1,BA5/DATEDIF(BK5,$BK$1,"M")*DATEDIF(BK5,$BK$1,"M")),"-"),0) -> 0 | AG5: =IFERROR(IF($F$5="正常工资薪金",IF(YEAR(BK5)<YEAR($BK$1),BB5/($D$1-1)*$D$1,BB5/DATEDIF(BK5,$BK$1,"M")*DATEDIF(BK5,$BK$1,"M")),"-"),0) -> 0 | AH5: =IFERROR(IF($F$5="正常工资薪金",IF(YEAR(BK5)<YEAR($BK$1),BC5/($D$1-1)*$D$1,BC5/(MONTH($BK$1)-MONTH(BK5))*(MONTH($BK$1)-MONTH(BK5)+1)),"-"),0) -> 0 | AI5: =IFERROR(IF($F$5="正常工资薪金",IF(YEAR(BK5)<YEAR($BK$1),BD5/($D$1-1)*$D$1,BD5/(MONTH($BK$1)-MONTH(BK5))*(MONTH($BK$1)-MONTH(BK5)+1)),"-"),0) -> 0 | AJ5: =IFERROR(IF($F$5="正常工资薪金",IF(YEAR(BK5)<YEAR($BK$1),BE5/($D$1-1)*$D$1,BE5/(MONTH($BK$1)-MONTH(BK5))*(MONTH($BK$1)-MONTH(BK5)+1)),"-"),0) -> 0 | AK5: =IFERROR(IF($F$5="正常工资薪金",IF(YEAR(BK5)<YEAR($BK$1),BF5/($D$1-1)*$D$1,BF5/(MONTH($BK$1)-MONTH(BK5))*(MONTH($BK$1)-MONTH(BK5)+1)),"-"),0) -> 0 | AL5: 0 | AM5: 0 | AN5: 100% | AO5: 0 | AP5: =IF(IF(F5="正常工资薪金",AC5-AD5-AE5-AF5-AG5-AH5-AI5-AJ5-AK5-AL5-AM5,G5-H5-I5)<0,0,IF(F5="正常工资薪金",AC5-AD5-AE5-AF5-AG5-AH5-AI5-AJ5-AK5-AL5-AM5,G5-H5-I5)) -> #N/A | AQ5: {=_xlfn.IFS(F5="正常工资薪金",VLOOKUP(AP5,{0,0.03;36000,0.1;144000,0.2;300000,0.25;420000,0.3;660000,0.35;960000,0.45},2,1),F5="一般劳务报酬所得",IF(AP5<=20000,0.2,IF(AP5<=50000,0.3,0.4)),F5="全年一次性奖金收入",VLOOKUP(AP5/12,{0,0.03;3000,0.1;12000,0.2;25000,0.25;35000,0.3;55000,0.35;80000,0.45},2,1),F5="解除劳动合同一次性补偿金",VLOOKUP(AP5,{0,0.03;36000,0.1;144000,0.2;300000,0.25;420000,0.3;660000,0.35;960000,0.45},2,1))} -> #N/A | AR5: {=_xlfn.IFS(F5="正常工资薪金",VLOOKUP(AP5,{0,0;36000,2520;144000,16920;300000,31920;420000,52920;660000,85920;960000,181920},2,1),F5="一般劳务报酬所得",IF(AP5<=20000,0,IF(AS<=50000,2000,7000)),F5="全年一次性奖金收入",VLOOKUP(AP5/12,{0,0;3000,210;12000,1410;25000,2660;35000,4410;55000,7160;80000,15160},2,1),F5="解除劳动合同一次性补偿金",VLOOKUP(AP5,{0,0;36000,2520;144000,16920;300000,31920;420000,52920;660000,85920;960000,181920},2,1))} -> #N/A | AS5: =AP5*AQ5-AR5 -> #N/A | AT5: 0 | AU5: =BI5+BJ5 -> 28160.43 | AV5: =IF(AS5-AT5-AU5>0,AS5-AT5-AU5,0) -> #N/A | AX5: =IFERROR(IF(F5="正常工资薪金",VLOOKUP(D5&"*",个税上月累计情况!E:AL,26,0),0),0) -> 280000 | AY5: =IFERROR(IF(F5="正常工资薪金",VLOOKUP(D5&"*",个税上月累计情况!E:AL,27,0),0),0) -> 35000 | AZ5: =IFERROR(IF(F5="正常工资薪金",VLOOKUP(D5&"*",个税上月累计情况!E:AL,28,0),0),0) -> 19597.83 | BA5: =IFERROR(IF(F5="正常工资薪金",VLOOKUP(D5&"*",个税上月累计情况!E:AL,29,0),0),0) -> 0 | BB5: =IFERROR(IF(F5="正常工资薪金",VLOOKUP(D5&"*",个税上月累计情况!E:AL,30,0),0),0) -> 0 | BC5: =IFERROR(IF(F5="正常工资薪金",VLOOKUP(D5&"*",个税上月累计情况!E:AL,31,0),0),0) -> 0 | BD5: =IFERROR(IF(F5="正常工资薪金",VLOOKUP(D5&"*",个税上月累计情况!E:AL,32,0),0),0) -> 0 | BE5: =IFERROR(IF(F5="正常工资薪金",VLOOKUP(D5&"*",个税上月累计情况!E:AL,33,0),0),0) -> 0 | BF5: =IFERROR(IF(F5="正常工资薪金",VLOOKUP(D5&"*",个税上月累计情况!E:AL,34,0),0),0) -> 0 | BG5: =IFERROR(IF(F5="正常工资薪金",VLOOKUP(D5&"*",个税上月累计情况!E:AN,35,0),0),0) -> 0 | BH5: =IFERROR(IF(F5="正常工资薪金",VLOOKUP(D5&"*",个税上月累计情况!E:AN,36,0),0),0) -> 0 | BI5: =IFERROR(IF(F5="正常工资薪金",VLOOKUP(D5&"*",个税上月累计情况!D:AW,46,0),0),0) -> 21660.54 | BJ5: =IFERROR(IF(F5="正常工资薪金",VLOOKUP(D5&"*",个税上月累计情况!D:AX,47,0),0),0) -> 6499.89 | BK5: =VLOOKUP(B5,花名册!C:N,12,0) -> #N/A
B6: 牛飞芸 | C6: 居民身份证 | D6: 620402199105092732 | E6: 否 | F6: 正常工资薪金 | G6: {=_xlfn.IFS(F6="正常工资薪金",VLOOKUP(D6&"*",工资表明细!D:BL,61,0),F6="一般劳务报酬所得",VLOOKUP(D6&"*",工资表明细!D:BJ,59,0),F6="全年一次性奖金收入",VLOOKUP(D6&"*",工资表明细!D:BI,58,0),F6="解除劳动合同一次性补偿金",VLOOKUP(D6&"*",工资表明细!D:BH,57,0))} -> #N/A | H6: =IF(F6="一般劳务报酬所得",800,0) -> 0 | I6: 0 | J6: =IF(F6="正常工资薪金",5000,0) -> 5000 | K6: =IF(F6="正常工资薪金",VLOOKUP(D6&"*",工资表明细!D:AP,39,0),0) -> #N/A | L6: =IF(F6="正常工资薪金",VLOOKUP(D6&"*",工资表明细!D:AQ,40,0),0) -> #N/A | M6: =IF(F6="正常工资薪金",VLOOKUP(D6&"*",工资表明细!D:AR,41,0),0) -> #N/A | N6: =IF(F6="正常工资薪金",VLOOKUP(D6&"*",工资表明细!D:AT,43,0),0) -> #N/A | O6: 1 | P6: 1 | Q6: 1 | R6: 1 | S6: 1 | T6: 1 | U6: 1 | V6: 1 | W6: - | X6: 1 | Y6: - | Z6: - | AA6: - | AB6: 1 | AC6: =IF(F6="正常工资薪金",G6+AX6,"-") -> #N/A | AD6: =IF(F6="正常工资薪金",J6+AY6,"-") -> 40000 | AE6: =IF(F6="正常工资薪金",K6+L6+M6+N6+AZ6,"-") -> #N/A | AF6: =IFERROR(IF($F$5="正常工资薪金",IF(YEAR(BK6)<YEAR($BK$1),BA6/($D$1-1)*$D$1,BA6/DATEDIF(BK6,$BK$1,"M")*DATEDIF(BK6,$BK$1,"M")),"-"),0) -> 0 | AG6: =IFERROR(IF($F$5="正常工资薪金",IF(YEAR(BK6)<YEAR($BK$1),BB6/($D$1-1)*$D$1,BB6/DATEDIF(BK6,$BK$1,"M")*DATEDIF(BK6,$BK$1,"M")),"-"),0) -> 0 | AH6: =IFERROR(IF($F$5="正常工资薪金",IF(YEAR(BK6)<YEAR($BK$1),BC6/($D$1-1)*$D$1,BC6/(MONTH($BK$1)-MONTH(BK6))*(MONTH($BK$1)-MONTH(BK6)+1)),"-"),0) -> 0 | AI6: =IFERROR(IF($F$5="正常工资薪金",IF(YEAR(BK6)<YEAR($BK$1),BD6/($D$1-1)*$D$1,BD6/(MONTH($BK$1)-MONTH(BK6))*(MONTH($BK$1)-MONTH(BK6)+1)),"-"),0) -> 0 | AJ6: =IFERROR(IF($F$5="正常工资薪金",IF(YEAR(BK6)<YEAR($BK$1),BE6/($D$1-1)*$D$1,BE6/(MONTH($BK$1)-MONTH(BK6))*(MONTH($BK$1)-MONTH(BK6)+1)),"-"),0) -> 0 | AK6: =IFERROR(IF($F$5="正常工资薪金",IF(YEAR(BK6)<YEAR($BK$1),BF6/($D$1-1)*$D$1,BF6/(MONTH($BK$1)-MONTH(BK6))*(MONTH($BK$1)-MONTH(BK6)+1)),"-"),0) -> 0 | AL6: 0 | AM6: 0 | AN6: 100% | AO6: 0 | AP6: =IF(IF(F6="正常工资薪金",AC6-AD6-AE6-AF6-AG6-AH6-AI6-AJ6-AK6-AL6-AM6,G6-H6-I6)<0,0,IF(F6="正常工资薪金",AC6-AD6-AE6-AF6-AG6-AH6-AI6-AJ6-AK6-AL6-AM6,G6-H6-I6)) -> #N/A | AQ6: {=_xlfn.IFS(F6="正常工资薪金",VLOOKUP(AP6,{0,0.03;36000,0.1;144000,0.2;300000,0.25;420000,0.3;660000,0.35;960000,0.45},2,1),F6="一般劳务报酬所得",IF(AP6<=20000,0.2,IF(AP6<=50000,0.3,0.4)),F6="全年一次性奖金收入",VLOOKUP(AP6/12,{0,0.03;3000,0.1;12000,0.2;25000,0.25;35000,0.3;55000,0.35;80000,0.45},2,1),F6="解除劳动合同一次性补偿金",VLOOKUP(AP6,{0,0.03;36000,0.1;144000,0.2;300000,0.25;420000,0.3;660000,0.35;960000,0.45},2,1))} -> #N/A | AR6: {=_xlfn.IFS(F6="正常工资薪金",VLOOKUP(AP6,{0,0;36000,2520;144000,16920;300000,31920;420000,52920;660000,85920;960000,181920},2,1),F6="一般劳务报酬所得",IF(AP6<=20000,0,IF(AS<=50000,2000,7000)),F6="全年一次性奖金收入",VLOOKUP(AP6/12,{0,0;3000,210;12000,1410;25000,2660;35000,4410;55000,7160;80000,15160},2,1),F6="解除劳动合同一次性补偿金",VLOOKUP(AP6,{0,0;36000,2520;144000,16920;300000,31920;420000,52920;660000,85920;960000,181920},2,1))} -> #N/A | AS6: =AP6*AQ6-AR6 -> #N/A | AT6: 0 | AU6: =BI6+BJ6 -> 2596.72 | AV6: =IF(AS6-AT6-AU6>0,AS6-AT6-AU6,0) -> #N/A | AX6: =IFERROR(IF(F6="正常工资薪金",VLOOKUP(D6&"*",个税上月累计情况!E:AL,26,0),0),0) -> 109505.3 | AY6: =IFERROR(IF(F6="正常工资薪金",VLOOKUP(D6&"*",个税上月累计情况!E:AL,27,0),0),0) -> 35000 | AZ6: =IFERROR(IF(F6="正常工资薪金",VLOOKUP(D6&"*",个税上月累计情况!E:AL,28,0),0),0) -> 12838.07 | BA6: =IFERROR(IF(F6="正常工资薪金",VLOOKUP(D6&"*",个税上月累计情况!E:AL,29,0),0),0) -> 0 | BB6: =IFERROR(IF(F6="正常工资薪金",VLOOKUP(D6&"*",个税上月累计情况!E:AL,30,0),0),0) -> 0 | BC6: =IFERROR(IF(F6="正常工资薪金",VLOOKUP(D6&"*",个税上月累计情况!E:AL,31,0),0),0) -> 0 | BD6: =IFERROR(IF(F6="正常工资薪金",VLOOKUP(D6&"*",个税上月累计情况!E:AL,32,0),0),0) -> 10500 | BE6: =IFERROR(IF(F6="正常工资薪金",VLOOKUP(D6&"*",个税上月累计情况!E:AL,33,0),0),0) -> 0 | BF6: =IFERROR(IF(F6="正常工资薪金",VLOOKUP(D6&"*",个税上月累计情况!E:AL,34,0),0),0) -> 0 | BG6: =IFERROR(IF(F6="正常工资薪金",VLOOKUP(D6&"*",个税上月累计情况!E:AN,35,0),0),0) -> 0 | BH6: =IFERROR(IF(F6="正常工资薪金",VLOOKUP(D6&"*",个税上月累计情况!E:AN,36,0),0),0) -> 0 | BI6: =IFERROR(IF(F6="正常工资薪金",VLOOKUP(D6&"*",个税上月累计情况!D:AW,46,0),0),0) -> 1841.91 | BJ6: =IFERROR(IF(F6="正常工资薪金",VLOOKUP(D6&"*",个税上月累计情况!D:AX,47,0),0),0) -> 754.81 | BK6: =VLOOKUP(B6,花名册!C:N,12,0) -> #N/A
B7: 刘洋 | C7: 居民身份证 | D7: 411102198406050051 | E7: 否 | F7: 正常工资薪金 | G7: {=_xlfn.IFS(F7="正常工资薪金",VLOOKUP(D7&"*",工资表明细!D:BL,61,0),F7="一般劳务报酬所得",VLOOKUP(D7&"*",工资表明细!D:BJ,59,0),F7="全年一次性奖金收入",VLOOKUP(D7&"*",工资表明细!D:BI,58,0),F7="解除劳动合同一次性补偿金",VLOOKUP(D7&"*",工资表明细!D:BH,57,0))} -> #N/A | H7: =IF(F7="一般劳务报酬所得",800,0) -> 0 | I7: 0 | J7: =IF(F7="正常工资薪金",5000,0) -> 5000 | K7: =IF(F7="正常工资薪金",VLOOKUP(D7&"*",工资表明细!D:AP,39,0),0) -> #N/A | L7: =IF(F7="正常工资薪金",VLOOKUP(D7&"*",工资表明细!D:AQ,40,0),0) -> #N/A | M7: =IF(F7="正常工资薪金",VLOOKUP(D7&"*",工资表明细!D:AR,41,0),0) -> #N/A | N7: =IF(F7="正常工资薪金",VLOOKUP(D7&"*",工资表明细!D:AT,43,0),0) -> #N/A | O7: 2 | P7: 2 | Q7: 2 | R7: 2 | S7: 2 | T7: 2 | U7: 2 | V7: 2 | W7: - | X7: 2 | Y7: - | Z7: - | AA7: - | AB7: 2 | AC7: =IF(F7="正常工资薪金",G7+AX7,"-") -> #N/A | AD7: =IF(F7="正常工资薪金",J7+AY7,"-") -> 40000 | AE7: =IF(F7="正常工资薪金",K7+L7+M7+N7+AZ7,"-") -> #N/A | AF7: =IFERROR(IF($F$5="正常工资薪金",IF(YEAR(BK7)<YEAR($BK$1),BA7/($D$1-1)*$D$1,BA7/DATEDIF(BK7,$BK$1,"M")*DATEDIF(BK7,$BK$1,"M")),"-"),0) -> 0 | AG7: =IFERROR(IF($F$5="正常工资薪金",IF(YEAR(BK7)<YEAR($BK$1),BB7/($D$1-1)*$D$1,BB7/DATEDIF(BK7,$BK$1,"M")*DATEDIF(BK7,$BK$1,"M")),"-"),0) -> 0 | AH7: =IFERROR(IF($F$5="正常工资薪金",IF(YEAR(BK7)<YEAR($BK$1),BC7/($D$1-1)*$D$1,BC7/(MONTH($BK$1)-MONTH(BK7))*(MONTH($BK$1)-MONTH(BK7)+1)),"-"),0) -> 0 | AI7: =IFERROR(IF($F$5="正常工资薪金",IF(YEAR(BK7)<YEAR($BK$1),BD7/($D$1-1)*$D$1,BD7/(MONTH($BK$1)-MONTH(BK7))*(MONTH($BK$1)-MONTH(BK7)+1)),"-"),0) -> 0 | AJ7: =IFERROR(IF($F$5="正常工资薪金",IF(YEAR(BK7)<YEAR($BK$1),BE7/($D$1-1)*$D$1,BE7/(MONTH($BK$1)-MONTH(BK7))*(MONTH($BK$1)-MONTH(BK7)+1)),"-"),0) -> 0 | AK7: =IFERROR(IF($F$5="正常工资薪金",IF(YEAR(BK7)<YEAR($BK$1),BF7/($D$1-1)*$D$1,BF7/(MONTH($BK$1)-MONTH(BK7))*(MONTH($BK$1)-MONTH(BK7)+1)),"-"),0) -> 0 | AL7: 0 | AM7: 0 | AN7: 100% | AO7: 0 | AP7: =IF(IF(F7="正常工资薪金",AC7-AD7-AE7-AF7-AG7-AH7-AI7-AJ7-AK7-AL7-AM7,G7-H7-I7)<0,0,IF(F7="正常工资薪金",AC7-AD7-AE7-AF7-AG7-AH7-AI7-AJ7-AK7-AL7-AM7,G7-H7-I7)) -> #N/A | AQ7: {=_xlfn.IFS(F7="正常工资薪金",VLOOKUP(AP7,{0,0.03;36000,0.1;144000,0.2;300000,0.25;420000,0.3;660000,0.35;960000,0.45},2,1),F7="一般劳务报酬所得",IF(AP7<=20000,0.2,IF(AP7<=50000,0.3,0.4)),F7="全年一次性奖金收入",VLOOKUP(AP7/12,{0,0.03;3000,0.1;12000,0.2;25000,0.25;35000,0.3;55000,0.35;80000,0.45},2,1),F7="解除劳动合同一次性补偿金",VLOOKUP(AP7,{0,0.03;36000,0.1;144000,0.2;300000,0.25;420000,0.3;660000,0.35;960000,0.45},2,1))} -> #N/A | AR7: {=_xlfn.IFS(F7="正常工资薪金",VLOOKUP(AP7,{0,0;36000,2520;144000,16920;300000,31920;420000,52920;660000,85920;960000,181920},2,1),F7="一般劳务报酬所得",IF(AP7<=20000,0,IF(AS<=50000,2000,7000)),F7="全年一次性奖金收入",VLOOKUP(AP7/12,{0,0;3000,210;12000,1410;25000,2660;35000,4410;55000,7160;80000,15160},2,1),F7="解除劳动合同一次性补偿金",VLOOKUP(AP7,{0,0;36000,2520;144000,16920;300000,31920;420000,52920;660000,85920;960000,181920},2,1))} -> #N/A | AS7: =AP7*AQ7-AR7 -> #N/A | AT7: 0 | AU7: =BI7+BJ7 -> 23960.43 | AV7: =IF(AS7-AT7-AU7>0,AS7-AT7-AU7,0) -> #N/A | AX7: =IFERROR(IF(F7="正常工资薪金",VLOOKUP(D7&"*",个税上月累计情况!E:AL,26,0),0),0) -> 280000 | AY7: =IFERROR(IF(F7="正常工资薪金",VLOOKUP(D7&"*",个税上月累计情况!E:AL,27,0),0),0) -> 35000 | AZ7: =IFERROR(IF(F7="正常工资薪金",VLOOKUP(D7&"*",个税上月累计情况!E:AL,28,0),0),0) -> 19597.83 | BA7: =IFERROR(IF(F7="正常工资薪金",VLOOKUP(D7&"*",个税上月累计情况!E:AL,29,0),0),0) -> 0 | BB7: =IFERROR(IF(F7="正常工资薪金",VLOOKUP(D7&"*",个税上月累计情况!E:AL,30,0),0),0) -> 21000 | BC7: =IFERROR(IF(F7="正常工资薪金",VLOOKUP(D7&"*",个税上月累计情况!E:AL,31,0),0),0) -> 0 | BD7: =IFERROR(IF(F7="正常工资薪金",VLOOKUP(D7&"*",个税上月累计情况!E:AL,32,0),0),0) -> 0 | BE7: =IFERROR(IF(F7="正常工资薪金",VLOOKUP(D7&"*",个税上月累计情况!E:AL,33,0),0),0) -> 0 | BF7: =IFERROR(IF(F7="正常工资薪金",VLOOKUP(D7&"*",个税上月累计情况!E:AL,34,0),0),0) -> 0 | BG7: =IFERROR(IF(F7="正常工资薪金",VLOOKUP(D7&"*",个税上月累计情况!E:AN,35,0),0),0) -> 0 | BH7: =IFERROR(IF(F7="正常工资薪金",VLOOKUP(D7&"*",个税上月累计情况!E:AN,36,0),0),0) -> 0 | BI7: =IFERROR(IF(F7="正常工资薪金",VLOOKUP(D7&"*",个税上月累计情况!D:AW,46,0),0),0) -> 18060.54 | BJ7: =IFERROR(IF(F7="正常工资薪金",VLOOKUP(D7&"*",个税上月累计情况!D:AX,47,0),0),0) -> 5899.89 | BK7: =VLOOKUP(B7,花名册!C:N,12,0) -> #N/A
B8: 杨娟 | C8: 居民身份证 | D8: 141034199511170105 | E8: 否 | F8: 正常工资薪金 | G8: {=_xlfn.IFS(F8="正常工资薪金",VLOOKUP(D8&"*",工资表明细!D:BL,61,0),F8="一般劳务报酬所得",VLOOKUP(D8&"*",工资表明细!D:BJ,59,0),F8="全年一次性奖金收入",VLOOKUP(D8&"*",工资表明细!D:BI,58,0),F8="解除劳动合同一次性补偿金",VLOOKUP(D8&"*",工资表明细!D:BH,57,0))} -> #N/A | H8: =IF(F8="一般劳务报酬所得",800,0) -> 0 | I8: 3935.01 | J8: =IF(F8="正常工资薪金",5000,0) -> 5000 | K8: =IF(F8="正常工资薪金",VLOOKUP(D8&"*",工资表明细!D:AP,39,0),0) -> #N/A | L8: =IF(F8="正常工资薪金",VLOOKUP(D8&"*",工资表明细!D:AQ,40,0),0) -> #N/A | M8: =IF(F8="正常工资薪金",VLOOKUP(D8&"*",工资表明细!D:AR,41,0),0) -> #N/A | N8: =IF(F8="正常工资薪金",VLOOKUP(D8&"*",工资表明细!D:AT,43,0),0) -> #N/A | O8: 3 | P8: 3 | Q8: 3 | R8: 3 | S8: 3 | T8: 3 | U8: 3 | V8: 3 | W8: - | X8: 3 | Y8: - | Z8: - | AA8: - | AB8: 3 | AC8: =IF(F8="正常工资薪金",G8+AX8,"-") -> #N/A | AD8: =IF(F8="正常工资薪金",J8+AY8,"-") -> 40000 | AE8: =IF(F8="正常工资薪金",K8+L8+M8+N8+AZ8,"-") -> #N/A | AF8: =IFERROR(IF($F$5="正常工资薪金",IF(YEAR(BK8)<YEAR($BK$1),BA8/($D$1-1)*$D$1,BA8/DATEDIF(BK8,$BK$1,"M")*DATEDIF(BK8,$BK$1,"M")),"-"),0) -> 0 | AG8: =IFERROR(IF($F$5="正常工资薪金",IF(YEAR(BK8)<YEAR($BK$1),BB8/($D$1-1)*$D$1,BB8/DATEDIF(BK8,$BK$1,"M")*DATEDIF(BK8,$BK$1,"M")),"-"),0) -> 0 | AH8: =IFERROR(IF($F$5="正常工资薪金",IF(YEAR(BK8)<YEAR($BK$1),BC8/($D$1-1)*$D$1,BC8/(MONTH($BK$1)-MONTH(BK8))*(MONTH($BK$1)-MONTH(BK8)+1)),"-"),0) -> 0 | AI8: =IFERROR(IF($F$5="正常工资薪金",IF(YEAR(BK8)<YEAR($BK$1),BD8/($D$1-1)*$D$1,BD8/(MONTH($BK$1)-MONTH(BK8))*(MONTH($BK$1)-MONTH(BK8)+1)),"-"),0) -> 0 | AJ8: =IFERROR(IF($F$5="正常工资薪金",IF(YEAR(BK8)<YEAR($BK$1),BE8/($D$1-1)*$D$1,BE8/(MONTH($BK$1)-MONTH(BK8))*(MONTH($BK$1)-MONTH(BK8)+1)),"-"),0) -> 0 | AK8: =IFERROR(IF($F$5="正常工资薪金",IF(YEAR(BK8)<YEAR($BK$1),BF8/($D$1-1)*$D$1,BF8/(MONTH($BK$1)-MONTH(BK8))*(MONTH($BK$1)-MONTH(BK8)+1)),"-"),0) -> 0 | AL8: 0 | AM8: 0 | AN8: 100% | AO8: 0 | AP8: =IF(IF(F8="正常工资薪金",AC8-AD8-AE8-AF8-AG8-AH8-AI8-AJ8-AK8-AL8-AM8,G8-H8-I8)<0,0,IF(F8="正常工资薪金",AC8-AD8-AE8-AF8-AG8-AH8-AI8-AJ8-AK8-AL8-AM8,G8-H8-I8)) -> #N/A | AQ8: {=_xlfn.IFS(F8="正常工资薪金",VLOOKUP(AP8,{0,0.03;36000,0.1;144000,0.2;300000,0.25;420000,0.3;660000,0.35;960000,0.45},2,1),F8="一般劳务报酬所得",IF(AP8<=20000,0.2,IF(AP8<=50000,0.3,0.4)),F8="全年一次性奖金收入",VLOOKUP(AP8/12,{0,0.03;3000,0.1;12000,0.2;25000,0.25;35000,0.3;55000,0.35;80000,0.45},2,1),F8="解除劳动合同一次性补偿金",VLOOKUP(AP8,{0,0.03;36000,0.1;144000,0.2;300000,0.25;420000,0.3;660000,0.35;960000,0.45},2,1))} -> #N/A | AR8: {=_xlfn.IFS(F8="正常工资薪金",VLOOKUP(AP8,{0,0;36000,2520;144000,16920;300000,31920;420000,52920;660000,85920;960000,181920},2,1),F8="一般劳务报酬所得",IF(AP8<=20000,0,IF(AS<=50000,2000,7000)),F8="全年一次性奖金收入",VLOOKUP(AP8/12,{0,0;3000,210;12000,1410;25000,2660;35000,4410;55000,7160;80000,15160},2,1),F8="解除劳动合同一次性补偿金",VLOOKUP(AP8,{0,0;36000,2520;144000,16920;300000,31920;420000,52920;660000,85920;960000,181920},2,1))} -> #N/A | AS8: =AP8*AQ8-AR8 -> #N/A | AT8: 0 | AU8: =BI8+BJ8 -> 518.97 | AV8: =IF(AS8-AT8-AU8>0,AS8-AT8-AU8,0) -> #N/A | AX8: =IFERROR(IF(F8="正常工资薪金",VLOOKUP(D8&"*",个税上月累计情况!E:AL,26,0),0),0) -> 39781.1 | AY8: =IFERROR(IF(F8="正常工资薪金",VLOOKUP(D8&"*",个税上月累计情况!E:AL,27,0),0),0) -> 35000 | AZ8: =IFERROR(IF(F8="正常工资薪金",VLOOKUP(D8&"*",个税上月累计情况!E:AL,28,0),0),0) -> 10535.07 | BA8: =IFERROR(IF(F8="正常工资薪金",VLOOKUP(D8&"*",个税上月累计情况!E:AL,29,0),0),0) -> 0 | BB8: =IFERROR(IF(F8="正常工资薪金",VLOOKUP(D8&"*",个税上月累计情况!E:AL,30,0),0),0) -> 0 | BC8: =IFERROR(IF(F8="正常工资薪金",VLOOKUP(D8&"*",个税上月累计情况!E:AL,31,0),0),0) -> 0 | BD8: =IFERROR(IF(F8="正常工资薪金",VLOOKUP(D8&"*",个税上月累计情况!E:AL,32,0),0),0) -> 0 | BE8: =IFERROR(IF(F8="正常工资薪金",VLOOKUP(D8&"*",个税上月累计情况!E:AL,33,0),0),0) -> 0 | BF8: =IFERROR(IF(F8="正常工资薪金",VLOOKUP(D8&"*",个税上月累计情况!E:AL,34,0),0),0) -> 0 | BG8: =IFERROR(IF(F8="正常工资薪金",VLOOKUP(D8&"*",个税上月累计情况!E:AN,35,0),0),0) -> 0 | BH8: =IFERROR(IF(F8="正常工资薪金",VLOOKUP(D8&"*",个税上月累计情况!E:AN,36,0),0),0) -> 0 | BI8: =IFERROR(IF(F8="正常工资薪金",VLOOKUP(D8&"*",个税上月累计情况!D:AW,46,0),0),0) -> 518.97 | BJ8: =IFERROR(IF(F8="正常工资薪金",VLOOKUP(D8&"*",个税上月累计情况!D:AX,47,0),0),0) -> 0 | BK8: =VLOOKUP(B8,花名册!C:N,12,0) -> #N/A
B9: 杨金雪 | C9: 居民身份证 | D9: 211382199701014125 | E9: 否 | F9: 正常工资薪金 | G9: {=_xlfn.IFS(F9="正常工资薪金",VLOOKUP(D9&"*",工资表明细!D:BL,61,0),F9="一般劳务报酬所得",VLOOKUP(D9&"*",工资表明细!D:BJ,59,0),F9="全年一次性奖金收入",VLOOKUP(D9&"*",工资表明细!D:BI,58,0),F9="解除劳动合同一次性补偿金",VLOOKUP(D9&"*",工资表明细!D:BH,57,0))} -> #N/A | H9: =IF(F9="一般劳务报酬所得",800,0) -> 0 | I9: 0 | J9: =IF(F9="正常工资薪金",5000,0) -> 5000 | K9: =IF(F9="正常工资薪金",VLOOKUP(D9&"*",工资表明细!D:AP,39,0),0) -> #N/A | L9: =IF(F9="正常工资薪金",VLOOKUP(D9&"*",工资表明细!D:AQ,40,0),0) -> #N/A | M9: =IF(F9="正常工资薪金",VLOOKUP(D9&"*",工资表明细!D:AR,41,0),0) -> #N/A | N9: =IF(F9="正常工资薪金",VLOOKUP(D9&"*",工资表明细!D:AT,43,0),0) -> #N/A | O9: 4 | P9: 4 | Q9: 4 | R9: 4 | S9: 4 | T9: 4 | U9: 4 | V9: 4 | W9: - | X9: 4 | Y9: - | Z9: - | AA9: - | AB9: 4 | AC9: =IF(F9="正常工资薪金",G9+AX9,"-") -> #N/A | AD9: =IF(F9="正常工资薪金",J9+AY9,"-") -> 40000 | AE9: =IF(F9="正常工资薪金",K9+L9+M9+N9+AZ9,"-") -> #N/A | AF9: =IFERROR(IF($F$5="正常工资薪金",IF(YEAR(BK9)<YEAR($BK$1),BA9/($D$1-1)*$D$1,BA9/DATEDIF(BK9,$BK$1,"M")*DATEDIF(BK9,$BK$1,"M")),"-"),0) -> 0 | AG9: =IFERROR(IF($F$5="正常工资薪金",IF(YEAR(BK9)<YEAR($BK$1),BB9/($D$1-1)*$D$1,BB9/DATEDIF(BK9,$BK$1,"M")*DATEDIF(BK9,$BK$1,"M")),"-"),0) -> 0 | AH9: =IFERROR(IF($F$5="正常工资薪金",IF(YEAR(BK9)<YEAR($BK$1),BC9/($D$1-1)*$D$1,BC9/(MONTH($BK$1)-MONTH(BK9))*(MONTH($BK$1)-MONTH(BK9)+1)),"-"),0) -> 0 | AI9: =IFERROR(IF($F$5="正常工资薪金",IF(YEAR(BK9)<YEAR($BK$1),BD9/($D$1-1)*$D$1,BD9/(MONTH($BK$1)-MONTH(BK9))*(MONTH($BK$1)-MONTH(BK9)+1)),"-"),0) -> 0 | AJ9: =IFERROR(IF($F$5="正常工资薪金",IF(YEAR(BK9)<YEAR($BK$1),BE9/($D$1-1)*$D$1,BE9/(MONTH($BK$1)-MONTH(BK9))*(MONTH($BK$1)-MONTH(BK9)+1)),"-"),0) -> 0 | AK9: =IFERROR(IF($F$5="正常工资薪金",IF(YEAR(BK9)<YEAR($BK$1),BF9/($D$1-1)*$D$1,BF9/(MONTH($BK$1)-MONTH(BK9))*(MONTH($BK$1)-MONTH(BK9)+1)),"-"),0) -> 0 | AL9: 0 | AM9: 0 | AN9: 100% | AO9: 0 | AP9: =IF(IF(F9="正常工资薪金",AC9-AD9-AE9-AF9-AG9-AH9-AI9-AJ9-AK9-AL9-AM9,G9-H9-I9)<0,0,IF(F9="正常工资薪金",AC9-AD9-AE9-AF9-AG9-AH9-AI9-AJ9-AK9-AL9-AM9,G9-H9-I9)) -> #N/A | AQ9: {=_xlfn.IFS(F9="正常工资薪金",VLOOKUP(AP9,{0,0.03;36000,0.1;144000,0.2;300000,0.25;420000,0.3;660000,0.35;960000,0.45},2,1),F9="一般劳务报酬所得",IF(AP9<=20000,0.2,IF(AP9<=50000,0.3,0.4)),F9="全年一次性奖金收入",VLOOKUP(AP9/12,{0,0.03;3000,0.1;12000,0.2;25000,0.25;35000,0.3;55000,0.35;80000,0.45},2,1),F9="解除劳动合同一次性补偿金",VLOOKUP(AP9,{0,0.03;36000,0.1;144000,0.2;300000,0.25;420000,0.3;660000,0.35;960000,0.45},2,1))} -> #N/A | AR9: {=_xlfn.IFS(F9="正常工资薪金",VLOOKUP(AP9,{0,0;36000,2520;144000,16920;300000,31920;420000,52920;660000,85920;960000,181920},2,1),F9="一般劳务报酬所得",IF(AP9<=20000,0,IF(AS<=50000,2000,7000)),F9="全年一次性奖金收入",VLOOKUP(AP9/12,{0,0;3000,210;12000,1410;25000,2660;35000,4410;55000,7160;80000,15160},2,1),F9="解除劳动合同一次性补偿金",VLOOKUP(AP9,{0,0;36000,2520;144000,16920;300000,31920;420000,52920;660000,85920;960000,181920},2,1))} -> #N/A | AS9: =AP9*AQ9-AR9 -> #N/A | AT9: 0 | AU9: =BI9+BJ9 -> 711.99 | AV9: =IF(AS9-AT9-AU9>0,AS9-AT9-AU9,0) -> #N/A | AX9: =IFERROR(IF(F9="正常工资薪金",VLOOKUP(D9&"*",个税上月累计情况!E:AL,26,0),0),0) -> 66881.14 | AY9: =IFERROR(IF(F9="正常工资薪金",VLOOKUP(D9&"*",个税上月累计情况!E:AL,27,0),0),0) -> 35000 | AZ9: =IFERROR(IF(F9="正常工资薪金",VLOOKUP(D9&"*",个税上月累计情况!E:AL,28,0),0),0) -> 8148.07 | BA9: =IFERROR(IF(F9="正常工资薪金",VLOOKUP(D9&"*",个税上月累计情况!E:AL,29,0),0),0) -> 0 | BB9: =IFERROR(IF(F9="正常工资薪金",VLOOKUP(D9&"*",个税上月累计情况!E:AL,30,0),0),0) -> 0 | BC9: =IFERROR(IF(F9="正常工资薪金",VLOOKUP(D9&"*",个税上月累计情况!E:AL,31,0),0),0) -> 0 | BD9: =IFERROR(IF(F9="正常工资薪金",VLOOKUP(D9&"*",个税上月累计情况!E:AL,32,0),0),0) -> 0 | BE9: =IFERROR(IF(F9="正常工资薪金",VLOOKUP(D9&"*",个税上月累计情况!E:AL,33,0),0),0) -> 0 | BF9: =IFERROR(IF(F9="正常工资薪金",VLOOKUP(D9&"*",个税上月累计情况!E:AL,34,0),0),0) -> 0 | BG9: =IFERROR(IF(F9="正常工资薪金",VLOOKUP(D9&"*",个税上月累计情况!E:AN,35,0),0),0) -> 0 | BH9: =IFERROR(IF(F9="正常工资薪金",VLOOKUP(D9&"*",个税上月累计情况!E:AN,36,0),0),0) -> 0 | BI9: =IFERROR(IF(F9="正常工资薪金",VLOOKUP(D9&"*",个税上月累计情况!D:AW,46,0),0),0) -> 654.69 | BJ9: =IFERROR(IF(F9="正常工资薪金",VLOOKUP(D9&"*",个税上月累计情况!D:AX,47,0),0),0) -> 57.3 | BK9: =VLOOKUP(B9,花名册!C:N,12,0) -> #N/A
B10: 马顺华 | C10: 居民身份证 | D10: 429006198803300316 | E10: 否 | F10: 正常工资薪金 | G10: {=_xlfn.IFS(F10="正常工资薪金",VLOOKUP(D10&"*",工资表明细!D:BL,61,0),F10="一般劳务报酬所得",VLOOKUP(D10&"*",工资表明细!D:BJ,59,0),F10="全年一次性奖金收入",VLOOKUP(D10&"*",工资表明细!D:BI,58,0),F10="解除劳动合同一次性补偿金",VLOOKUP(D10&"*",工资表明细!D:BH,57,0))} -> #N/A | H10: =IF(F10="一般劳务报酬所得",800,0) -> 0 | I10: 0 | J10: =IF(F10="正常工资薪金",5000,0) -> 5000 | K10: =IF(F10="正常工资薪金",VLOOKUP(D10&"*",工资表明细!D:AP,39,0),0) -> #N/A | L10: =IF(F10="正常工资薪金",VLOOKUP(D10&"*",工资表明细!D:AQ,40,0),0) -> #N/A | M10: =IF(F10="正常工资薪金",VLOOKUP(D10&"*",工资表明细!D:AR,41,0),0) -> #N/A | N10: =IF(F10="正常工资薪金",VLOOKUP(D10&"*",工资表明细!D:AT,43,0),0) -> #N/A | O10: 5 | P10: 5 | Q10: 5 | R10: 5 | S10: 5 | T10: 5 | U10: 5 | V10: 5 | W10: - | X10: 5 | Y10: - | Z10: - | AA10: - | AB10: 5 | AC10: =IF(F10="正常工资薪金",G10+AX10,"-") -> #N/A | AD10: =IF(F10="正常工资薪金",J10+AY10,"-") -> 40000 | AE10: =IF(F10="正常工资薪金",K10+L10+M10+N10+AZ10,"-") -> #N/A | AF10: =IFERROR(IF($F$5="正常工资薪金",IF(YEAR(BK10)<YEAR($BK$1),BA10/($D$1-1)*$D$1,BA10/DATEDIF(BK10,$BK$1,"M")*DATEDIF(BK10,$BK$1,"M")),"-"),0) -> 0 | AG10: =IFERROR(IF($F$5="正常工资薪金",IF(YEAR(BK10)<YEAR($BK$1),BB10/($D$1-1)*$D$1,BB10/DATEDIF(BK10,$BK$1,"M")*DATEDIF(BK10,$BK$1,"M")),"-"),0) -> 0 | AH10: =IFERROR(IF($F$5="正常工资薪金",IF(YEAR(BK10)<YEAR($BK$1),BC10/($D$1-1)*$D$1,BC10/(MONTH($BK$1)-MONTH(BK10))*(MONTH($BK$1)-MONTH(BK10)+1)),"-"),0) -> 0 | AI10: =IFERROR(IF($F$5="正常工资薪金",IF(YEAR(BK10)<YEAR($BK$1),BD10/($D$1-1)*$D$1,BD10/(MONTH($BK$1)-MONTH(BK10))*(MONTH($BK$1)-MONTH(BK10)+1)),"-"),0) -> 0 | AJ10: =IFERROR(IF($F$5="正常工资薪金",IF(YEAR(BK10)<YEAR($BK$1),BE10/($D$1-1)*$D$1,BE10/(MONTH($BK$1)-MONTH(BK10))*(MONTH($BK$1)-MONTH(BK10)+1)),"-"),0) -> 0 | AK10: =IFERROR(IF($F$5="正常工资薪金",IF(YEAR(BK10)<YEAR($BK$1),BF10/($D$1-1)*$D$1,BF10/(MONTH($BK$1)-MONTH(BK10))*(MONTH($BK$1)-MONTH(BK10)+1)),"-"),0) -> 0 | AL10: 0 | AM10: 0 | AN10: 100% | AO10: 0 | AP10: =IF(IF(F10="正常工资薪金",AC10-AD10-AE10-AF10-AG10-AH10-AI10-AJ10-AK10-AL10-AM10,G10-H10-I10)<0,0,IF(F10="正常工资薪金",AC10-AD10-AE10-AF10-AG10-AH10-AI10-AJ10-AK10-AL10-AM10,G10-H10-I10)) -> #N/A | AQ10: {=_xlfn.IFS(F10="正常工资薪金",VLOOKUP(AP10,{0,0.03;36000,0.1;144000,0.2;300000,0.25;420000,0.3;660000,0.35;960000,0.45},2,1),F10="一般劳务报酬所得",IF(AP10<=20000,0.2,IF(AP10<=50000,0.3,0.4)),F10="全年一次性奖金收入",VLOOKUP(AP10/12,{0,0.03;3000,0.1;12000,0.2;25000,0.25;35000,0.3;55000,0.35;80000,0.45},2,1),F10="解除劳动合同一次性补偿金",VLOOKUP(AP10,{0,0.03;36000,0.1;144000,0.2;300000,0.25;420000,0.3;660000,0.35;960000,0.45},2,1))} -> #N/A | AR10: {=_xlfn.IFS(F10="正常工资薪金",VLOOKUP(AP10,{0,0;36000,2520;144000,16920;300000,31920;420000,52920;660000,85920;960000,181920},2,1),F10="一般劳务报酬所得",IF(AP10<=20000,0,IF(AS<=50000,2000,7000)),F10="全年一次性奖金收入",VLOOKUP(AP10/12,{0,0;3000,210;12000,1410;25000,2660;35000,4410;55000,7160;80000,15160},2,1),F10="解除劳动合同一次性补偿金",VLOOKUP(AP10,{0,0;36000,2520;144000,16920;300000,31920;420000,52920;660000,85920;960000,181920},2,1))} -> #N/A | AS10: =AP10*AQ10-AR10 -> #N/A | AT10: 0 | AU10: =BI10+BJ10 -> 566.73 | AV10: =IF(AS10-AT10-AU10>0,AS10-AT10-AU10,0) -> #N/A | AX10: =IFERROR(IF(F10="正常工资薪金",VLOOKUP(D10&"*",个税上月累计情况!E:AL,26,0),0),0) -> 72991.45 | AY10: =IFERROR(IF(F10="正常工资薪金",VLOOKUP(D10&"*",个税上月累计情况!E:AL,27,0),0),0) -> 35000 | AZ10: =IFERROR(IF(F10="正常工资薪金",VLOOKUP(D10&"*",个税上月累计情况!E:AL,28,0),0),0) -> 8600.34 | BA10: =IFERROR(IF(F10="正常工资薪金",VLOOKUP(D10&"*",个税上月累计情况!E:AL,29,0),0),0) -> 0 | BB10: =IFERROR(IF(F10="正常工资薪金",VLOOKUP(D10&"*",个税上月累计情况!E:AL,30,0),0),0) -> 10500 | BC10: =IFERROR(IF(F10="正常工资薪金",VLOOKUP(D10&"*",个税上月累计情况!E:AL,31,0),0),0) -> 0 | BD10: =IFERROR(IF(F10="正常工资薪金",VLOOKUP(D10&"*",个税上月累计情况!E:AL,32,0),0),0) -> 0 | BE10: =IFERROR(IF(F10="正常工资薪金",VLOOKUP(D10&"*",个税上月累计情况!E:AL,33,0),0),0) -> 0 | BF10: =IFERROR(IF(F10="正常工资薪金",VLOOKUP(D10&"*",个税上月累计情况!E:AL,34,0),0),0) -> 0 | BG10: =IFERROR(IF(F10="正常工资薪金",VLOOKUP(D10&"*",个税上月累计情况!E:AN,35,0),0),0) -> 0 | BH10: =IFERROR(IF(F10="正常工资薪金",VLOOKUP(D10&"*",个税上月累计情况!E:AN,36,0),0),0) -> 0 | BI10: =IFERROR(IF(F10="正常工资薪金",VLOOKUP(D10&"*",个税上月累计情况!D:AW,46,0),0),0) -> 481.94 | BJ10: =IFERROR(IF(F10="正常工资薪金",VLOOKUP(D10&"*",个税上月累计情况!D:AX,47,0),0),0) -> 84.79 | BK10: =VLOOKUP(B10,花名册!C:N,12,0) -> #N/A
B11: 耿惠欣 | C11: 居民身份证 | D11: 37028519940425172X | E11: 否 | F11: 正常工资薪金 | G11: {=_xlfn.IFS(F11="正常工资薪金",VLOOKUP(D11&"*",工资表明细!D:BL,61,0),F11="一般劳务报酬所得",VLOOKUP(D11&"*",工资表明细!D:BJ,59,0),F11="全年一次性奖金收入",VLOOKUP(D11&"*",工资表明细!D:BI,58,0),F11="解除劳动合同一次性补偿金",VLOOKUP(D11&"*",工资表明细!D:BH,57,0))} -> #N/A | H11: =IF(F11="一般劳务报酬所得",800,0) -> 0 | I11: 3763.53 | J11: =IF(F11="正常工资薪金",5000,0) -> 5000 | K11: =IF(F11="正常工资薪金",VLOOKUP(D11&"*",工资表明细!D:AP,39,0),0) -> #N/A | L11: =IF(F11="正常工资薪金",VLOOKUP(D11&"*",工资表明细!D:AQ,40,0),0) -> #N/A | M11: =IF(F11="正常工资薪金",VLOOKUP(D11&"*",工资表明细!D:AR,41,0),0) -> #N/A | N11: =IF(F11="正常工资薪金",VLOOKUP(D11&"*",工资表明细!D:AT,43,0),0) -> #N/A | O11: 6 | P11: 6 | Q11: 6 | R11: 6 | S11: 6 | T11: 6 | U11: 6 | V11: 6 | W11: - | X11: 6 | Y11: - | Z11: - | AA11: - | AB11: 6 | AC11: =IF(F11="正常工资薪金",G11+AX11,"-") -> #N/A | AD11: =IF(F11="正常工资薪金",J11+AY11,"-") -> 40000 | AE11: =IF(F11="正常工资薪金",K11+L11+M11+N11+AZ11,"-") -> #N/A | AF11: =IFERROR(IF($F$5="正常工资薪金",IF(YEAR(BK11)<YEAR($BK$1),BA11/($D$1-1)*$D$1,BA11/DATEDIF(BK11,$BK$1,"M")*DATEDIF(BK11,$BK$1,"M")),"-"),0) -> 0 | AG11: =IFERROR(IF($F$5="正常工资薪金",IF(YEAR(BK11)<YEAR($BK$1),BB11/($D$1-1)*$D$1,BB11/DATEDIF(BK11,$BK$1,"M")*DATEDIF(BK11,$BK$1,"M")),"-"),0) -> 0 | AH11: =IFERROR(IF($F$5="正常工资薪金",IF(YEAR(BK11)<YEAR($BK$1),BC11/($D$1-1)*$D$1,BC11/(MONTH($BK$1)-MONTH(BK11))*(MONTH($BK$1)-MONTH(BK11)+1)),"-"),0) -> 0 | AI11: =IFERROR(IF($F$5="正常工资薪金",IF(YEAR(BK11)<YEAR($BK$1),BD11/($D$1-1)*$D$1,BD11/(MONTH($BK$1)-MONTH(BK11))*(MONTH($BK$1)-MONTH(BK11)+1)),"-"),0) -> 0 | AJ11: =IFERROR(IF($F$5="正常工资薪金",IF(YEAR(BK11)<YEAR($BK$1),BE11/($D$1-1)*$D$1,BE11/(MONTH($BK$1)-MONTH(BK11))*(MONTH($BK$1)-MONTH(BK11)+1)),"-"),0) -> 0 | AK11: =IFERROR(IF($F$5="正常工资薪金",IF(YEAR(BK11)<YEAR($BK$1),BF11/($D$1-1)*$D$1,BF11/(MONTH($BK$1)-MONTH(BK11))*(MONTH($BK$1)-MONTH(BK11)+1)),"-"),0) -> 0 | AL11: 0 | AM11: 0 | AN11: 100% | AO11: 0 | AP11: =IF(IF(F11="正常工资薪金",AC11-AD11-AE11-AF11-AG11-AH11-AI11-AJ11-AK11-AL11-AM11,G11-H11-I11)<0,0,IF(F11="正常工资薪金",AC11-AD11-AE11-AF11-AG11-AH11-AI11-AJ11-AK11-AL11-AM11,G11-H11-I11)) -> #N/A | AQ11: {=_xlfn.IFS(F11="正常工资薪金",VLOOKUP(AP11,{0,0.03;36000,0.1;144000,0.2;300000,0.25;420000,0.3;660000,0.35;960000,0.45},2,1),F11="一般劳务报酬所得",IF(AP11<=20000,0.2,IF(AP11<=50000,0.3,0.4)),F11="全年一次性奖金收入",VLOOKUP(AP11/12,{0,0.03;3000,0.1;12000,0.2;25000,0.25;35000,0.3;55000,0.35;80000,0.45},2,1),F11="解除劳动合同一次性补偿金",VLOOKUP(AP11,{0,0.03;36000,0.1;144000,0.2;300000,0.25;420000,0.3;660000,0.35;960000,0.45},2,1))} -> #N/A | AR11: {=_xlfn.IFS(F11="正常工资薪金",VLOOKUP(AP11,{0,0;36000,2520;144000,16920;300000,31920;420000,52920;660000,85920;960000,181920},2,1),F11="一般劳务报酬所得",IF(AP11<=20000,0,IF(AS<=50000,2000,7000)),F11="全年一次性奖金收入",VLOOKUP(AP11/12,{0,0;3000,210;12000,1410;25000,2660;35000,4410;55000,7160;80000,15160},2,1),F11="解除劳动合同一次性补偿金",VLOOKUP(AP11,{0,0;36000,2520;144000,16920;300000,31920;420000,52920;660000,85920;960000,181920},2,1))} -> #N/A | AS11: =AP11*AQ11-AR11 -> #N/A | AT11: 0 | AU11: =BI11+BJ11 -> 436.85 | AV11: =IF(AS11-AT11-AU11>0,AS11-AT11-AU11,0) -> #N/A | AX11: =IFERROR(IF(F11="正常工资薪金",VLOOKUP(D11&"*",个税上月累计情况!E:AL,26,0),0),0) -> 48198.57 | AY11: =IFERROR(IF(F11="正常工资薪金",VLOOKUP(D11&"*",个税上月累计情况!E:AL,27,0),0),0) -> 35000 | AZ11: =IFERROR(IF(F11="正常工资薪金",VLOOKUP(D11&"*",个税上月累计情况!E:AL,28,0),0),0) -> 9719.43 | BA11: =IFERROR(IF(F11="正常工资薪金",VLOOKUP(D11&"*",个税上月累计情况!E:AL,29,0),0),0) -> 0 | BB11: =IFERROR(IF(F11="正常工资薪金",VLOOKUP(D11&"*",个税上月累计情况!E:AL,30,0),0),0) -> 0 | BC11: =IFERROR(IF(F11="正常工资薪金",VLOOKUP(D11&"*",个税上月累计情况!E:AL,31,0),0),0) -> 0 | BD11: =IFERROR(IF(F11="正常工资薪金",VLOOKUP(D11&"*",个税上月累计情况!E:AL,32,0),0),0) -> 10500 | BE11: =IFERROR(IF(F11="正常工资薪金",VLOOKUP(D11&"*",个税上月累计情况!E:AL,33,0),0),0) -> 0 | BF11: =IFERROR(IF(F11="正常工资薪金",VLOOKUP(D11&"*",个税上月累计情况!E:AL,34,0),0),0) -> 0 | BG11: =IFERROR(IF(F11="正常工资薪金",VLOOKUP(D11&"*",个税上月累计情况!E:AN,35,0),0),0) -> 0 | BH11: =IFERROR(IF(F11="正常工资薪金",VLOOKUP(D11&"*",个税上月累计情况!E:AN,36,0),0),0) -> 0 | BI11: =IFERROR(IF(F11="正常工资薪金",VLOOKUP(D11&"*",个税上月累计情况!D:AW,46,0),0),0) -> 436.85 | BJ11: =IFERROR(IF(F11="正常工资薪金",VLOOKUP(D11&"*",个税上月累计情况!D:AX,47,0),0),0) -> 0 | BK11: =VLOOKUP(B11,花名册!C:N,12,0) -> #N/A
B12: 王鹏辉 | C12: 居民身份证 | D12: 421181198909130413 | E12: 否 | F12: 正常工资薪金 | G12: {=_xlfn.IFS(F12="正常工资薪金",VLOOKUP(D12&"*",工资表明细!D:BL,61,0),F12="一般劳务报酬所得",VLOOKUP(D12&"*",工资表明细!D:BJ,59,0),F12="全年一次性奖金收入",VLOOKUP(D12&"*",工资表明细!D:BI,58,0),F12="解除劳动合同一次性补偿金",VLOOKUP(D12&"*",工资表明细!D:BH,57,0))} -> #N/A | H12: =IF(F12="一般劳务报酬所得",800,0) -> 0 | I12: 0 | J12: =IF(F12="正常工资薪金",5000,0) -> 5000 | K12: =IF(F12="正常工资薪金",VLOOKUP(D12&"*",工资表明细!D:AP,39,0),0) -> #N/A | L12: =IF(F12="正常工资薪金",VLOOKUP(D12&"*",工资表明细!D:AQ,40,0),0) -> #N/A | M12: =IF(F12="正常工资薪金",VLOOKUP(D12&"*",工资表明细!D:AR,41,0),0) -> #N/A | N12: =IF(F12="正常工资薪金",VLOOKUP(D12&"*",工资表明细!D:AT,43,0),0) -> #N/A | O12: 7 | P12: 7 | Q12: 7 | R12: 7 | S12: 7 | T12: 7 | U12: 7 | V12: 7 | W12: - | X12: 7 | Y12: - | Z12: - | AA12: - | AB12: 7 | AC12: =IF(F12="正常工资薪金",G12+AX12,"-") -> #N/A | AD12: =IF(F12="正常工资薪金",J12+AY12,"-") -> 40000 | AE12: =IF(F12="正常工资薪金",K12+L12+M12+N12+AZ12,"-") -> #N/A | AF12: =IFERROR(IF($F$5="正常工资薪金",IF(YEAR(BK12)<YEAR($BK$1),BA12/($D$1-1)*$D$1,BA12/DATEDIF(BK12,$BK$1,"M")*DATEDIF(BK12,$BK$1,"M")),"-"),0) -> 0 | AG12: =IFERROR(IF($F$5="正常工资薪金",IF(YEAR(BK12)<YEAR($BK$1),BB12/($D$1-1)*$D$1,BB12/DATEDIF(BK12,$BK$1,"M")*DATEDIF(BK12,$BK$1,"M")),"-"),0) -> 0 | AH12: =IFERROR(IF($F$5="正常工资薪金",IF(YEAR(BK12)<YEAR($BK$1),BC12/($D$1-1)*$D$1,BC12/(MONTH($BK$1)-MONTH(BK12))*(MONTH($BK$1)-MONTH(BK12)+1)),"-"),0) -> 0 | AI12: =IFERROR(IF($F$5="正常工资薪金",IF(YEAR(BK12)<YEAR($BK$1),BD12/($D$1-1)*$D$1,BD12/(MONTH($BK$1)-MONTH(BK12))*(MONTH($BK$1)-MONTH(BK12)+1)),"-"),0) -> 0 | AJ12: =IFERROR(IF($F$5="正常工资薪金",IF(YEAR(BK12)<YEAR($BK$1),BE12/($D$1-1)*$D$1,BE12/(MONTH($BK$1)-MONTH(BK12))*(MONTH($BK$1)-MONTH(BK12)+1)),"-"),0) -> 0 | AK12: =IFERROR(IF($F$5="正常工资薪金",IF(YEAR(BK12)<YEAR($BK$1),BF12/($D$1-1)*$D$1,BF12/(MONTH($BK$1)-MONTH(BK12))*(MONTH($BK$1)-MONTH(BK12)+1)),"-"),0) -> 0 | AL12: 0 | AM12: 0 | AN12: 100% | AO12: 0 | AP12: =IF(IF(F12="正常工资薪金",AC12-AD12-AE12-AF12-AG12-AH12-AI12-AJ12-AK12-AL12-AM12,G12-H12-I12)<0,0,IF(F12="正常工资薪金",AC12-AD12-AE12-AF12-AG12-AH12-AI12-AJ12-AK12-AL12-AM12,G12-H12-I12)) -> #N/A | AQ12: {=_xlfn.IFS(F12="正常工资薪金",VLOOKUP(AP12,{0,0.03;36000,0.1;144000,0.2;300000,0.25;420000,0.3;660000,0.35;960000,0.45},2,1),F12="一般劳务报酬所得",IF(AP12<=20000,0.2,IF(AP12<=50000,0.3,0.4)),F12="全年一次性奖金收入",VLOOKUP(AP12/12,{0,0.03;3000,0.1;12000,0.2;25000,0.25;35000,0.3;55000,0.35;80000,0.45},2,1),F12="解除劳动合同一次性补偿金",VLOOKUP(AP12,{0,0.03;36000,0.1;144000,0.2;300000,0.25;420000,0.3;660000,0.35;960000,0.45},2,1))} -> #N/A | AR12: {=_xlfn.IFS(F12="正常工资薪金",VLOOKUP(AP12,{0,0;36000,2520;144000,16920;300000,31920;420000,52920;660000,85920;960000,181920},2,1),F12="一般劳务报酬所得",IF(AP12<=20000,0,IF(AS<=50000,2000,7000)),F12="全年一次性奖金收入",VLOOKUP(AP12/12,{0,0;3000,210;12000,1410;25000,2660;35000,4410;55000,7160;80000,15160},2,1),F12="解除劳动合同一次性补偿金",VLOOKUP(AP12,{0,0;36000,2520;144000,16920;300000,31920;420000,52920;660000,85920;960000,181920},2,1))} -> #N/A | AS12: =AP12*AQ12-AR12 -> #N/A | AT12: 0 | AU12: =BI12+BJ12 -> 5150.77 | AV12: =IF(AS12-AT12-AU12>0,AS12-AT12-AU12,0) -> #N/A | AX12: =IFERROR(IF(F12="正常工资薪金",VLOOKUP(D12&"*",个税上月累计情况!E:AL,26,0),0),0) -> 147222.56 | AY12: =IFERROR(IF(F12="正常工资薪金",VLOOKUP(D12&"*",个税上月累计情况!E:AL,27,0),0),0) -> 35000 | AZ12: =IFERROR(IF(F12="正常工资薪金",VLOOKUP(D12&"*",个税上月累计情况!E:AL,28,0),0),0) -> 25014.85 | BA12: =IFERROR(IF(F12="正常工资薪金",VLOOKUP(D12&"*",个税上月累计情况!E:AL,29,0),0),0) -> 0 | BB12: =IFERROR(IF(F12="正常工资薪金",VLOOKUP(D12&"*",个税上月累计情况!E:AL,30,0),0),0) -> 0 | BC12: =IFERROR(IF(F12="正常工资薪金",VLOOKUP(D12&"*",个税上月累计情况!E:AL,31,0),0),0) -> 0 | BD12: =IFERROR(IF(F12="正常工资薪金",VLOOKUP(D12&"*",个税上月累计情况!E:AL,32,0),0),0) -> 10500 | BE12: =IFERROR(IF(F12="正常工资薪金",VLOOKUP(D12&"*",个税上月累计情况!E:AL,33,0),0),0) -> 0 | BF12: =IFERROR(IF(F12="正常工资薪金",VLOOKUP(D12&"*",个税上月累计情况!E:AL,34,0),0),0) -> 0 | BG12: =IFERROR(IF(F12="正常工资薪金",VLOOKUP(D12&"*",个税上月累计情况!E:AN,35,0),0),0) -> 0 | BH12: =IFERROR(IF(F12="正常工资薪金",VLOOKUP(D12&"*",个税上月累计情况!E:AN,36,0),0),0) -> 0 | BI12: =IFERROR(IF(F12="正常工资薪金",VLOOKUP(D12&"*",个税上月累计情况!D:AW,46,0),0),0) -> 4202.79 | BJ12: =IFERROR(IF(F12="正常工资薪金",VLOOKUP(D12&"*",个税上月累计情况!D:AX,47,0),0),0) -> 947.98 | BK12: =VLOOKUP(B12,花名册!C:N,12,0) -> #N/A
B13: 郭子轶 | C13: 居民身份证 | D13: 510106197603021421 | E13: 否 | F13: 正常工资薪金 | G13: {=_xlfn.IFS(F13="正常工资薪金",VLOOKUP(D13&"*",工资表明细!D:BL,61,0),F13="一般劳务报酬所得",VLOOKUP(D13&"*",工资表明细!D:BJ,59,0),F13="全年一次性奖金收入",VLOOKUP(D13&"*",工资表明细!D:BI,58,0),F13="解除劳动合同一次性补偿金",VLOOKUP(D13&"*",工资表明细!D:BH,57,0))} -> #N/A | H13: =IF(F13="一般劳务报酬所得",800,0) -> 0 | I13: 0 | J13: =IF(F13="正常工资薪金",5000,0) -> 5000 | K13: =IF(F13="正常工资薪金",VLOOKUP(D13&"*",工资表明细!D:AP,39,0),0) -> #N/A | L13: =IF(F13="正常工资薪金",VLOOKUP(D13&"*",工资表明细!D:AQ,40,0),0) -> #N/A | M13: =IF(F13="正常工资薪金",VLOOKUP(D13&"*",工资表明细!D:AR,41,0),0) -> #N/A | N13: =IF(F13="正常工资薪金",VLOOKUP(D13&"*",工资表明细!D:AT,43,0),0) -> #N/A | O13: 8 | P13: 8 | Q13: 8 | R13: 8 | S13: 8 | T13: 8 | U13: 8 | V13: 8 | W13: - | X13: 8 | Y13: - | Z13: - | AA13: - | AB13: 8 | AC13: =IF(F13="正常工资薪金",G13+AX13,"-") -> #N/A | AD13: =IF(F13="正常工资薪金",J13+AY13,"-") -> 40000 | AE13: =IF(F13="正常工资薪金",K13+L13+M13+N13+AZ13,"-") -> #N/A | AF13: =IFERROR(IF($F$5="正常工资薪金",IF(YEAR(BK13)<YEAR($BK$1),BA13/($D$1-1)*$D$1,BA13/DATEDIF(BK13,$BK$1,"M")*DATEDIF(BK13,$BK$1,"M")),"-"),0) -> 0 | AG13: =IFERROR(IF($F$5="正常工资薪金",IF(YEAR(BK13)<YEAR($BK$1),BB13/($D$1-1)*$D$1,BB13/DATEDIF(BK13,$BK$1,"M")*DATEDIF(BK13,$BK$1,"M")),"-"),0) -> 0 | AH13: =IFERROR(IF($F$5="正常工资薪金",IF(YEAR(BK13)<YEAR($BK$1),BC13/($D$1-1)*$D$1,BC13/(MONTH($BK$1)-MONTH(BK13))*(MONTH($BK$1)-MONTH(BK13)+1)),"-"),0) -> 0 | AI13: =IFERROR(IF($F$5="正常工资薪金",IF(YEAR(BK13)<YEAR($BK$1),BD13/($D$1-1)*$D$1,BD13/(MONTH($BK$1)-MONTH(BK13))*(MONTH($BK$1)-MONTH(BK13)+1)),"-"),0) -> 0 | AJ13: =IFERROR(IF($F$5="正常工资薪金",IF(YEAR(BK13)<YEAR($BK$1),BE13/($D$1-1)*$D$1,BE13/(MONTH($BK$1)-MONTH(BK13))*(MONTH($BK$1)-MONTH(BK13)+1)),"-"),0) -> 0 | AK13: =IFERROR(IF($F$5="正常工资薪金",IF(YEAR(BK13)<YEAR($BK$1),BF13/($D$1-1)*$D$1,BF13/(MONTH($BK$1)-MONTH(BK13))*(MONTH($BK$1)-MONTH(BK13)+1)),"-"),0) -> 0 | AL13: 0 | AM13: 0 | AN13: 100% | AO13: 0 | AP13: =IF(IF(F13="正常工资薪金",AC13-AD13-AE13-AF13-AG13-AH13-AI13-AJ13-AK13-AL13-AM13,G13-H13-I13)<0,0,IF(F13="正常工资薪金",AC13-AD13-AE13-AF13-AG13-AH13-AI13-AJ13-AK13-AL13-AM13,G13-H13-I13)) -> #N/A | AQ13: {=_xlfn.IFS(F13="正常工资薪金",VLOOKUP(AP13,{0,0.03;36000,0.1;144000,0.2;300000,0.25;420000,0.3;660000,0.35;960000,0.45},2,1),F13="一般劳务报酬所得",IF(AP13<=20000,0.2,IF(AP13<=50000,0.3,0.4)),F13="全年一次性奖金收入",VLOOKUP(AP13/12,{0,0.03;3000,0.1;12000,0.2;25000,0.25;35000,0.3;55000,0.35;80000,0.45},2,1),F13="解除劳动合同一次性补偿金",VLOOKUP(AP13,{0,0.03;36000,0.1;144000,0.2;300000,0.25;420000,0.3;660000,0.35;960000,0.45},2,1))} -> #N/A | AR13: {=_xlfn.IFS(F13="正常工资薪金",VLOOKUP(AP13,{0,0;36000,2520;144000,16920;300000,31920;420000,52920;660000,85920;960000,181920},2,1),F13="一般劳务报酬所得",IF(AP13<=20000,0,IF(AS<=50000,2000,7000)),F13="全年一次性奖金收入",VLOOKUP(AP13/12,{0,0;3000,210;12000,1410;25000,2660;35000,4410;55000,7160;80000,15160},2,1),F13="解除劳动合同一次性补偿金",VLOOKUP(AP13,{0,0;36000,2520;144000,16920;300000,31920;420000,52920;660000,85920;960000,181920},2,1))} -> #N/A | AS13: =AP13*AQ13-AR13 -> #N/A | AT13: 0 | AU13: =BI13+BJ13 -> 13809.79 | AV13: =IF(AS13-AT13-AU13>0,AS13-AT13-AU13,0) -> #N/A | AX13: =IFERROR(IF(F13="正常工资薪金",VLOOKUP(D13&"*",个税上月累计情况!E:AL,26,0),0),0) -> 226856.07 | AY13: =IFERROR(IF(F13="正常工资薪金",VLOOKUP(D13&"*",个税上月累计情况!E:AL,27,0),0),0) -> 35000 | AZ13: =IFERROR(IF(F13="正常工资薪金",VLOOKUP(D13&"*",个税上月累计情况!E:AL,28,0),0),0) -> 38207.12 | BA13: =IFERROR(IF(F13="正常工资薪金",VLOOKUP(D13&"*",个税上月累计情况!E:AL,29,0),0),0) -> 0 | BB13: =IFERROR(IF(F13="正常工资薪金",VLOOKUP(D13&"*",个税上月累计情况!E:AL,30,0),0),0) -> 0 | BC13: =IFERROR(IF(F13="正常工资薪金",VLOOKUP(D13&"*",个税上月累计情况!E:AL,31,0),0),0) -> 0 | BD13: =IFERROR(IF(F13="正常工资薪金",VLOOKUP(D13&"*",个税上月累计情况!E:AL,32,0),0),0) -> 0 | BE13: =IFERROR(IF(F13="正常工资薪金",VLOOKUP(D13&"*",个税上月累计情况!E:AL,33,0),0),0) -> 0 | BF13: =IFERROR(IF(F13="正常工资薪金",VLOOKUP(D13&"*",个税上月累计情况!E:AL,34,0),0),0) -> 0 | BG13: =IFERROR(IF(F13="正常工资薪金",VLOOKUP(D13&"*",个税上月累计情况!E:AN,35,0),0),0) -> 0 | BH13: =IFERROR(IF(F13="正常工资薪金",VLOOKUP(D13&"*",个税上月累计情况!E:AN,36,0),0),0) -> 0 | BI13: =IFERROR(IF(F13="正常工资薪金",VLOOKUP(D13&"*",个税上月累计情况!D:AW,46,0),0),0) -> 10649.91 | BJ13: =IFERROR(IF(F13="正常工资薪金",VLOOKUP(D13&"*",个税上月累计情况!D:AX,47,0),0),0) -> 3159.88 | BK13: =VLOOKUP(B13,花名册!C:N,12,0) -> #N/A
B14: 陈昱光 | C14: 居民身份证 | D14: 410881199208201514 | E14: 否 | F14: 正常工资薪金 | G14: {=_xlfn.IFS(F14="正常工资薪金",VLOOKUP(D14&"*",工资表明细!D:BL,61,0),F14="一般劳务报酬所得",VLOOKUP(D14&"*",工资表明细!D:BJ,59,0),F14="全年一次性奖金收入",VLOOKUP(D14&"*",工资表明细!D:BI,58,0),F14="解除劳动合同一次性补偿金",VLOOKUP(D14&"*",工资表明细!D:BH,57,0))} -> #N/A | H14: =IF(F14="一般劳务报酬所得",800,0) -> 0 | I14: 0 | J14: =IF(F14="正常工资薪金",5000,0) -> 5000 | K14: =IF(F14="正常工资薪金",VLOOKUP(D14&"*",工资表明细!D:AP,39,0),0) -> #N/A | L14: =IF(F14="正常工资薪金",VLOOKUP(D14&"*",工资表明细!D:AQ,40,0),0) -> #N/A | M14: =IF(F14="正常工资薪金",VLOOKUP(D14&"*",工资表明细!D:AR,41,0),0) -> #N/A | N14: =IF(F14="正常工资薪金",VLOOKUP(D14&"*",工资表明细!D:AT,43,0),0) -> #N/A | O14: 9 | P14: 9 | Q14: 9 | R14: 9 | S14: 9 | T14: 9 | U14: 9 | V14: 9 | W14: - | X14: 9 | Y14: - | Z14: - | AA14: - | AB14: 9 | AC14: =IF(F14="正常工资薪金",G14+AX14,"-") -> #N/A | AD14: =IF(F14="正常工资薪金",J14+AY14,"-") -> 40000 | AE14: =IF(F14="正常工资薪金",K14+L14+M14+N14+AZ14,"-") -> #N/A | AF14: =IFERROR(IF($F$5="正常工资薪金",IF(YEAR(BK14)<YEAR($BK$1),BA14/($D$1-1)*$D$1,BA14/DATEDIF(BK14,$BK$1,"M")*DATEDIF(BK14,$BK$1,"M")),"-"),0) -> 0 | AG14: =IFERROR(IF($F$5="正常工资薪金",IF(YEAR(BK14)<YEAR($BK$1),BB14/($D$1-1)*$D$1,BB14/DATEDIF(BK14,$BK$1,"M")*DATEDIF(BK14,$BK$1,"M")),"-"),0) -> 0 | AH14: =IFERROR(IF($F$5="正常工资薪金",IF(YEAR(BK14)<YEAR($BK$1),BC14/($D$1-1)*$D$1,BC14/(MONTH($BK$1)-MONTH(BK14))*(MONTH($BK$1)-MONTH(BK14)+1)),"-"),0) -> 0 | AI14: =IFERROR(IF($F$5="正常工资薪金",IF(YEAR(BK14)<YEAR($BK$1),BD14/($D$1-1)*$D$1,BD14/(MONTH($BK$1)-MONTH(BK14))*(MONTH($BK$1)-MONTH(BK14)+1)),"-"),0) -> 0 | AJ14: =IFERROR(IF($F$5="正常工资薪金",IF(YEAR(BK14)<YEAR($BK$1),BE14/($D$1-1)*$D$1,BE14/(MONTH($BK$1)-MONTH(BK14))*(MONTH($BK$1)-MONTH(BK14)+1)),"-"),0) -> 0 | AK14: =IFERROR(IF($F$5="正常工资薪金",IF(YEAR(BK14)<YEAR($BK$1),BF14/($D$1-1)*$D$1,BF14/(MONTH($BK$1)-MONTH(BK14))*(MONTH($BK$1)-MONTH(BK14)+1)),"-"),0) -> 0 | AL14: 0 | AM14: 0 | AN14: 100% | AO14: 0 | AP14: =IF(IF(F14="正常工资薪金",AC14-AD14-AE14-AF14-AG14-AH14-AI14-AJ14-AK14-AL14-AM14,G14-H14-I14)<0,0,IF(F14="正常工资薪金",AC14-AD14-AE14-AF14-AG14-AH14-AI14-AJ14-AK14-AL14-AM14,G14-H14-I14)) -> #N/A | AQ14: {=_xlfn.IFS(F14="正常工资薪金",VLOOKUP(AP14,{0,0.03;36000,0.1;144000,0.2;300000,0.25;420000,0.3;660000,0.35;960000,0.45},2,1),F14="一般劳务报酬所得",IF(AP14<=20000,0.2,IF(AP14<=50000,0.3,0.4)),F14="全年一次性奖金收入",VLOOKUP(AP14/12,{0,0.03;3000,0.1;12000,0.2;25000,0.25;35000,0.3;55000,0.35;80000,0.45},2,1),F14="解除劳动合同一次性补偿金",VLOOKUP(AP14,{0,0.03;36000,0.1;144000,0.2;300000,0.25;420000,0.3;660000,0.35;960000,0.45},2,1))} -> #N/A | AR14: {=_xlfn.IFS(F14="正常工资薪金",VLOOKUP(AP14,{0,0;36000,2520;144000,16920;300000,31920;420000,52920;660000,85920;960000,181920},2,1),F14="一般劳务报酬所得",IF(AP14<=20000,0,IF(AS<=50000,2000,7000)),F14="全年一次性奖金收入",VLOOKUP(AP14/12,{0,0;3000,210;12000,1410;25000,2660;35000,4410;55000,7160;80000,15160},2,1),F14="解除劳动合同一次性补偿金",VLOOKUP(AP14,{0,0;36000,2520;144000,16920;300000,31920;420000,52920;660000,85920;960000,181920},2,1))} -> #N/A | AS14: =AP14*AQ14-AR14 -> #N/A | AT14: 0 | AU14: =BI14+BJ14 -> 4043.85 | AV14: =IF(AS14-AT14-AU14>0,AS14-AT14-AU14,0) -> #N/A | AX14: =IFERROR(IF(F14="正常工资薪金",VLOOKUP(D14&"*",个税上月累计情况!E:AL,26,0),0),0) -> 112643.55 | AY14: =IFERROR(IF(F14="正常工资薪金",VLOOKUP(D14&"*",个税上月累计情况!E:AL,27,0),0),0) -> 35000 | AZ14: =IFERROR(IF(F14="正常工资薪金",VLOOKUP(D14&"*",个税上月累计情况!E:AL,28,0),0),0) -> 12005.07 | BA14: =IFERROR(IF(F14="正常工资薪金",VLOOKUP(D14&"*",个税上月累计情况!E:AL,29,0),0),0) -> 0 | BB14: =IFERROR(IF(F14="正常工资薪金",VLOOKUP(D14&"*",个税上月累计情况!E:AL,30,0),0),0) -> 0 | BC14: =IFERROR(IF(F14="正常工资薪金",VLOOKUP(D14&"*",个税上月累计情况!E:AL,31,0),0),0) -> 0 | BD14: =IFERROR(IF(F14="正常工资薪金",VLOOKUP(D14&"*",个税上月累计情况!E:AL,32,0),0),0) -> 0 | BE14: =IFERROR(IF(F14="正常工资薪金",VLOOKUP(D14&"*",个税上月累计情况!E:AL,33,0),0),0) -> 0 | BF14: =IFERROR(IF(F14="正常工资薪金",VLOOKUP(D14&"*",个税上月累计情况!E:AL,34,0),0),0) -> 0 | BG14: =IFERROR(IF(F14="正常工资薪金",VLOOKUP(D14&"*",个税上月累计情况!E:AN,35,0),0),0) -> 0 | BH14: =IFERROR(IF(F14="正常工资薪金",VLOOKUP(D14&"*",个税上月累计情况!E:AN,36,0),0),0) -> 0 | BI14: =IFERROR(IF(F14="正常工资薪金",VLOOKUP(D14&"*",个税上月累计情况!D:AW,46,0),0),0) -> 3107.68 | BJ14: =IFERROR(IF(F14="正常工资薪金",VLOOKUP(D14&"*",个税上月累计情况!D:AX,47,0),0),0) -> 936.17 | BK14: =VLOOKUP(B14,花名册!C:N,12,0) -> #N/A
B15: 姜文超 | C15: 居民身份证 | D15: 370831198704081514 | E15: 否 | F15: 正常工资薪金 | G15: {=_xlfn.IFS(F15="正常工资薪金",VLOOKUP(D15&"*",工资表明细!D:BL,61,0),F15="一般劳务报酬所得",VLOOKUP(D15&"*",工资表明细!D:BJ,59,0),F15="全年一次性奖金收入",VLOOKUP(D15&"*",工资表明细!D:BI,58,0),F15="解除劳动合同一次性补偿金",VLOOKUP(D15&"*",工资表明细!D:BH,57,0))} -> #N/A | H15: =IF(F15="一般劳务报酬所得",800,0) -> 0 | I15: 0 | J15: =IF(F15="正常工资薪金",5000,0) -> 5000 | K15: =IF(F15="正常工资薪金",VLOOKUP(D15&"*",工资表明细!D:AP,39,0),0) -> #N/A | L15: =IF(F15="正常工资薪金",VLOOKUP(D15&"*",工资表明细!D:AQ,40,0),0) -> #N/A | M15: =IF(F15="正常工资薪金",VLOOKUP(D15&"*",工资表明细!D:AR,41,0),0) -> #N/A | N15: =IF(F15="正常工资薪金",VLOOKUP(D15&"*",工资表明细!D:AT,43,0),0) -> #N/A | O15: 10 | P15: 10 | Q15: 10 | R15: 10 | S15: 10 | T15: 10 | U15: 10 | V15: 10 | W15: - | X15: 10 | Y15: - | Z15: - | AA15: - | AB15: 10 | AC15: =IF(F15="正常工资薪金",G15+AX15,"-") -> #N/A | AD15: =IF(F15="正常工资薪金",J15+AY15,"-") -> 40000 | AE15: =IF(F15="正常工资薪金",K15+L15+M15+N15+AZ15,"-") -> #N/A | AF15: =IFERROR(IF($F$5="正常工资薪金",IF(YEAR(BK15)<YEAR($BK$1),BA15/($D$1-1)*$D$1,BA15/DATEDIF(BK15,$BK$1,"M")*DATEDIF(BK15,$BK$1,"M")),"-"),0) -> 0 | AG15: =IFERROR(IF($F$5="正常工资薪金",IF(YEAR(BK15)<YEAR($BK$1),BB15/($D$1-1)*$D$1,BB15/DATEDIF(BK15,$BK$1,"M")*DATEDIF(BK15,$BK$1,"M")),"-"),0) -> 0 | AH15: =IFERROR(IF($F$5="正常工资薪金",IF(YEAR(BK15)<YEAR($BK$1),BC15/($D$1-1)*$D$1,BC15/(MONTH($BK$1)-MONTH(BK15))*(MONTH($BK$1)-MONTH(BK15)+1)),"-"),0) -> 0 | AI15: =IFERROR(IF($F$5="正常工资薪金",IF(YEAR(BK15)<YEAR($BK$1),BD15/($D$1-1)*$D$1,BD15/(MONTH($BK$1)-MONTH(BK15))*(MONTH($BK$1)-MONTH(BK15)+1)),"-"),0) -> 0 | AJ15: =IFERROR(IF($F$5="正常工资薪金",IF(YEAR(BK15)<YEAR($BK$1),BE15/($D$1-1)*$D$1,BE15/(MONTH($BK$1)-MONTH(BK15))*(MONTH($BK$1)-MONTH(BK15)+1)),"-"),0) -> 0 | AK15: =IFERROR(IF($F$5="正常工资薪金",IF(YEAR(BK15)<YEAR($BK$1),BF15/($D$1-1)*$D$1,BF15/(MONTH($BK$1)-MONTH(BK15))*(MONTH($BK$1)-MONTH(BK15)+1)),"-"),0) -> 0 | AL15: 0 | AM15: 0 | AN15: 100% | AO15: 0 | AP15: =IF(IF(F15="正常工资薪金",AC15-AD15-AE15-AF15-AG15-AH15-AI15-AJ15-AK15-AL15-AM15,G15-H15-I15)<0,0,IF(F15="正常工资薪金",AC15-AD15-AE15-AF15-AG15-AH15-AI15-AJ15-AK15-AL15-AM15,G15-H15-I15)) -> #N/A | AQ15: {=_xlfn.IFS(F15="正常工资薪金",VLOOKUP(AP15,{0,0.03;36000,0.1;144000,0.2;300000,0.25;420000,0.3;660000,0.35;960000,0.45},2,1),F15="一般劳务报酬所得",IF(AP15<=20000,0.2,IF(AP15<=50000,0.3,0.4)),F15="全年一次性奖金收入",VLOOKUP(AP15/12,{0,0.03;3000,0.1;12000,0.2;25000,0.25;35000,0.3;55000,0.35;80000,0.45},2,1),F15="解除劳动合同一次性补偿金",VLOOKUP(AP15,{0,0.03;36000,0.1;144000,0.2;300000,0.25;420000,0.3;660000,0.35;960000,0.45},2,1))} -> #N/A | AR15: {=_xlfn.IFS(F15="正常工资薪金",VLOOKUP(AP15,{0,0;36000,2520;144000,16920;300000,31920;420000,52920;660000,85920;960000,181920},2,1),F15="一般劳务报酬所得",IF(AP15<=20000,0,IF(AS<=50000,2000,7000)),F15="全年一次性奖金收入",VLOOKUP(AP15/12,{0,0;3000,210;12000,1410;25000,2660;35000,4410;55000,7160;80000,15160},2,1),F15="解除劳动合同一次性补偿金",VLOOKUP(AP15,{0,0;36000,2520;144000,16920;300000,31920;420000,52920;660000,85920;960000,181920},2,1))} -> #N/A | AS15: =AP15*AQ15-AR15 -> #N/A | AT15: 0 | AU15: =BI15+BJ15 -> 26549.99 | AV15: =IF(AS15-AT15-AU15>0,AS15-AT15-AU15,0) -> #N/A | AX15: =IFERROR(IF(F15="正常工资薪金",VLOOKUP(D15&"*",个税上月累计情况!E:AL,26,0),0),0) -> 280000 | AY15: =IFERROR(IF(F15="正常工资薪金",VLOOKUP(D15&"*",个税上月累计情况!E:AL,27,0),0),0) -> 35000 | AZ15: =IFERROR(IF(F15="正常工资薪金",VLOOKUP(D15&"*",个税上月累计情况!E:AL,28,0),0),0) -> 17150.07 | BA15: =IFERROR(IF(F15="正常工资薪金",VLOOKUP(D15&"*",个税上月累计情况!E:AL,29,0),0),0) -> 0 | BB15: =IFERROR(IF(F15="正常工资薪金",VLOOKUP(D15&"*",个税上月累计情况!E:AL,30,0),0),0) -> 10500 | BC15: =IFERROR(IF(F15="正常工资薪金",VLOOKUP(D15&"*",个税上月累计情况!E:AL,31,0),0),0) -> 0 | BD15: =IFERROR(IF(F15="正常工资薪金",VLOOKUP(D15&"*",个税上月累计情况!E:AL,32,0),0),0) -> 0 | BE15: =IFERROR(IF(F15="正常工资薪金",VLOOKUP(D15&"*",个税上月累计情况!E:AL,33,0),0),0) -> 0 | BF15: =IFERROR(IF(F15="正常工资薪金",VLOOKUP(D15&"*",个税上月累计情况!E:AL,34,0),0),0) -> 0 | BG15: =IFERROR(IF(F15="正常工资薪金",VLOOKUP(D15&"*",个税上月累计情况!E:AN,35,0),0),0) -> 0 | BH15: =IFERROR(IF(F15="正常工资薪金",VLOOKUP(D15&"*",个税上月累计情况!E:AN,36,0),0),0) -> 0 | BI15: =IFERROR(IF(F15="正常工资薪金",VLOOKUP(D15&"*",个税上月累计情况!D:AW,46,0),0),0) -> 20339.99 | BJ15: =IFERROR(IF(F15="正常工资薪金",VLOOKUP(D15&"*",个税上月累计情况!D:AX,47,0),0),0) -> 6210 | BK15: =VLOOKUP(B15,花名册!C:N,12,0) -> #N/A
B16: 周海明 | C16: 居民身份证 | D16: 130427198606116938 | E16: 否 | F16: 正常工资薪金 | G16: {=_xlfn.IFS(F16="正常工资薪金",VLOOKUP(D16&"*",工资表明细!D:BL,61,0),F16="一般劳务报酬所得",VLOOKUP(D16&"*",工资表明细!D:BJ,59,0),F16="全年一次性奖金收入",VLOOKUP(D16&"*",工资表明细!D:BI,58,0),F16="解除劳动合同一次性补偿金",VLOOKUP(D16&"*",工资表明细!D:BH,57,0))} -> #N/A | H16: =IF(F16="一般劳务报酬所得",800,0) -> 0 | I16: 0 | J16: =IF(F16="正常工资薪金",5000,0) -> 5000 | K16: =IF(F16="正常工资薪金",VLOOKUP(D16&"*",工资表明细!D:AP,39,0),0) -> #N/A | L16: =IF(F16="正常工资薪金",VLOOKUP(D16&"*",工资表明细!D:AQ,40,0),0) -> #N/A | M16: =IF(F16="正常工资薪金",VLOOKUP(D16&"*",工资表明细!D:AR,41,0),0) -> #N/A | N16: =IF(F16="正常工资薪金",VLOOKUP(D16&"*",工资表明细!D:AT,43,0),0) -> #N/A | O16: 11 | P16: 11 | Q16: 11 | R16: 11 | S16: 11 | T16: 11 | U16: 11 | V16: 11 | W16: - | X16: 11 | Y16: - | Z16: - | AA16: - | AB16: 11 | AC16: =IF(F16="正常工资薪金",G16+AX16,"-") -> #N/A | AD16: =IF(F16="正常工资薪金",J16+AY16,"-") -> 40000 | AE16: =IF(F16="正常工资薪金",K16+L16+M16+N16+AZ16,"-") -> #N/A | AF16: =IFERROR(IF($F$5="正常工资薪金",IF(YEAR(BK16)<YEAR($BK$1),BA16/($D$1-1)*$D$1,BA16/DATEDIF(BK16,$BK$1,"M")*DATEDIF(BK16,$BK$1,"M")),"-"),0) -> 0 | AG16: =IFERROR(IF($F$5="正常工资薪金",IF(YEAR(BK16)<YEAR($BK$1),BB16/($D$1-1)*$D$1,BB16/DATEDIF(BK16,$BK$1,"M")*DATEDIF(BK16,$BK$1,"M")),"-"),0) -> 0 | AH16: =IFERROR(IF($F$5="正常工资薪金",IF(YEAR(BK16)<YEAR($BK$1),BC16/($D$1-1)*$D$1,BC16/(MONTH($BK$1)-MONTH(BK16))*(MONTH($BK$1)-MONTH(BK16)+1)),"-"),0) -> 0 | AI16: =IFERROR(IF($F$5="正常工资薪金",IF(YEAR(BK16)<YEAR($BK$1),BD16/($D$1-1)*$D$1,BD16/(MONTH($BK$1)-MONTH(BK16))*(MONTH($BK$1)-MONTH(BK16)+1)),"-"),0) -> 0 | AJ16: =IFERROR(IF($F$5="正常工资薪金",IF(YEAR(BK16)<YEAR($BK$1),BE16/($D$1-1)*$D$1,BE16/(MONTH($BK$1)-MONTH(BK16))*(MONTH($BK$1)-MONTH(BK16)+1)),"-"),0) -> 0 | AK16: =IFERROR(IF($F$5="正常工资薪金",IF(YEAR(BK16)<YEAR($BK$1),BF16/($D$1-1)*$D$1,BF16/(MONTH($BK$1)-MONTH(BK16))*(MONTH($BK$1)-MONTH(BK16)+1)),"-"),0) -> 0 | AL16: 0 | AM16: 0 | AN16: 100% | AO16: 0 | AP16: =IF(IF(F16="正常工资薪金",AC16-AD16-AE16-AF16-AG16-AH16-AI16-AJ16-AK16-AL16-AM16,G16-H16-I16)<0,0,IF(F16="正常工资薪金",AC16-AD16-AE16-AF16-AG16-AH16-AI16-AJ16-AK16-AL16-AM16,G16-H16-I16)) -> #N/A | AQ16: {=_xlfn.IFS(F16="正常工资薪金",VLOOKUP(AP16,{0,0.03;36000,0.1;144000,0.2;300000,0.25;420000,0.3;660000,0.35;960000,0.45},2,1),F16="一般劳务报酬所得",IF(AP16<=20000,0.2,IF(AP16<=50000,0.3,0.4)),F16="全年一次性奖金收入",VLOOKUP(AP16/12,{0,0.03;3000,0.1;12000,0.2;25000,0.25;35000,0.3;55000,0.35;80000,0.45},2,1),F16="解除劳动合同一次性补偿金",VLOOKUP(AP16,{0,0.03;36000,0.1;144000,0.2;300000,0.25;420000,0.3;660000,0.35;960000,0.45},2,1))} -> #N/A | AR16: {=_xlfn.IFS(F16="正常工资薪金",VLOOKUP(AP16,{0,0;36000,2520;144000,16920;300000,31920;420000,52920;660000,85920;960000,181920},2,1),F16="一般劳务报酬所得",IF(AP16<=20000,0,IF(AS<=50000,2000,7000)),F16="全年一次性奖金收入",VLOOKUP(AP16/12,{0,0;3000,210;12000,1410;25000,2660;35000,4410;55000,7160;80000,15160},2,1),F16="解除劳动合同一次性补偿金",VLOOKUP(AP16,{0,0;36000,2520;144000,16920;300000,31920;420000,52920;660000,85920;960000,181920},2,1))} -> #N/A | AS16: =AP16*AQ16-AR16 -> #N/A | AT16: 0 | AU16: =BI16+BJ16 -> 2110.11 | AV16: =IF(AS16-AT16-AU16>0,AS16-AT16-AU16,0) -> #N/A | AX16: =IFERROR(IF(F16="正常工资薪金",VLOOKUP(D16&"*",个税上月累计情况!E:AL,26,0),0),0) -> 100605.4 | AY16: =IFERROR(IF(F16="正常工资薪金",VLOOKUP(D16&"*",个税上月累计情况!E:AL,27,0),0),0) -> 35000 | AZ16: =IFERROR(IF(F16="正常工资薪金",VLOOKUP(D16&"*",个税上月累计情况!E:AL,28,0),0),0) -> 11585.07 | BA16: =IFERROR(IF(F16="正常工资薪金",VLOOKUP(D16&"*",个税上月累计情况!E:AL,29,0),0),0) -> 0 | BB16: =IFERROR(IF(F16="正常工资薪金",VLOOKUP(D16&"*",个税上月累计情况!E:AL,30,0),0),0) -> 0 | BC16: =IFERROR(IF(F16="正常工资薪金",VLOOKUP(D16&"*",个税上月累计情况!E:AL,31,0),0),0) -> 0 | BD16: =IFERROR(IF(F16="正常工资薪金",VLOOKUP(D16&"*",个税上月累计情况!E:AL,32,0),0),0) -> 10500 | BE16: =IFERROR(IF(F16="正常工资薪金",VLOOKUP(D16&"*",个税上月累计情况!E:AL,33,0),0),0) -> 0 | BF16: =IFERROR(IF(F16="正常工资薪金",VLOOKUP(D16&"*",个税上月累计情况!E:AL,34,0),0),0) -> 0 | BG16: =IFERROR(IF(F16="正常工资薪金",VLOOKUP(D16&"*",个税上月累计情况!E:AN,35,0),0),0) -> 0 | BH16: =IFERROR(IF(F16="正常工资薪金",VLOOKUP(D16&"*",个税上月累计情况!E:AN,36,0),0),0) -> 0 | BI16: =IFERROR(IF(F16="正常工资薪金",VLOOKUP(D16&"*",个税上月累计情况!D:AW,46,0),0),0) -> 2110.11 | BJ16: =IFERROR(IF(F16="正常工资薪金",VLOOKUP(D16&"*",个税上月累计情况!D:AX,47,0),0),0) -> 0 | BK16: =VLOOKUP(B16,花名册!C:N,12,0) -> #N/A
